Workbook

Sheet Statement_of_Profit&Loss
B2: Period Start | E2: 45694 | F2: =E3+1 -> 45717 | G2: =F3+1 -> 45748 | H2: =G3+1 -> 45778 | I2: =H3+1 -> 45809 | J2: =I3+1 -> 45839 | K2: =J3+1 -> 45870 | L2: =K3+1 -> 45901 | M2: =L3+1 -> 45931
B3: Period End | E3: =EOMONTH(E2,0) -> 45716 | F3: =EOMONTH(F2,0) -> 45747 | G3: =EOMONTH(G2,0) -> 45777 | H3: =EOMONTH(H2,0) -> 45808 | I3: =EOMONTH(I2,0) -> 45838 | J3: =EOMONTH(J2,0) -> 45869 | K3: =EOMONTH(K2,0) -> 45900 | L3: =EOMONTH(L2,0) -> 45930 | M3: =EOMONTH(M2,0) -> 45961
B4: ဝင်ငွေအလုံးစုံပါဝင်သောရှင်းတမ်းပေါင်းချုပ် ( Profit & Loss Accounts ) | C4: Notes | E4: =TEXT(E3,"MMMM-YYY") -> February-2025 | F4: =TEXT(F3,"MMMM-YYY") -> March-2025 | G4: =TEXT(G3,"MMMM-YYY") -> April-2025 | H4: =TEXT(H3,"MMMM-YYY") -> May-2025 | I4: =TEXT(I3,"MMMM-YYY") -> June-2025 | J4: =TEXT(J3,"MMMM-YYY") -> July-2025 | K4: =TEXT(K3,"MMMM-YYY") -> August-2025 | L4: =TEXT(L3,"MMMM-YYY") -> September-2025 | M4: =TEXT(M3,"MMMM-YYY") -> October-2025
B5: ဝင်ငွေ ( Revenue ) | C5: 1 | E5: =Financial_Notes!D6 -> 12876000 | F5: =Financial_Notes!E6 -> 38186000 | G5: =Financial_Notes!F6 -> 52160000 | H5: =Financial_Notes!G6 -> 57481000 | I5: =Financial_Notes!H6 -> 33478500 | J5: =Financial_Notes!I6 -> 19774500 | K5: =Financial_Notes!J6 -> 19759500 | L5: =Financial_Notes!K6 -> 25669100 | M5: =Financial_Notes!L6 -> 21894000 | Q5: =SUM(K5:M5) -> 67322600
B6: ကုန်ရောင်းတန်ဖိုး ( Cost of Sale ) | C6: 2 | E6: =Financial_Notes!D25 -> 11630835 | F6: =Financial_Notes!E25 -> 35800729 | G6: =Financial_Notes!F25 -> 45238168 | H6: =Financial_Notes!G25 -> 48869666 | I6: =Financial_Notes!H25 -> 29203605 | J6: =Financial_Notes!I25 -> 17914425 | K6: =Financial_Notes!J25 -> 20165754 | L6: =Financial_Notes!K25 -> 26546845 | M6: =Financial_Notes!L25 -> 21981285
B7: အကြမ်းအမြတ် ( Gross Profit) | E7: =E5-E6 -> 1245164.8 | F7: =F5-F6 -> 2385271.2 | G7: =G5-G6 -> 6921831.9 | H7: =H5-H6 -> 8611334.2 | I7: =I5-I6 -> 4274895.1 | J7: =J5-J6 -> 1860075.4 | K7: =K5-K6 -> -406254.34 | L7: =L5-L6 -> -877745.05 | M7: =M5-M6 -> -87284.84
B8: အကြမ်းအမြတ်အစွန်း % ( Gross Profit Margin % ) | E8: =E7/E5 -> 0.096704317 | F8: =F7/F5 -> 0.062464546 | G8: =G7/G5 -> 0.13270383 | H8: =H7/H5 -> 0.14981184 | I8: =I7/I5 -> 0.12769076 | J8: =J7/J5 -> 0.094064344 | K8: =K7/K5 -> -0.02055995 | L8: =L7/L5 -> -0.034194617 | M8: =M7/M5 -> -0.0039867014
B9: လုပ်ငန်းလည်ပတ်မှုကုန်ကျစရိတ်များ ( SG&A Expenses ) - | C9: 3
B10: - ဈေးကွက်ရှာဖွေရေးနှင့် ကြောငြာကုန်ကျစရိတ်များ ( Marketing & Advertising Expenses ) | E10: {=Financial_Notes!D30:D39} -> 84000 | F10: {=Financial_Notes!E30:E39} -> 0 | G10: {=Financial_Notes!F30:F39} -> 0 | H10: {=Financial_Notes!G30:G39} -> 0 | I10: {=Financial_Notes!H30:H39} -> 0 | J10: {=Financial_Notes!I30:I39} -> 0 | K10: {=Financial_Notes!J30:J39} -> 0 | L10: {=Financial_Notes!K30:K39} -> 0 | M10: {=Financial_Notes!L30:L39} -> 0
B11: - ရုံးပိုင်းဆိုင်ရာဝန်ထမ်းစရိတ်များ ( Staff Salaries ) | E11: 0 | F11: 0 | G11: 0 | H11: 0 | I11: 0 | J11: 0 | K11: 0 | L11: 0 | M11: 0
B12: - ဝန်ထမ်းစားသောက်စရိတ်များ ( Meal Allowance ) | E12: 0 | F12: 0 | G12: 0 | H12: 0 | I12: 0 | J12: 0 | K12: 0 | L12: 0 | M12: 0
B13: - ရေ၊ မီးသုံးစွဲမှု ထိန်းသိမ်းခြင်းစရိတ်များ ( Utilities Expenses ) | E13: 0 | F13: 0 | G13: 0 | H13: 0 | I13: 0 | J13: 0 | K13: 0 | L13: 0 | M13: 0
B14: - သယ်ယူပို့ဆောင်ရေးနှင့် ဖြန့်ဖြူးရေးကုန်ကျစရိတ်များ ( Transportation & Distribution Expense ) | E14: 0 | F14: 0 | G14: 0 | H14: 0 | I14: 0 | J14: 0 | K14: 0 | L14: 0 | M14: 0
B15: - စက်ရုံအဆောက်အဦများနှင့် ရုံးသုံးပစ္စည်းများနှင့် ပြုပြင်ထိန်းသိမ်းရေးစရိတ်များ ( Factory Buildings & Office Supplies and Maintenance ) | E15: 0 | F15: 0 | G15: 1146150 | H15: 583000 | I15: 0 | J15: 10000 | K15: 0 | L15: 274898 | M15: 394898
B16: - ကုန်ထုတ်လုပ်ငန်းနှင့်တိုက်ရိုက်မပတ်သတ်သော ပုံသေပိုင်ပစ္စည်း တန်ဖိုးလျှော့စရိတ်များ ( Depreciation Expenses - SG&A ) | E16: 601666.67 | F16: 658800 | G16: 960628.67 | H16: 947079.67 | I16: 933983 | J16: 921323 | K16: 909084 | L16: 897254 | M16: 885817
B17: - ဂိုဒေါင်ရှိပစ္စည်းစာရင်းပယ်ဖျက်မှုဆိုင်ရာ ကုန်ကျစရိတ်များ ( Inventory Write-off ) | E17: 0 | F17: 0 | G17: 0 | H17: 0 | I17: 0 | J17: 0 | K17: 1729738.5 | L17: 1340478 | M17: 0
B18: - တခြားကုန်ကျစရိတ်များ ( Other Expenses ) | E18: 0 | F18: 0 | G18: 200000 | H18: 0 | I18: 0 | J18: 0 | K18: 0 | L18: 0 | M18: 0
B19: - စီမံအုပ်ချုပ်သူများနှင့် ဒါရိုက်တာများ ခံစားခွင့် ( Key Managment Personnel and Director Compensation) | E19: 0 | F19: 107227.03 | G19: 0 | H19: 0 | I19: 0 | J19: 0 | K19: 0 | L19: 0 | M19: 0
B20: ဘဏ္ဍာရေးစရိတ်နှင့် အခွန်မဆောင်မီ အမြတ်ငွေ ( EBIT ) | E20: =E7-SUM(E10:E19) -> 559498.11 | F20: =F7-SUM(F10:F19) -> 1619244.1 | G20: =G7-SUM(G10:G19) -> 4615053.2 | H20: =H7-SUM(H10:H19) -> 7081254.6 | I20: =I7-SUM(I10:I19) -> 3340912.1 | J20: =J7-SUM(J10:J19) -> 928752.37 | K20: =K7-SUM(K10:K19) -> -3045076.8 | L20: =L7-SUM(L10:L19) -> -3390375.1 | M20: =M7-SUM(M10:M19) -> -1367999.8
B21: ဘဏ္ဍာရေးစရိတ်နှင့် အခွန်မဆောင်မီ အမြတ်အစွန်း % ( EBIT Margin % ) | E21: =E20/E5 -> 0.043452789 | F21: =F20/F5 -> 0.042404131 | G21: =G20/G5 -> 0.088478781 | H21: =H20/H5 -> 0.12319296 | I21: =I20/I5 -> 0.099792766 | J21: =J20/J5 -> 0.046967173 | K21: =K20/K5 -> -0.15410698 | L21: =L20/L5 -> -0.13208001 | M21: =M20/M5 -> -0.062482865
B22: တန်ဖိုးလျှော့စရိတ်စုစုပေါင်း ( Depreciation & Amortisation ) | C22: 4 | E22: =Financial_Notes!D46 -> 945425 | F22: =Financial_Notes!E46 -> 1015225 | G22: =Financial_Notes!F46 -> 2788779.7 | H22: =Financial_Notes!G46 -> 2714291.7 | I22: =Financial_Notes!H46 -> 2642288 | J22: =Financial_Notes!I46 -> 2572685 | K22: =Financial_Notes!J46 -> 2505400 | L22: =Financial_Notes!K46 -> 2440360 | M22: =Financial_Notes!L46 -> 2377486
B23: တန်ဖိုးလျှော့စရိတ်များ၊ ဘဏ္ဍာရေးစရိတ်နှင့် အခွန်မဆောင်မီ အမြတ်ငွေ ( EBITDA ) | E23: =E20+E22 -> 1504923.1 | F23: =F20+F22 -> 2634469.1 | G23: =G20+G22 -> 7403832.9 | H23: =H20+H22 -> 9795546.2 | I23: =I20+I22 -> 5983200.1 | J23: =J20+J22 -> 3501437.4 | K23: =K20+K22 -> -539676.84 | L23: =L20+L22 -> -950015.05 | M23: =M20+M22 -> 1009486.2
B24: တန်ဖိုးလျှော့စရိတ်များ၊ ဘဏ္ဍာရေးစရိတ်နှင့် အခွန်မဆောင်မီ အမြတ်အစွန်း % ( EBITDA Margin % ) | E24: =E23/E5 -> 0.11687815 | F24: =F23/F5 -> 0.068990445 | G24: =G23/G5 -> 0.14194465 | H24: =H23/H5 -> 0.17041364 | I24: =I23/I5 -> 0.17871769 | J24: =J23/J5 -> 0.17706831 | K24: =K23/K5 -> -0.027312272 | L24: =L23/L5 -> -0.037010065 | M24: =M23/M5 -> 0.046107891
B25: တခြားဝင်ငွေများ ( Other Income ) | C25: 5 | E25: =Financial_Notes!D52 -> 0 | F25: =Financial_Notes!E52 -> 0 | G25: =Financial_Notes!F52 -> 348030 | H25: =Financial_Notes!G52 -> 0 | I25: =Financial_Notes!H52 -> 0 | J25: =Financial_Notes!I52 -> 0 | K25: =Financial_Notes!J52 -> 0 | L25: =Financial_Notes!K52 -> 0 | M25: =Financial_Notes!L52 -> 818728.93
B26: မမျှော်လင့်သောသဘာဝဘေးအန္တရာယ်များကြောင့် ထိခိုက်ဆုံးရှုံးမှုများအတွက် စာရင်းပယ်ဖျက်မှုစရိတ်များ ( Inventory Loss due to unexpected events ) | C26: 6 | E26: =Financial_Notes!D59 -> 0 | F26: =Financial_Notes!E59 -> 1213698.9 | G26: =Financial_Notes!F59 -> 0 | H26: =Financial_Notes!G59 -> 0 | I26: =Financial_Notes!H59 -> 0 | J26: =Financial_Notes!I59 -> 0 | K26: =Financial_Notes!J59 -> 0 | L26: =Financial_Notes!K59 -> 0 | M26: =Financial_Notes!L59 -> 0
B27: အခွန်မလျာထားမီ အမြတ် ( Profit Before Tax ) | E27: =E20+E25-E26 -> 559498.11 | F27: =F20+F25-F26 -> 405545.2 | G27: =G20+G25-G26 -> 4963083.2 | H27: =H20+H25-H26 -> 7081254.6 | I27: =I20+I25-I26 -> 3340912.1 | J27: =J20+J25-J26 -> 928752.37 | K27: =K20+K25-K26 -> -3045076.8 | L27: =L20+L25-L26 -> -3390375.1 | M27: =M20+M25-M26 -> -549270.91 | Q27: =SUM(K27:M27) -> -6984722.8
B28: အခွန်မလျာထားမီ အမြတ်အစွန်း % ( Profit Before Tax Margin % ) | E28: =E27/E5 -> 0.043452789 | F28: =F27/F5 -> 0.010620259 | G28: =G27/G5 -> 0.095151135 | H28: =H27/H5 -> 0.12319296 | I28: =I27/I5 -> 0.099792766 | J28: =J27/J5 -> 0.046967173 | K28: =K27/K5 -> -0.15410698 | L28: =L27/L5 -> -0.13208001 | M28: =M27/M5 -> -0.025087737 | Q28: =Q27/Q5 -> -0.10375005

Sheet Statement_of_Financial Position
B2: Period Start | E2: 45694 | F2: =E3+1 -> 45717 | G2: =F3+1 -> 45748 | H2: =G3+1 -> 45778 | I2: =H3+1 -> 45809 | J2: =I3+1 -> 45839 | K2: =J3+1 -> 45870 | L2: =K3+1 -> 45901 | M2: =L3+1 -> 45931
B3: Period End | E3: =EOMONTH(E2,0) -> 45716 | F3: =EOMONTH(F2,0) -> 45747 | G3: =EOMONTH(G2,0) -> 45777 | H3: =EOMONTH(H2,0) -> 45808 | I3: =EOMONTH(I2,0) -> 45838 | J3: =EOMONTH(J2,0) -> 45869 | K3: =EOMONTH(K2,0) -> 45900 | L3: =EOMONTH(L2,0) -> 45930 | M3: =EOMONTH(M2,0) -> 45961
B4: ဘဏ္ဍာရေးအခြေအနေပြရှင်းတမ်းပေါင်းချုပ် ( Balance Sheet Accounts ) | C4: Notes | E4: =TEXT(E3,"MMMM-YYY") -> February-2025 | F4: =TEXT(F3,"MMMM-YYY") -> March-2025 | G4: =TEXT(G3,"MMMM-YYY") -> April-2025 | H4: =TEXT(H3,"MMMM-YYY") -> May-2025 | I4: =TEXT(I3,"MMMM-YYY") -> June-2025 | J4: =TEXT(J3,"MMMM-YYY") -> July-2025 | K4: =TEXT(K3,"MMMM-YYY") -> August-2025 | L4: =TEXT(L3,"MMMM-YYY") -> September-2025 | M4: =TEXT(M3,"MMMM-YYY") -> October-2025
B5: ရပိုင်ခွင့်များ ( Assets )
B6: ငွေသားလက်ကျန်များ ( Cash ) | C6: 11 | E6: =Financial_Notes!D66 -> 58249420 | F6: =Financial_Notes!E66 -> 26125592 | G6: =Financial_Notes!F66 -> 57533472 | H6: =Financial_Notes!G66 -> 27135002 | I6: =Financial_Notes!H66 -> 1.4628264e+08 | J6: =Financial_Notes!I66 -> 3.0887052e+08 | K6: =Financial_Notes!J66 -> 44008442 | L6: =Financial_Notes!K66 -> 47056992 | M6: =Financial_Notes!L66 -> 2.5791817e+08
B7: ကုန်ပစ္စည်းရောင်းခြင်းမှ ရရန်ရှိများ ( Account Receivable ) | C7: 12 | E7: =Financial_Notes!D71 -> 0 | F7: =Financial_Notes!E71 -> 0 | G7: =Financial_Notes!F71 -> 0 | H7: =Financial_Notes!G71 -> 0 | I7: =Financial_Notes!H71 -> 0 | J7: =Financial_Notes!I71 -> 0 | K7: =Financial_Notes!J71 -> 0 | L7: =Financial_Notes!K71 -> 0 | M7: =Financial_Notes!L71 -> 0
B8: ကုန်ပစ္စည်းလက်ကျန်များ ( Inventory ) | C8: 13 | E8: =Financial_Notes!D80 -> 83741327 | F8: =Financial_Notes!E80 -> 85493925 | G8: =Financial_Notes!F80 -> 61824408 | H8: =Financial_Notes!G80 -> 62018424 | I8: =Financial_Notes!H80 -> 48853984 | J8: =Financial_Notes!I80 -> 49709541 | K8: =Financial_Notes!J80 -> 52328165 | L8: =Financial_Notes!K80 -> 39580198 | M8: =Financial_Notes!L80 -> 40815032
B9: ကြိုတင်ပေးချေထားမှုများ ( Advance Payments ) | C9: 14 | E9: =Financial_Notes!D86 -> 0 | F9: =Financial_Notes!E86 -> 0 | G9: =Financial_Notes!F86 -> 0 | H9: =Financial_Notes!G86 -> 0 | I9: =Financial_Notes!H86 -> 0 | J9: =Financial_Notes!I86 -> 0 | K9: =Financial_Notes!J86 -> 261063780 | L9: =Financial_Notes!K86 -> 267758882 | M9: =Financial_Notes!L86 -> 454383984
B10: ရွှေ့ဆိုင်းထားသော ပမာဏကုန်ကျစရိတ်များ (Deferred Preliminary Expenses) | C10: 15 | E10: =Financial_Notes!D89 -> 0 | F10: =Financial_Notes!E89 -> 0 | G10: =Financial_Notes!F89 -> 0 | H10: =Financial_Notes!G89 -> 0 | I10: =Financial_Notes!H89 -> 0 | J10: =Financial_Notes!I89 -> 0 | K10: =Financial_Notes!J89 -> 0 | L10: =Financial_Notes!K89 -> 0 | M10: =Financial_Notes!L89 -> 2034100
B11: လက်ငင်းရပိုင်ခွင့်များ၏ စုစုပေါင်းတန်ဖိုး ( Total Current Assets ) | E11: =SUM(E6:E10) -> 1.4199075e+08 | F11: =SUM(F6:F10) -> 1.1161952e+08 | G11: =SUM(G6:G10) -> 1.1935788e+08 | H11: =SUM(H6:H10) -> 89153426 | I11: =SUM(I6:I10) -> 1.9513663e+08 | J11: =SUM(J6:J10) -> 3.5858006e+08 | K11: =SUM(K6:K10) -> 3.5740039e+08 | L11: =SUM(L6:L10) -> 3.5439607e+08 | M11: =SUM(M6:M10) -> 7.5515129e+08
B13: ပုံသေပိုင်ပစ္စည်းများ ( Property Plant and Equipment ) - | C13: 16
B14: - မြေပိုင်ဆိုင်မှုများ ( Land ) | E14: =Financial_Notes!D94 -> 429290000 | F14: =Financial_Notes!E94 -> 429290000 | G14: =Financial_Notes!F94 -> 429290000 | H14: =Financial_Notes!G94 -> 429290000 | I14: =Financial_Notes!H94 -> 429290000 | J14: =Financial_Notes!I94 -> 429290000 | K14: =Financial_Notes!J94 -> 429290000 | L14: =Financial_Notes!K94 -> 429290000 | M14: =Financial_Notes!L94 -> 429290000
B15: - အဆောင်အဦးနှင့် တခြားဆက်စပ်ပိုင်ဆိုင်မှုများ ( Buildings & Structures ) | E15: =Financial_Notes!D95-Financial_Notes!D101 -> 1.1249583e+08 | F15: =Financial_Notes!E95-Financial_Notes!E101 -> 1.1194167e+08 | G15: =Financial_Notes!F95-Financial_Notes!F101 -> 1.113875e+08 | H15: =Financial_Notes!G95-Financial_Notes!G101 -> 1.1083333e+08 | I15: =Financial_Notes!H95-Financial_Notes!H101 -> 1.1027917e+08 | J15: =Financial_Notes!I95-Financial_Notes!I101 -> 1.09725e+08 | K15: =Financial_Notes!J95-Financial_Notes!J101 -> 4.2561583e+08 | L15: =Financial_Notes!K95-Financial_Notes!K101 -> 4.2506167e+08 | M15: =Financial_Notes!L95-Financial_Notes!L101 -> 4.245075e+08
B16: - စက်ယန္တရားနှင့် စက်ပစ္စည်းပိုင်ဆိုင်မှုများ ( Machinery & Equipment ) | E16: =Financial_Notes!D96-Financial_Notes!D102 -> 53680942 | F16: =Financial_Notes!E96-Financial_Notes!E102 -> 54844517 | G16: =Financial_Notes!F96-Financial_Notes!F102 -> 53016366 | H16: =Financial_Notes!G96-Financial_Notes!G102 -> 51249154 | I16: =Financial_Notes!H96-Financial_Notes!H102 -> 49540849 | J16: =Financial_Notes!I96-Financial_Notes!I102 -> 1.1588949e+08 | K16: =Financial_Notes!J96-Financial_Notes!J102 -> 1.1429317e+08 | L16: =Financial_Notes!K96-Financial_Notes!K102 -> 1.1480436e+08 | M16: =Financial_Notes!L96-Financial_Notes!L102 -> 1.134407e+08
B17: - လျှပ်စစ်နှင့် အသုံးအဆောင်ပစ္စည်းပိုင်ဆိုင်မှုများ ( Electrical & Utility Systems ) | E17: =Financial_Notes!D98-Financial_Notes!D104 -> 12298500 | F17: =Financial_Notes!E98-Financial_Notes!E104 -> 12193867 | G17: =Financial_Notes!F98-Financial_Notes!F104 -> 11787405 | H17: =Financial_Notes!G98-Financial_Notes!G104 -> 11394492 | I17: =Financial_Notes!H98-Financial_Notes!H104 -> 11014676 | J17: =Financial_Notes!I98-Financial_Notes!I104 -> 1.0267252e+08 | K17: =Financial_Notes!J98-Financial_Notes!J104 -> 1.023176e+08 | L17: =Financial_Notes!K98-Financial_Notes!K104 -> 1.0197452e+08 | M17: =Financial_Notes!L98-Financial_Notes!L104 -> 1.0164287e+08
B18: - ဆောက်လုပ်ဆဲအဆောက်အဦးပိုင်ဆိုင်မှုများ ( Construction in Progress ) | E18: =Financial_Notes!D99 -> 90334300 | F18: =Financial_Notes!E99 -> 120606300 | G18: =Financial_Notes!F99 -> 120619800 | H18: =Financial_Notes!G99 -> 160619800 | I18: =Financial_Notes!H99 -> 210619800 | J18: =Financial_Notes!I99 -> 340652800 | K18: =Financial_Notes!J99 -> 24847800 | L18: =Financial_Notes!K99 -> 24847800 | M18: =Financial_Notes!L99 -> 75792800
B19: လက်ငင်းမဟုတ်သော ရပိုင်ခွင့်များ၏ စုစုပေါင်းတန်ဖိုး ( Total Non-current Assets ) | E19: =SUM(E14:E18) -> 698099575 | F19: =SUM(F14:F18) -> 7.2887635e+08 | G19: =SUM(G14:G18) -> 7.2610107e+08 | H19: =SUM(H14:H18) -> 7.6338678e+08 | I19: =SUM(I14:I18) -> 8.1074449e+08 | J19: =SUM(J14:J18) -> 1.0982298e+09 | K19: =SUM(K14:K18) -> 1.0963644e+09 | L19: =SUM(L14:L18) -> 1.0959783e+09 | M19: =SUM(M14:M18) -> 1.1446739e+09
B20: ရပိုင်ခွင့်များ၏ စုစုပေါင်းတန်ဖိုး ( Total Assets ) | E20: =E11+E19 -> 8.4009032e+08 | F20: =F11+F19 -> 8.4049587e+08 | G20: =G11+G19 -> 8.4545895e+08 | H20: =H11+H19 -> 8.525402e+08 | I20: =I11+I19 -> 1.0058811e+09 | J20: =J11+J19 -> 1.4568099e+09 | K20: =K11+K19 -> 1.4537648e+09 | L20: =L11+L19 -> 1.4503744e+09 | M20: =M11+M19 -> 1.8998251e+09
B22: ရင်းနှီးငွေ ( Equity )
B23: ထုတ်ဝေပေးသွင်းပြီးရှယ်ယာရင်းနှီးငွေ ( Paid-up Capital ) | C23: 17 | E23: =Financial_Notes!D110 -> 8.3953082e+08 | F23: =Financial_Notes!E110 -> 8.3953082e+08 | G23: =Financial_Notes!F110 -> 8.3953082e+08 | H23: =Financial_Notes!G110 -> 8.3953082e+08 | I23: =Financial_Notes!H110 -> 9.8953082e+08 | J23: =Financial_Notes!I110 -> 1.4395308e+09 | K23: =Financial_Notes!J110 -> 1.4395308e+09 | L23: =Financial_Notes!K110 -> 1.4395308e+09 | M23: =Financial_Notes!L110 -> 1.8895308e+09
B24: ကာလအစရှိ အမြတ်လက်ကျန်များ ( Retained Earnings ) | C24: 18 | E24: =Financial_Notes!D116 -> 0 | F24: =Financial_Notes!E116 -> 559498.11 | G24: =Financial_Notes!F116 -> 965043.31 | H24: =Financial_Notes!G116 -> 5928126.5 | I24: =Financial_Notes!H116 -> 13009381 | J24: =Financial_Notes!I116 -> 16350293 | K24: =Financial_Notes!J116 -> 17279046 | L24: =Financial_Notes!K116 -> 14233969 | M24: =Financial_Notes!L116 -> 10843594
B25: ကာလအဆုံးရှိ လုပ်ငန်း၏အသားတင်အမြတ် သို့ ဆုံးရှုံးမှု ( Profit or Loss for the period ) | E25: ='Statement_of_Profit&Loss'!E27 -> 559498.11 | F25: ='Statement_of_Profit&Loss'!F27 -> 405545.2 | G25: ='Statement_of_Profit&Loss'!G27 -> 4963083.2 | H25: ='Statement_of_Profit&Loss'!H27 -> 7081254.6 | I25: ='Statement_of_Profit&Loss'!I27 -> 3340912.1 | J25: ='Statement_of_Profit&Loss'!J27 -> 928752.37 | K25: ='Statement_of_Profit&Loss'!K27 -> -3045076.8 | L25: ='Statement_of_Profit&Loss'!L27 -> -3390375.1 | M25: ='Statement_of_Profit&Loss'!M27 -> -549270.91
B26: ရင်းနှီးငွေ စုစုပေါင်းတန်ဖိုး ( Total Equity ) | E26: =SUM(E23:E25) -> 8.4009032e+08 | F26: =SUM(F23:F25) -> 8.4049587e+08 | G26: =SUM(G23:G25) -> 8.4545895e+08 | H26: =SUM(H23:H25) -> 8.525402e+08 | I26: =SUM(I23:I25) -> 1.0058811e+09 | J26: =SUM(J23:J25) -> 1.4568099e+09 | K26: =SUM(K23:K25) -> 1.4537648e+09 | L26: =SUM(L23:L25) -> 1.4503744e+09 | M26: =SUM(M23:M25) -> 1.8998251e+09
B27: Balance Check | E27: =E26-E20 -> 0 | F27: =F26-F20 -> 0 | G27: =G26-G20 -> 0 | H27: =H26-H20 -> 0 | I27: =I26-I20 -> 0 | J27: =J26-J20 -> 0 | K27: =K26-K20 -> 0 | L27: =L26-L20 -> 0 | M27: =M26-M20 -> 0

Sheet Statement_of Cashflow
B2: Period Start | E2: 45694 | F2: =E3+1 -> 45717 | G2: =F3+1 -> 45748 | H2: =G3+1 -> 45778 | I2: =H3+1 -> 45809 | J2: =I3+1 -> 45839 | K2: =J3+1 -> 45870 | L2: =K3+1 -> 45901 | M2: =L3+1 -> 45931
B3: Period End | E3: =EOMONTH(E2,0) -> 45716 | F3: =EOMONTH(F2,0) -> 45747 | G3: =EOMONTH(G2,0) -> 45777 | H3: =EOMONTH(H2,0) -> 45808 | I3: =EOMONTH(I2,0) -> 45838 | J3: =EOMONTH(J2,0) -> 45869 | K3: =EOMONTH(K2,0) -> 45900 | L3: =EOMONTH(L2,0) -> 45930 | M3: =EOMONTH(M2,0) -> 45961
B4: ငွေသားစီးဆင်းမှုရှင်းတမ်းများပေါင်းချုပ် ( Cash Flow Accounts ) | C4: Notes | E4: =TEXT(E3,"MMMM-YYY") -> February-2025 | F4: =TEXT(F3,"MMMM-YYY") -> March-2025 | G4: =TEXT(G3,"MMMM-YYY") -> April-2025 | H4: =TEXT(H3,"MMMM-YYY") -> May-2025 | I4: =TEXT(I3,"MMMM-YYY") -> June-2025 | J4: =TEXT(J3,"MMMM-YYY") -> July-2025 | K4: =TEXT(K3,"MMMM-YYY") -> August-2025 | L4: =TEXT(L3,"MMMM-YYY") -> September-2025 | M4: =TEXT(M3,"MMMM-YYY") -> October-2025
B5: လုပ်ငန်းဆောင်ရွက်ချက်များအရ ငွေသားစီးဆင်းမှုများ ( Operating Activites ) -
B6: အခွန်မဆောင်မီ အသားတင်အမြတ် ( Profit Before Tax ) | E6: ='Statement_of_Profit&Loss'!E27 -> 559498.11 | F6: ='Statement_of_Profit&Loss'!F27 -> 405545.2 | G6: ='Statement_of_Profit&Loss'!G27 -> 4963083.2 | H6: ='Statement_of_Profit&Loss'!H27 -> 7081254.6 | I6: ='Statement_of_Profit&Loss'!I27 -> 3340912.1 | J6: ='Statement_of_Profit&Loss'!J27 -> 928752.37 | K6: ='Statement_of_Profit&Loss'!K27 -> -3045076.8 | L6: ='Statement_of_Profit&Loss'!L27 -> -3390375.1 | M6: ='Statement_of_Profit&Loss'!M27 -> -549270.91
B7: ငွေသားမဟုတ်သော ကိုက်ညှိရေးဆွဲချက်များ (Non-cash items adjustment ) -
B8: - တန်ဖိုးလျှော့စရိတ်များ ( Depreication and Amortisation ) | E8: ='Statement_of_Profit&Loss'!E22 -> 945425 | F8: ='Statement_of_Profit&Loss'!F22 -> 1015225 | G8: ='Statement_of_Profit&Loss'!G22 -> 2788779.7 | H8: ='Statement_of_Profit&Loss'!H22 -> 2714291.7 | I8: ='Statement_of_Profit&Loss'!I22 -> 2642288 | J8: ='Statement_of_Profit&Loss'!J22 -> 2572685 | K8: ='Statement_of_Profit&Loss'!K22 -> 2505400 | L8: ='Statement_of_Profit&Loss'!L22 -> 2440360 | M8: ='Statement_of_Profit&Loss'!M22 -> 2377486
B9: လုပ်ငန်းလည်ပတ်ငွေပြောင်းလဲမှုများ ( Changes in Working Capital ) -
B10: - ဝယ်သူများထံမှ ရရန်ရှိများ ( Changes in Account receivable ) | E10: =Financial_Notes!D71 -> 0 | F10: =Financial_Notes!E71 -> 0 | G10: =Financial_Notes!F71 -> 0 | H10: =Financial_Notes!G71 -> 0 | I10: =Financial_Notes!H71 -> 0 | J10: =Financial_Notes!I71 -> 0 | K10: =Financial_Notes!J71 -> 0 | L10: =Financial_Notes!K71 -> 0 | M10: =Financial_Notes!L71 -> 0
B11: - ကုန်ပစ္စည်းလက်ကျန်များ ( Changes in Inventory ) | E11: =47966123.44-Financial_Notes!D80 -> -35775203 | F11: ='Statement_of_Financial Position'!E8-'Statement_of_Financial Position'!F8 -> -1752598.2 | G11: ='Statement_of_Financial Position'!F8-'Statement_of_Financial Position'!G8 -> 23669517 | H11: ='Statement_of_Financial Position'!G8-'Statement_of_Financial Position'!H8 -> -194016.24 | I11: ='Statement_of_Financial Position'!H8-'Statement_of_Financial Position'!I8 -> 13164440 | J11: ='Statement_of_Financial Position'!I8-'Statement_of_Financial Position'!J8 -> -855557.37 | K11: ='Statement_of_Financial Position'!J8-'Statement_of_Financial Position'!K8 -> -2618623.2 | L11: ='Statement_of_Financial Position'!K8-'Statement_of_Financial Position'!L8 -> 12747967 | M11: ='Statement_of_Financial Position'!L8-'Statement_of_Financial Position'!M8 -> -1234834.2
B12: - ကြိုတင်ပေးချေထားမှုများ ( Changes in Advanced Payments ) | E12: 0 | F12: ='Statement_of_Financial Position'!F9-'Statement_of_Financial Position'!E9 -> 0 | G12: ='Statement_of_Financial Position'!G9-'Statement_of_Financial Position'!F9 -> 0 | H12: ='Statement_of_Financial Position'!H9-'Statement_of_Financial Position'!G9 -> 0 | I12: ='Statement_of_Financial Position'!I9-'Statement_of_Financial Position'!H9 -> 0 | J12: ='Statement_of_Financial Position'!J9-'Statement_of_Financial Position'!I9 -> 0 | K12: =-('Statement_of_Financial Position'!K9-'Statement_of_Financial Position'!J9) -> -261063780 | L12: =-('Statement_of_Financial Position'!L9-'Statement_of_Financial Position'!K9) -> -6695102 | M12: =-('Statement_of_Financial Position'!M9-'Statement_of_Financial Position'!L9) -> -186625102
B13: - ရွှေ့ဆိုင်းထားသော ပဏာမကုန်ကျစရိတ်များ (Changes in Deferred Preliminary Expenses) | E13: 0 | F13: =-('Statement_of_Financial Position'!F10-'Statement_of_Financial Position'!E10) -> 0 | G13: =-('Statement_of_Financial Position'!G10-'Statement_of_Financial Position'!F10) -> 0 | H13: =-('Statement_of_Financial Position'!H10-'Statement_of_Financial Position'!G10) -> 0 | I13: =-('Statement_of_Financial Position'!I10-'Statement_of_Financial Position'!H10) -> 0 | J13: =-('Statement_of_Financial Position'!J10-'Statement_of_Financial Position'!I10) -> 0 | K13: =-('Statement_of_Financial Position'!K10-'Statement_of_Financial Position'!J10) -> 0 | L13: =-('Statement_of_Financial Position'!L10-'Statement_of_Financial Position'!K10) -> 0 | M13: =-('Statement_of_Financial Position'!M10-'Statement_of_Financial Position'!L10) -> -2034100
B14: လုပ်ငန်းဆောင်ရွက်ချက်များအရ အသားတင်ငွေသား (အသုံးပြုမှု)/စီးဝင်မှု ( Net Cash Flow from Operating Activities ) | E14: =SUM(E6:E13) -> -34270280 | F14: =SUM(F6:F13) -> -331828.03 | G14: =SUM(G6:G13) -> 31421380 | H14: =SUM(H6:H13) -> 9601530 | I14: =SUM(I6:I13) -> 19147640 | J14: =SUM(J6:J13) -> 2645880 | K14: =SUM(K6:K13) -> -264222080 | L14: =SUM(L6:L13) -> 5102850 | M14: =SUM(M6:M13) -> -1.8806582e+08
B16: ရင်းနှီးမြှပ်နှံမှုလုပ်ဆောင်ချက်များအရ ငွေသားစီးဆင်းမှုများ ( Investing Activites ) -
B17: - စက်ရုံတည်ဆောက်ခြင်းလုပ်ငန်းစဉ်များအတွက် ငွေသားအသုံးပြုမှုများ ( Investments in PPE - Construction in progress ) | E17: =-Financial_Notes!D99 -> -90334300 | F17: -30272000 | G17: -13500 | H17: -40000000 | I17: -50000000 | J17: -130033000 | K17: -640000 | L17: 0 | M17: -50945000
B18: - မြေယာဝယ်ယူမှု ( Land Purchase ) | E18: =219000000-Financial_Notes!D94 -> -210290000 | F18: 0 | G18: 0 | H18: 0 | I18: 0 | J18: 0 | K18: 0 | L18: 0 | M18: 0
B19: - ပုံသေပိုင်ပစ္စည်းဝယ်ယူမှု ( Fixed Asset Purchase ) | E19: -6856000 | F19: -1520000 | G19: 0 | H19: 0 | I19: 0 | J19: -160025000 | K19: 0 | L19: -2054300 | M19: -128000
B20: ရင်းနှီးမြှပ်နှံမှုလုပ်ဆောင်ချက်များအရ အသားတင် (အသုံးပြုမှု)/စီးဝင်မှု ( Net Cash Flow from Investing Activities ) | E20: =SUM(E17:E19) -> -307480300 | F20: =SUM(F17:F19) -> -31792000 | G20: =SUM(G17:G19) -> -13500 | H20: =SUM(H17:H19) -> -40000000 | I20: =SUM(I17:I19) -> -50000000 | J20: =SUM(J17:J19) -> -290058000 | K20: =SUM(K17:K19) -> -640000 | L20: =SUM(L17:L19) -> -2054300 | M20: =SUM(M17:M19) -> -51073000
B22: ဘဏ္ဍာရေးဆောင်ရွက်များအရ အသားတင်ငွေသား အသုံးပြုမှု ( Financing Activites ) -
B23: အစုရှယ်ယာထုတ်ဝေရောင်းချခြင်းမှ ရငွေ ( Proceeds from issuance of ordinary shares ) | E23: 400000000 | F23: 0 | G23: 0 | H23: 0 | I23: 150000000 | J23: 450000000 | K23: 0 | L23: 0 | M23: 450000000
B24: ဘဏ္ဍာရေးဆောင်ရွက်များအရ အသားတင်ငွေသား (အသုံးပြုမှု)/စီးဝင်မှု ( Net Cash Flow from Investing Activities ) | E24: =E23 -> 400000000 | F24: =F23 -> 0 | G24: =G23 -> 0 | H24: =H23 -> 0 | I24: =I23 -> 150000000 | J24: =J23 -> 450000000 | K24: =K23 -> 0 | L24: =L23 -> 0 | M24: =M23 -> 450000000
B26: ငွေသားလက်ကျန်များ အသားတင် (အလျော့)/အတိုး ( Net Changes in Cash During the Period ) | E26: =E14+E20+E24 -> 58249420 | F26: =F14+F20+F24 -> -32123828 | G26: =G14+G20+G24 -> 31407880 | H26: =H14+H20+H24 -> -30398470 | I26: =I14+I20+I24 -> 119147640 | J26: =J14+J20+J24 -> 162587880 | K26: =K14+K20+K24 -> -264862080 | L26: =L14+L20+L24 -> 3048550 | M26: =M14+M20+M24 -> 2.1086118e+08
B27: ကာလအစရှိ ငွေသားလက်ကျန်များ ( Cash at the beginning ) | E27: 0 | F27: =E28 -> 58249420 | G27: =F28 -> 26125592 | H27: =G28 -> 57533472 | I27: =H28 -> 27135002 | J27: =I28 -> 1.4628264e+08 | K27: =J28 -> 3.0887052e+08 | L27: =K28 -> 44008442 | M27: =L28 -> 47056992
B28: ကာလအဆုံးရှိ ငွေသားလက်ကျန်များ ( Cash at the end of the period ) | E28: =E26+E27 -> 58249420 | F28: =F26+F27 -> 26125592 | G28: =G26+G27 -> 57533472 | H28: =H26+H27 -> 27135002 | I28: =I26+I27 -> 1.4628264e+08 | J28: =J26+J27 -> 3.0887052e+08 | K28: =K26+K27 -> 44008442 | L28: =L26+L27 -> 47056992 | M28: =M26+M27 -> 2.5791817e+08
B29: Check | E29: =E28='Statement_of_Financial Position'!E6 -> TRUE | F29: =F28='Statement_of_Financial Position'!F6 -> TRUE | G29: =G28='Statement_of_Financial Position'!G6 -> TRUE | H29: =H28='Statement_of_Financial Position'!H6 -> TRUE | I29: =I28='Statement_of_Financial Position'!I6 -> TRUE | J29: =J28='Statement_of_Financial Position'!J6 -> TRUE | K29: =K28='Statement_of_Financial Position'!K6 -> TRUE | L29: =L28='Statement_of_Financial Position'!L6 -> TRUE | M29: =M28='Statement_of_Financial Position'!M6 -> TRUE

Sheet Financial_Notes
B2: Note
B3: 1 | C3: Revenue
D4: Feb_2025 | E4: Mar_2025 | F4: April_2025 | G4: May_2025 | H4: June_2025 | I4: July_2025 | J4: Aug_2025 | K4: Sep_2025 | L4: Oct_2025
C5: Sales Revenue | D5: 12876000 | E5: 38186000 | F5: 52160000 | G5: 57481000 | H5: 33478500 | I5: 19774500 | J5: 19759500 | K5: 25669100 | L5: 21894000
D6: =SUM(D5:D5) -> 12876000 | E6: =SUM(E5:E5) -> 38186000 | F6: =SUM(F5:F5) -> 52160000 | G6: =SUM(G5:G5) -> 57481000 | H6: =SUM(H5:H5) -> 33478500 | I6: =SUM(I5:I5) -> 19774500 | J6: =SUM(J5:J5) -> 19759500 | K6: =SUM(K5:K5) -> 25669100 | L6: =SUM(L5:L5) -> 21894000
B9: 2 | C9: COGS
D10: Feb_2025 | E10: Mar_2025 | F10: April_2025 | G10: May_2025 | H10: June_2025 | I10: July_2025 | J10: Aug_2025 | K10: Sep_2025 | L10: Oct_2025
C11: Opening Inventory - Raw Materials | D11: 5605177.4 | E11: 9965463.8 | F11: 8136940.8 | G11: 8212072.4 | H11: 5597336.1 | I11: 5914124 | J11: 4790395.1 | K11: 7190701 | L11: 6515831.8
C12: Opening Inventory - Packaging | D12: 7899300 | E12: 22801950 | F12: 24876371 | G12: 23855351 | H12: 22235469 | I12: 9216388 | J12: 7452014.8 | K12: 12692758 | L12: 15343618
C13: Opening Inventory - Work-in-Progress
C14: Opening Inventory - Finished Goods | D14: 34461646 | E14: 50973913 | F14: 52480613 | G14: 29756984 | H14: 34185619 | I14: 33723472 | J14: 37467131 | K14: 32444705 | L14: 17720747
C15: Purchases Raw Materials | D15: 9393050 | E15: 18487471 | F15: 3821200 | G15: 7719100 | H15: 5392060 | I15: 2408379 | J15: 5239371 | K15: 318000 | L15: 6671900
C16: Purchases Packaging | D16: 35553030 | E16: 18273130 | F16: 14210300 | G16: 37619370 | H16: 7693800 | I16: 12550941 | J16: 16236429 | K16: 9574250 | L16: 11393950
C17: Closing Inventory - Raw Materials | D17: -9965463.8 | E17: -8136940.8 | F17: -8212072.4 | G17: -5597336.1 | H17: -5914124.1 | I17: -4790395.1 | J17: -7190701.1 | K17: -6515831.8 | L17: -8507511.8
C18: Closing Inventory - Packaging | D18: -22801950 | E18: -24876371 | F18: -23855351 | G18: -22235469 | H18: -9216388.4 | I18: -7452014.8 | J18: -14422497 | K18: -16684096 | L18: -8810565.5
C19: Closing Inventory - Work-in-Progress
C20: Closing Inventory - Finished Goods | D20: -50973913 | E20: -53694312 | F20: -29756984 | G20: -34185619 | H20: -33723472 | I20: -37467131 | J20: -32444705 | K20: -17720747 | L20: -23496954
C21: Direct Labor Wages | D21: 1810000 | E21: 1650000 | F21: 1650000 | G21: 1745000 | H21: 1245000 | I21: 1400000 | J21: 1400000 | K21: 1710000 | L21: 2240000
C22: Machine Maintenance & Repair Expense | D22: 62900 | E22: 0 | F22: 59000 | G22: 213000 | H22: 0 | I22: 0 | J22: 42000 | K22: 1994000 | L22: 441000
C23: Production Utilities (Electricity & Water) | D23: 243300 | E23: 0 | F23: 0 | G23: 0 | H23: 0 | I23: 759300 | J23: 0 | K23: 0 | L23: 977600
C24: Depreciation Expenses - COGS | D24: 343758.33 | E24: 356425 | F24: 1828151 | G24: 1767212 | H24: 1708305 | I24: 1651362 | J24: 1596316 | K24: 1543106 | L24: 1491669
D25: =SUM(D11:D24) -> 11630835 | E25: =SUM(E11:E24) -> 35800729 | F25: =SUM(F11:F24) -> 45238168 | G25: =SUM(G11:G24) -> 48869666 | H25: =SUM(H11:H24) -> 29203605 | I25: =SUM(I11:I24) -> 17914425 | J25: =SUM(J11:J24) -> 20165754 | K25: =SUM(K11:K24) -> 26546845 | L25: =SUM(L11:L24) -> 21981285
B28: 3 | C28: SG&A
D29: Feb_2025 | E29: Mar_2025 | F29: April_2025 | G29: May_2025 | H29: June_2025 | I29: July_2025 | J29: Aug_2025 | K29: Sep_2025 | L29: Oct_2025
C30: Marketing & Advertising Expense | D30: 84000 | E30: 0 | F30: 0 | G30: 0 | H30: 0 | I30: 0 | J30: 0 | K30: 0 | L30: 0
C31: Office Salaries | D31: 0 | E31: 0 | F31: 0 | G31: 0 | H31: 0 | I31: 0 | J31: 0 | K31: 0 | L31: 0
C32: Meal Allowance Expense | D32: 0 | E32: 0 | F32: 0 | G32: 0 | H32: 0 | I32: 0 | J32: 0 | K32: 0 | L32: 0
C33: Utilities (Electricity & Water) | D33: 0 | E33: 0 | F33: 0 | G33: 0 | H33: 0 | I33: 0 | J33: 0 | K33: 0 | L33: 0
C34: Transportation & Distribution Expense | D34: 0 | E34: 0 | F34: 0 | G34: 0 | H34: 0 | I34: 0 | J34: 0 | K34: 0 | L34: 0
C35: Factory Buildings & Office Supplies and Maintenance | D35: 0 | E35: 0 | F35: 1146150 | G35: 583000 | H35: 0 | I35: 10000 | J35: 0 | K35: 274898 | L35: 394898
C36: Depreciation Expenses - SG&A | D36: 601666.67 | E36: 658800 | F36: 960628.67 | G36: 947079.67 | H36: 933983 | I36: 921323 | J36: 909084 | K36: 897254 | L36: 885817
C37: Inventory Write-off | D37: 0 | E37: 0 | F37: 0 | G37: 0 | H37: 0 | I37: 0 | J37: 1729738.5 | K37: 1340478 | L37: 0
C38: Other Expenses | D38: 0 | E38: 0 | F38: 200000 | G38: 0 | H38: 0 | I38: 0 | J38: 0 | K38: 0 | L38: 0
C39: Key Managment Personnel and Director Compensation | D39: 0 | E39: 107227.03 | F39: 0 | G39: 0 | H39: 0 | I39: 0 | J39: 0 | K39: 0 | L39: 0
D40: =SUM(D30:D39) -> 685666.67 | E40: =SUM(E30:E39) -> 766027.03 | F40: =SUM(F30:F39) -> 2306778.7 | G40: =SUM(G30:G39) -> 1530079.7 | H40: =SUM(H30:H39) -> 933983 | I40: =SUM(I30:I39) -> 931323 | J40: =SUM(J30:J39) -> 2638822.5 | K40: =SUM(K30:K39) -> 2512630 | L40: =SUM(L30:L39) -> 1280715
B43: 4 | C43: Depreication & Amortisation | D43: Feb_2025 | E43: Mar_2025 | F43: April_2025 | G43: May_2025 | H43: June_2025 | I43: July_2025 | J43: Aug_2025 | K43: Sep_2025 | L43: Sep_2025
C44: Depreciation Expenses - COGS | D44: 343758.33 | E44: 356425 | F44: 1828151 | G44: 1767212 | H44: 1708305 | I44: 1651362 | J44: 1596316 | K44: 1543106 | L44: 1491669
C45: Depreciation Expenses - SG&A | D45: 601666.67 | E45: 658800 | F45: 960628.67 | G45: 947079.67 | H45: 933983 | I45: 921323 | J45: 909084 | K45: 897254 | L45: 885817
D46: =SUM(D44:D45) -> 945425 | E46: =SUM(E44:E45) -> 1015225 | F46: =SUM(F44:F45) -> 2788779.7 | G46: =SUM(G44:G45) -> 2714291.7 | H46: =SUM(H44:H45) -> 2642288 | I46: =SUM(I44:I45) -> 2572685 | J46: =SUM(J44:J45) -> 2505400 | K46: =SUM(K44:K45) -> 2440360 | L46: =SUM(L44:L45) -> 2377486
B49: 5 | C49: Other Income
...

Sheet Sheet4
B4: Account | C4: February-2025 | D4: March-2025 | E4: April-2025 | F4: May-2025 | G4: June-2025 | H4: July-2025 | I4: August-2025 | J4: September-2025 | K4: October-2025
B5: ဝင်ငွေ ( Revenue ) | C5: 12876000 | D5: 38186000 | E5: 52160000 | F5: 57481000 | G5: 33478500 | H5: 19774500 | I5: 19759500 | J5: 25669100 | K5: 21894000
B6: အခွန်မလျာထားမီ အမြတ် ( Profit Before Tax ) | C6: 559498.11 | D6: 405545.2 | E6: 4963083.2 | F6: 7081254.6 | G6: 3340912.1 | H6: 928752.37 | I6: -3045076.8 | J6: -3390375.1 | K6: -549270.91
B7: အခွန်မလျာထားမီ အမြတ်အစွန်း % ( Profit Before Tax Margin % ) | C7: 0.043452789 | D7: 0.010620259 | E7: 0.095151135 | F7: 0.12319296 | G7: 0.099792766 | H7: 0.046967173 | I7: -0.15410698 | J7: -0.13208001 | K7: -0.025087737

Sheet Copy of Monthly P&L
B2: YOUR COMPANY NAME | Q2: Monthly Profit and Loss Statement
Q3: For the Year Ended MM/DD/YYYY
B7: Show Categories
B8: TRUE | C8: =PROPER(B24) -> Revenue
B10: TRUE | C10: =PROPER(B25) -> Cost Of Goods Sold
B12: TRUE | C12: =PROPER(B26) -> Total Expenses
B14: TRUE | C14: =PROPER(B27) -> Net Profit / Loss
B17: CATEGORY | D17: =E23 -> FEB | E17: =F23 -> MAR | F17: =G23 -> APR | G17: =H23 -> MAY | H17: =I23 -> JUN | I17: =J23 -> JUL | J17: =K23 -> AUG | K17: =L23 -> SEP | ... O17: =P23 -> JAN
B18: Revenue | D18: 87137 | E18: 50964 | F18: 86259 | G18: 79607 | H18: 71341 | I18: 88114 | J18: 59503 | K18: 64060 | L18: 71160 | M18: 60826 | N18: 52063 | O18: 69167
B19: Cost Of Goods Sold | D19: 33324 | E19: 26542 | F19: 41047 | G19: 29883 | H19: 45828 | I19: 40046 | J19: 38135 | K19: 36655 | L19: 40328 | M19: 32649 | N19: 48086 | O19: 48494
B20: Total Expenses | D20: 18170 | E20: 17385 | F20: 16587 | G20: 18128 | H20: 18608 | I20: 16934 | J20: 16446 | K20: 17697 | L20: 18155 | M20: 17847 | N20: 17832 | O20: 19582
B21: Net Profit / Loss | D21: 35643 | E21: 7037 | F21: 28625 | G21: 31596 | H21: 6905 | I21: 31134 | J21: 4922 | K21: 9708 | L21: 12677 | M21: 10330 | N21: -13855 | O21: 1091
B23: CATEGORY | D23: TREND | E23: FEB | F23: MAR | G23: APR | H23: MAY | I23: JUN | J23: JUL | K23: AUG | L23: SEP | M23: OCT | N23: NOV | O23: DEC | P23: JAN | Q23: YTD
B24: REVENUE | D24: =IFERROR(__xludf.DUMMYFUNCTION("IFERROR(SPARKLINE(E24:P24, {""charttype"",""line"";""color"",""#0000FF"";""empty"",""ignore"";""nan"",""convert""}))"),"") | E24: =E34 -> 87137 | F24: =F34 -> 50964 | G24: =G34 -> 86259 | H24: =H34 -> 79607 | I24: =I34 -> 71341 | J24: =J34 -> 88114 | K24: =K34 -> 59503 | L24: =L34 -> 64060 | ... P24: =P34 -> 69167 | Q24: =SUM(E24:P24) -> 840201
B25: COST OF GOODS SOLD | D25: =IFERROR(__xludf.DUMMYFUNCTION("IFERROR(SPARKLINE(E25:P25, {""charttype"",""line"";""color"",""#FF0000"";""empty"",""ignore"";""nan"",""convert""}))"),"") | E25: =E44 -> 33324 | F25: =F44 -> 26542 | G25: =G44 -> 41047 | H25: =H44 -> 29883 | I25: =I44 -> 45828 | J25: =J44 -> 40046 | K25: =K44 -> 38135 | L25: =L44 -> 36655 | ... P25: =P44 -> 48494 | Q25: =SUM(E25:P25) -> 461017
B26: TOTAL EXPENSES | D26: =IFERROR(__xludf.DUMMYFUNCTION("IFERROR(SPARKLINE(E26:P26, {""charttype"",""line"";""color"",""#FF0000"";""empty"",""ignore"";""nan"",""convert""}))"),"") | E26: =E61 -> 18170 | F26: =F61 -> 17385 | G26: =G61 -> 16587 | H26: =H61 -> 18128 | I26: =I61 -> 18608 | J26: =J61 -> 16934 | K26: =K61 -> 16446 | L26: =L61 -> 17697 | ... Q26: =Q61 -> 213371
B27: NET PROFIT / LOSS | D27: =IFERROR(__xludf.DUMMYFUNCTION("IFERROR(SPARKLINE(E27:P27, {""charttype"",""line"";""color"",""#0000FF"";""empty"",""ignore"";""nan"",""convert""}))"),"") | E27: =E63 -> 35643 | F27: =F63 -> 7037 | G27: =G63 -> 28625 | H27: =H63 -> 31596 | I27: =I63 -> 6905 | J27: =J63 -> 31134 | K27: =K63 -> 4922 | L27: =L63 -> 9708 | ... Q27: =Q63 -> 165813
B29: REVENUE | D29: TREND | E29: FEB | F29: MAR | G29: APR | H29: MAY | I29: JUN | J29: JUL | K29: AUG | L29: SEP | M29: OCT | N29: NOV | O29: DEC | P29: JAN | Q29: YTD
B30: Sales Revenue | D30: =IFERROR(__xludf.DUMMYFUNCTION("IFERROR(SPARKLINE(E30:P30, {""charttype"",""line"";""color"",""#0000FF"";""empty"",""ignore"";""nan"",""convert""}))"),"") | E30: 89297 | F30: 51817 | G30: 85600 | H30: 80295 | I30: 72998 | J30: 87088 | K30: 61207 | L30: 65849 | M30: 71072 | N30: 61317 | O30: 51889 | P30: 66560 | Q30: =SUM(E30:P30) -> 844989
B31: Other Revenue | D31: =IFERROR(__xludf.DUMMYFUNCTION("IFERROR(SPARKLINE(E31:P31, {""charttype"",""line"";""color"",""#0000FF"";""empty"",""ignore"";""nan"",""convert""}))"),"") | E31: 6857 | F31: 7684 | G31: 8962 | H31: 7541 | I31: 6804 | J31: 7376 | K31: 6711 | L31: 5743 | M31: 6303 | N31: 7988 | O31: 7786 | P31: 9786 | Q31: =SUM(E31:P31) -> 89541
B32: Sales Discounts | D32: =IFERROR(__xludf.DUMMYFUNCTION("IFERROR(SPARKLINE(E32:P32, {""charttype"",""line"";""color"",""#FF0000"";""empty"",""ignore"";""nan"",""convert""}))"),"") | E32: -4609 | F32: -4091 | G32: -3785 | H32: -3876 | I32: -4669 | J32: -3339 | K32: -4909 | L32: -3667 | M32: -3013 | N32: -3668 | O32: -4578 | P32: -3476 | Q32: =SUM(E32:P32) -> -47680
B33: Sales Returns, allowances and others | D33: =IFERROR(__xludf.DUMMYFUNCTION("IFERROR(SPARKLINE(E33:P33, {""charttype"",""line"";""color"",""#FF0000"";""empty"",""ignore"";""nan"",""convert""}))"),"") | E33: -4408 | F33: -4446 | G33: -4518 | H33: -4353 | I33: -3792 | J33: -3011 | K33: -3506 | L33: -3865 | M33: -3202 | N33: -4811 | O33: -3034 | P33: -3703 | Q33: =SUM(E33:P33) -> -46649
B34: ="TOTAL "&C29 -> TOTAL | D34: =IFERROR(__xludf.DUMMYFUNCTION("IFERROR(SPARKLINE(E34:P34, {""charttype"",""line"";""color"",""#0000FF"";""empty"",""ignore"";""nan"",""convert""}))"),"") | E34: =SUM(E30:E33) -> 87137 | F34: =SUM(F30:F33) -> 50964 | G34: =SUM(G30:G33) -> 86259 | H34: =SUM(H30:H33) -> 79607 | I34: =SUM(I30:I33) -> 71341 | J34: =SUM(J30:J33) -> 88114 | K34: =SUM(K30:K33) -> 59503 | L34: =SUM(L30:L33) -> 64060 | ... Q34: =SUM(Q30:Q33) -> 840201
B36: COST OF GOODS SOLD | D36: TREND | E36: FEB | F36: MAR | G36: APR | H36: MAY | I36: JUN | J36: JUL | K36: AUG | L36: SEP | M36: OCT | N36: NOV | O36: DEC | P36: JAN | Q36: YTD
B37: Cost of raw materials | D37: =IFERROR(__xludf.DUMMYFUNCTION("IFERROR(SPARKLINE(E37:P37, {""charttype"",""line"";""color"",""#FF0000"";""empty"",""ignore"";""nan"",""convert""}))"),"") | E37: 6719 | F37: 1884 | G37: 7489 | H37: 7037 | I37: 8340 | J37: 8883 | K37: 3176 | L37: 2715 | M37: 7862 | N37: 4710 | O37: 4158 | P37: 9662 | Q37: =SUM(E37:P37) -> 72635
B38: Cost of parts used | D38: =IFERROR(__xludf.DUMMYFUNCTION("IFERROR(SPARKLINE(E38:P38, {""charttype"",""line"";""color"",""#FF0000"";""empty"",""ignore"";""nan"",""convert""}))"),"") | E38: 6851 | F38: 6443 | G38: 5265 | H38: 3580 | I38: 7785 | J38: 6300 | K38: 1382 | L38: 9373 | M38: 9652 | N38: 3355 | O38: 2023 | P38: 5143 | Q38: =SUM(E38:P38) -> 67152
B39: Direct labor costs | D39: =IFERROR(__xludf.DUMMYFUNCTION("IFERROR(SPARKLINE(E39:P39, {""charttype"",""line"";""color"",""#FF0000"";""empty"",""ignore"";""nan"",""convert""}))"),"") | E39: 3189 | F39: 3753 | G39: 3192 | H39: 1533 | I39: 7499 | J39: 3980 | K39: 7884 | L39: 9727 | M39: 5852 | N39: 6705 | O39: 9774 | P39: 6065 | Q39: =SUM(E39:P39) -> 69153
B40: Overhead costs | D40: =IFERROR(__xludf.DUMMYFUNCTION("IFERROR(SPARKLINE(E40:P40, {""charttype"",""line"";""color"",""#FF0000"";""empty"",""ignore"";""nan"",""convert""}))"),"") | E40: 3499 | F40: 5245 | G40: 6343 | H40: 5148 | I40: 2413 | J40: 6877 | K40: 7859 | L40: 2460 | M40: 3712 | N40: 7415 | O40: 9736 | P40: 7735 | Q40: =SUM(E40:P40) -> 68442
B41: Inventory Adjustments | D41: =IFERROR(__xludf.DUMMYFUNCTION("IFERROR(SPARKLINE(E41:P41, {""charttype"",""line"";""color"",""#FF0000"";""empty"",""ignore"";""nan"",""convert""}))"),"") | E41: 2487 | F41: 4367 | G41: 8972 | H41: 3694 | I41: 8480 | J41: 4447 | K41: 8393 | L41: 2514 | M41: 2780 | N41: 4581 | O41: 5776 | P41: 4491 | Q41: =SUM(E41:P41) -> 60982
B42: Freight and Shipping | D42: =IFERROR(__xludf.DUMMYFUNCTION("IFERROR(SPARKLINE(E42:P42, {""charttype"",""line"";""color"",""#FF0000"";""empty"",""ignore"";""nan"",""convert""}))"),"") | E42: 6386 | F42: 1698 | G42: 3679 | H42: 3804 | I42: 8444 | J42: 5668 | K42: 4213 | L42: 5510 | M42: 9444 | N42: 2250 | O42: 6882 | P42: 9579 | Q42: =SUM(E42:P42) -> 67557
B43: Depreciation | D43: =IFERROR(__xludf.DUMMYFUNCTION("IFERROR(SPARKLINE(E43:P43, {""charttype"",""line"";""color"",""#FF0000"";""empty"",""ignore"";""nan"",""convert""}))"),"") | E43: 4193 | F43: 3152 | G43: 6107 | H43: 5087 | I43: 2867 | J43: 3891 | K43: 5228 | L43: 4356 | M43: 1026 | N43: 3633 | O43: 9737 | P43: 5819 | Q43: =SUM(E43:P43) -> 55096
B44: ="TOTAL "&C36 -> TOTAL | D44: =IFERROR(__xludf.DUMMYFUNCTION("IFERROR(SPARKLINE(E44:P44, {""charttype"",""line"";""color"",""#FF0000"";""empty"",""ignore"";""nan"",""convert""}))"),"") | E44: =SUM(E37:E43) -> 33324 | F44: =SUM(F37:F43) -> 26542 | G44: =SUM(G37:G43) -> 41047 | H44: =SUM(H37:H43) -> 29883 | I44: =SUM(I37:I43) -> 45828 | J44: =SUM(J37:J43) -> 40046 | K44: =SUM(K37:K43) -> 38135 | L44: =SUM(L37:L43) -> 36655 | ... Q44: =SUM(Q37:Q43) -> 461017
B46: GROSS PROFIT/LOSS | D46: =IFERROR(__xludf.DUMMYFUNCTION("IFERROR(SPARKLINE(E46:P46, {""charttype"",""line"";""color"",""#0000FF"";""empty"",""ignore"";""nan"",""convert""}))"),"") | E46: =E34-E44 -> 53813 | F46: =F34-F44 -> 24422 | G46: =G34-G44 -> 45212 | H46: =H34-H44 -> 49724 | I46: =I34-I44 -> 25513 | J46: =J34-J44 -> 48068 | K46: =K34-K44 -> 21368 | L46: =L34-L44 -> 27405 | ... Q46: =Q34-Q44 -> 379184
B48: EXPENSES | D48: TREND | E48: JAN | F48: FEB | G48: MAR | H48: APR | I48: MAY | J48: JUN | K48: JUL | L48: AUG | M48: SEP | N48: OCT | O48: NOV | P48: DEC | Q48: YTD
B49: Automobile | D49: =IFERROR(__xludf.DUMMYFUNCTION("IFERROR(SPARKLINE(E49:P49, {""charttype"",""line"";""color"",""#FF0000"";""empty"",""ignore"";""nan"",""convert""}))"),"") | E49: 1951 | F49: 1114 | G49: 1619 | H49: 1862 | I49: 1027 | J49: 1105 | K49: 1872 | L49: 1167 | M49: 1053 | N49: 1111 | O49: 1335 | P49: 1682 | Q49: =SUM(E49:P49) -> 16898
B50: Rented Equipment | D50: =IFERROR(__xludf.DUMMYFUNCTION("IFERROR(SPARKLINE(E50:P50, {""charttype"",""line"";""color"",""#FF0000"";""empty"",""ignore"";""nan"",""convert""}))"),"") | E50: 1227 | F50: 1794 | G50: 1548 | H50: 1796 | I50: 1209 | J50: 1828 | K50: 1390 | L50: 1846 | M50: 1704 | N50: 1900 | O50: 1087 | P50: 1749 | Q50: =SUM(E50:P50) -> 19078
B51: Insurance | D51: =IFERROR(__xludf.DUMMYFUNCTION("IFERROR(SPARKLINE(E51:P51, {""charttype"",""line"";""color"",""#FF0000"";""empty"",""ignore"";""nan"",""convert""}))"),"") | E51: 1442 | F51: 1537 | G51: 1238 | H51: 1836 | I51: 1981 | J51: 1219 | K51: 1244 | L51: 1596 | M51: 1270 | N51: 1288 | O51: 1935 | P51: 1975 | Q51: =SUM(E51:P51) -> 18561
B52: Job expenses | D52: =IFERROR(__xludf.DUMMYFUNCTION("IFERROR(SPARKLINE(E52:P52, {""charttype"",""line"";""color"",""#FF0000"";""empty"",""ignore"";""nan"",""convert""}))"),"") | E52: 1157 | F52: 1389 | G52: 1033 | H52: 1177 | I52: 1825 | J52: 1950 | K52: 1252 | L52: 1417 | M52: 1050 | N52: 1585 | O52: 1227 | P52: 1613 | Q52: =SUM(E52:P52) -> 16675
B53: Legal and Professional Fees | D53: =IFERROR(__xludf.DUMMYFUNCTION("IFERROR(SPARKLINE(E53:P53, {""charttype"",""line"";""color"",""#FF0000"";""empty"",""ignore"";""nan"",""convert""}))"),"") | E53: 1639 | F53: 1035 | G53: 1408 | H53: 1039 | I53: 1218 | J53: 1472 | K53: 1024 | L53: 1185 | M53: 1743 | N53: 1316 | O53: 1934 | P53: 1893 | Q53: =SUM(E53:P53) -> 16906
B54: Maintenance and Repair | D54: =IFERROR(__xludf.DUMMYFUNCTION("IFERROR(SPARKLINE(E54:P54, {""charttype"",""line"";""color"",""#FF0000"";""empty"",""ignore"";""nan"",""convert""}))"),"") | E54: 1799 | F54: 1936 | G54: 1118 | H54: 1305 | I54: 1194 | J54: 1519 | K54: 1008 | L54: 1001 | M54: 1919 | N54: 1213 | O54: 1055 | P54: 1896 | Q54: =SUM(E54:P54) -> 16963
...
