Workbook

Sheet Feb_2025
B1: Period | C1: =TEXT(C3,"MMMM-YYY") -> February-2025
B2: Start | C2: 45689 | E2: Balance Check | F2: =IF(SUM(D:D) = SUM(E:E), "✅ Balanced", "⚠️ Unbalanced") -> ✅ Balanced
B3: End | C3: =EOMONTH(C2,0) -> 45716
D5: =SUM(D8:D1001) -> 9.0015545e+08 | E5: =SUM(E8:E1001) -> 9.0015545e+08 | F5: =D5-E5 -> 0
A7: Account Name | B7: COA Account Number | C7: Opening Balance (MMK) | D7: Debits (MMK) | E7: Credits (MMK) | F7: Ending Balance (MMK)
A8: Cash in hand | B8: 10000 | C8: 0 | F8: =C8+D8-E8 -> 0
A9: Cash at Bank | B9: 10100 | C9: 0 | D9: 412876000 | E9: 354626580 | F9: =C9+D9-E9 -> 58249420
A10: Accounts Receivable | B10: 11000 | C10: 0 | F10: =C10+D10-E10 -> 0
A11: Inventory - Raw Material | B11: 12000 | C11: 5605177 | D11: 9965463.8 | E11: 5605177.4 | F11: =C11+D11-E11 -> 9965463.3
A12: Inventory - Packaging | B12: 12100 | C12: 7899300 | D12: 22801950 | E12: 7899300 | F12: =C12+D12-E12 -> 22801950
A13: Inventory - Finished Goods | B13: 12200 | C13: 34461646 | D13: 50973913 | E13: 34461646 | F13: =C13+D13-E13 -> 50973913 | H13: COGS per box - 6593 MMK
A14: Inventory Adjustments | B14: 12300 | C14: 0 | F14: =C14+D14-E14 -> 0
A15: Advanced Payments | B15: 13000 | C15: 0 | F15: =C15+D15-E15 -> 0
A16: Land | B16: 15000 | C16: 219000000 | D16: 210290000 | E16: 0 | F16: =C16+D16-E16 -> 429290000
A17: Buildings & Structures | B17: 15100 | C17: 133000000 | F17: =C17+D17-E17 -> 133000000
A18: Machinery & Equipment | B18: 15200 | C18: 66400000 | F18: =C18+D18-E18 -> 66400000
A19: Office & Facility Equipment | B19: 15300 | C19: 0 | F19: =C19+D19-E19 -> 0
A20: Electrical & Utility Systems | B20: 15400 | C20: 7200000 | D20: 6856000 | E20: 0 | F20: =C20+D20-E20 -> 14056000
A21: Construction in Progress | B21: 15500 | C21: 0 | D21: 90334300 | E21: 0 | F21: =C21+D21-E21 -> 90334300
A22: Motor Vehicles | B22: 15600 | C22: 0 | F22: =C22+D22-E22 -> 0 | J22: =SUM(F16:F20)-SUM(F22:F25) -> 609522775
A23: Accumulated Depreciation - Buildings & Structures | B23: 15110 | C23: 19950000 | D23: 0 | E23: 554166.67 | F23: =C23+E23-D23 -> 20504167
A24: Accumulated Depreciation - Machinery & Equipment | B24: 15210 | C24: 12375300 | D24: 0 | E24: 343758.33 | F24: =C24+E24-D24 -> 12719058
A25: Accumulated Depreciation - Office & Facility Equipment | B25: 15310 | C25: 0 | F25: =C25+E25-D25 -> 0
A26: Accumulated Depreciation - Electrical & Utility Systems | B26: 15410 | C26: 1710000 | D26: 0 | E26: 47500 | F26: =C26+E26-D26 -> 1757500
A27: Accumulated Depreciation - Motor Vehicles | B27: 15610 | C27: 0 | F27: =C27+E27-D27 -> 0
A28: Deferred Preliminary Expenses | B28: 14000 | C28: 0 | F28: =C28+D28-E28 -> 0
A29: Accounts Payable | B29: 20000 | C29: 0 | F29: =C29+E29-D29 -> 0
A30: Short-term Loans | B30: 21000 | C30: 0 | F30: =C30+E30-D30 -> 0
A31: Utility Bills | B31: 22000 | C31: 0 | F31: =C31+E31-D31 -> 0
A32: Provision for Managment Compensation | B32: 22100 | C32: 0 | F32: =C32+E32-D32 -> 0
A33: Wages Payable | B33: 22200 | C33: 0 | F33: =C33+E33-D33 -> 0
A34: Bank Loan | B34: 25000 | C34: 0 | F34: =C34+E34-D34 -> 0
A35: Paid-up Capital | B35: 31000 | C35: 439530823 | D35: 0 | E35: 400000000 | F35: =C35+E35-D35 -> 839530823
A36: Retained Earnings | B36: 32000 | F36: =C36+E36-D36 -> 0
A37: Sales Revenue | B37: 40000 | C37: 0 | D37: 0 | E37: 12876000 | F37: =C37+E37-D37 -> 12876000
A38: Opening Inventory - Raw Materials | B38: 50000 | C38: 0 | D38: 5605177.4 | E38: 0 | F38: =C38+D38-E38 -> 5605177.4
A39: Opening Inventory - Packaging | B39: 50100 | C39: 0 | D39: 7899300 | E39: 0 | F39: =C39+D39-E39 -> 7899300
A40: Opening Inventory - Finished Goods | B40: 50200 | C40: 0 | D40: 34461646 | E40: 0 | F40: =C40+D40-E40 -> 34461646
A41: Purchases Raw Materials | B41: 50010 | C41: 0 | D41: 9393050 | E41: 0 | F41: =C41+D41-E41 -> 9393050
A42: Purchases Packaging | B42: 50110 | C42: 0 | D42: 35553030 | E42: 0 | F42: =C42+D42-E42 -> 35553030
...

Sheet Mar_2025
B1: Period | C1: =TEXT(C3,"MMMM-YYY") -> March-2025
B2: Start | C2: 45717 | E2: Balance Check | F2: =IF(SUM(D:D) = SUM(E:E), "✅ Balanced", "⚠️ Unbalanced") -> ✅ Balanced
B3: End | C3: =EOMONTH(C2,0) -> 45747
D5: =SUM(D8:D1001) -> 2.811737e+08 | E5: =SUM(E8:E1001) -> 2.811737e+08 | F5: =D5-E5 -> 0
A7: Account Name | B7: COA Account Number | C7: Opening Balance (MMK) | D7: Debits (MMK) | E7: Credits (MMK) | F7: Ending Balance (MMK)
A8: Cash in hand | B8: 10000 | C8: =Feb_2025!F8 -> 0 | F8: =C8+D8-E8 -> 0
A9: Cash at Bank | B9: 10100 | C9: =Feb_2025!F9 -> 58249420 | D9: 38186000 | E9: 70309828 | F9: =C9+D9-E9 -> 26125592
A10: Accounts Receivable | B10: 11000 | C10: =Feb_2025!F10 -> 0 | F10: =C10+D10-E10 -> 0
A11: Inventory - Raw Material | B11: 12000 | C11: =Feb_2025!F11 -> 9965463.3 | D11: 8136940.8 | E11: 9965463.8 | F11: =C11+D11-E11 -> 8136940.4
A12: Inventory - Packaging | B12: 12100 | C12: =Feb_2025!F12 -> 22801950 | D12: 24876371 | E12: 22801950 | F12: =C12+D12-E12 -> 24876371
A13: Inventory - Finished Goods | B13: 12200 | C13: =Feb_2025!F13 -> 50973913 | D13: 53694312 | E13: 52187612 | F13: =C13+D13-E13 -> 52480613
A14: Inventory Adjustments | B14: 12300 | C14: =Feb_2025!F14 -> 0 | F14: =C14+D14-E14 -> 0
A15: Advanced Payments | B15: 13000 | C15: =Feb_2025!F15 -> 0 | F15: =C15+D15-E15 -> 0
A16: Land | B16: 15000 | C16: =Feb_2025!F16 -> 429290000 | F16: =C16+D16-E16 -> 429290000
A17: Buildings & Structures | B17: 15100 | C17: =Feb_2025!F17 -> 133000000 | F17: =C17+D17-E17 -> 133000000
A18: Machinery & Equipment | B18: 15200 | C18: =Feb_2025!F18 -> 66400000 | D18: 1520000 | E18: 0 | F18: =C18+D18-E18 -> 67920000
A19: Office & Facility Equipment | B19: 15300 | C19: =Feb_2025!F19 -> 0 | F19: =C19+D19-E19 -> 0
A20: Electrical & Utility Systems | B20: 15400 | C20: =Feb_2025!F20 -> 14056000 | F20: =C20+D20-E20 -> 14056000
A21: Construction in Progress | B21: 15500 | C21: =Feb_2025!F21 -> 90334300 | D21: 30272000 | E21: 0 | F21: =C21+D21-E21 -> 120606300
A22: Motor Vehicles | B22: 15600 | C22: =Feb_2025!F22 -> 0 | F22: =C22+D22-E22 -> 0
A23: Accumulated Depreciation - Buildings & Structures | B23: 15110 | C23: =Feb_2025!F23 -> 20504167 | D23: 0 | E23: 554166.67 | F23: =C23+E23-D23 -> 21058333
A24: Accumulated Depreciation - Machinery & Equipment | B24: 15210 | C24: =Feb_2025!F24 -> 12719058 | D24: 0 | E24: 356425 | F24: =C24+E24-D24 -> 13075483
A25: Accumulated Depreciation - Office & Facility Equipment | B25: 15310 | C25: =Feb_2025!F25 -> 0 | F25: =C25+E25-D25 -> 0
A26: Accumulated Depreciation - Electrical & Utility Systems | B26: 15410 | C26: =Feb_2025!F26 -> 1757500 | D26: 0 | E26: 104633.33 | F26: =C26+E26-D26 -> 1862133.3
A27: Accumulated Depreciation - Motor Vehicles | B27: 15610 | C27: =Feb_2025!F27 -> 0 | F27: =C27+E27-D27 -> 0
A28: Deferred Preliminary Expenses | B28: 14000 | C28: =Feb_2025!F28 -> 0 | F28: =C28+D28-E28 -> 0
A29: Accounts Payable | B29: 20000 | C29: =Feb_2025!F29 -> 0 | F29: =C29+E29-D29 -> 0
A30: Short-term Loans | B30: 21000 | C30: =Feb_2025!F30 -> 0 | F30: =C30+E30-D30 -> 0
A31: Utility Bills | B31: 22000 | C31: =Feb_2025!F31 -> 0 | F31: =C31+E31-D31 -> 0
A32: Provision for Managment Compensation | B32: 22100 | C32: =Feb_2025!F32 -> 0 | F32: =C32+E32-D32 -> 0
A33: Wages Payable | B33: 22200 | C33: =Feb_2025!F33 -> 0 | F33: =C33+E33-D33 -> 0
A34: Bank Loan | B34: 25000 | C34: =Feb_2025!F34 -> 0 | F34: =C34+E34-D34 -> 0
A35: Paid-up Capital | B35: 31000 | C35: =Feb_2025!F35 -> 839530823 | F35: =C35+E35-D35 -> 839530823
A36: Retained Earnings | B36: 32000 | C36: =Feb_2025!F36 -> 0 | F36: =C36+E36-D36 -> 0
A37: Sales Revenue | B37: 40000 | C37: =Feb_2025!F37 -> 12876000 | D37: 0 | E37: 38186000 | F37: =C37+E37-D37 -> 51062000
A38: Opening Inventory - Raw Materials | B38: 50000 | C38: =Feb_2025!F38 -> 5605177.4 | D38: 9965463.8 | E38: 0 | F38: =C38+D38-E38 -> 15570641
A39: Opening Inventory - Packaging | B39: 50100 | C39: =Feb_2025!F39 -> 7899300 | D39: 22801950 | E39: 0 | F39: =C39+D39-E39 -> 30701250
A40: Opening Inventory - Finished Goods | B40: 50200 | C40: =Feb_2025!F40 -> 34461646 | D40: 50973913 | E40: 0 | F40: =C40+D40-E40 -> 85435559
A41: Purchases Raw Materials | B41: 50010 | C41: =Feb_2025!F41 -> 9393050 | D41: 18487471 | E41: 0 | F41: =C41+D41-E41 -> 27880521
A42: Purchases Packaging | B42: 50110 | C42: =Feb_2025!F42 -> 35553030 | D42: 18273130 | E42: 0 | F42: =C42+D42-E42 -> 53826160
...

Sheet April_2025
B1: Period | C1: =TEXT(C3,"MMMM-YYY") -> April-2025
B2: Start | C2: 45748 | E2: Balance Check | F2: =IF(SUM(D:D) = SUM(E:E), "✅ Balanced", "⚠️ Unbalanced") -> ✅ Balanced
B3: End | C3: =EOMONTH(C2,0) -> 45777
D5: =SUM(D8:D1001) -> 2.2371529e+08 | E5: =SUM(E8:E1001) -> 2.2371529e+08 | F5: =D5-E5 -> 0
A7: Account Name | B7: COA Account Number | C7: Opening Balance (MMK) | D7: Debits (MMK) | E7: Credits (MMK) | F7: Ending Balance (MMK)
A8: Cash in hand | B8: 10000 | C8: =Mar_2025!F8 -> 0 | F8: =C8+D8-E8 -> 0
A9: Cash at Bank | B9: 10100 | C9: =Mar_2025!F9 -> 26125592 | D9: 52508030 | E9: 21100150 | F9: =C9+D9-E9 -> 57533472
A10: Accounts Receivable | B10: 11000 | C10: =Mar_2025!F10 -> 0 | F10: =C10+D10-E10 -> 0
A11: Inventory - Raw Material | B11: 12000 | C11: =Mar_2025!F11 -> 8136940.4 | D11: 8212072.4 | E11: 8136940.8 | F11: =C11+D11-E11 -> 8212071.9
A12: Inventory - Packaging | B12: 12100 | C12: =Mar_2025!F12 -> 24876371 | D12: 23855351 | E12: 24876371 | F12: =C12+D12-E12 -> 23855351
A13: Inventory - Finished Goods | B13: 12200 | C13: =Mar_2025!F13 -> 52480613 | D13: 29756984 | E13: 52480613 | F13: =C13+D13-E13 -> 29756984
A14: Inventory Adjustments | B14: 12300 | C14: =Mar_2025!F14 -> 0 | F14: =C14+D14-E14 -> 0
A15: Advanced Payments | B15: 13000 | C15: =Mar_2025!F15 -> 0 | F15: =C15+D15-E15 -> 0
A16: Land | B16: 15000 | C16: =Mar_2025!F16 -> 429290000 | F16: =C16+D16-E16 -> 429290000
A17: Buildings & Structures | B17: 15100 | C17: =Mar_2025!F17 -> 133000000 | F17: =C17+D17-E17 -> 133000000
A18: Machinery & Equipment | B18: 15200 | C18: =Mar_2025!F18 -> 67920000 | F18: =C18+D18-E18 -> 67920000
A19: Office & Facility Equipment | B19: 15300 | C19: =Mar_2025!F19 -> 0 | F19: =C19+D19-E19 -> 0
A20: Electrical & Utility Systems | B20: 15400 | C20: =Mar_2025!F20 -> 14056000 | F20: =C20+D20-E20 -> 14056000
A21: Construction in Progress | B21: 15500 | C21: =Mar_2025!F21 -> 120606300 | D21: 13500 | E21: 0 | F21: =C21+D21-E21 -> 120619800
A22: Motor Vehicles | B22: 15600 | C22: =Mar_2025!F22 -> 0 | F22: =C22+D22-E22 -> 0
A23: Accumulated Depreciation - Buildings & Structures | B23: 15110 | C23: =Mar_2025!F23 -> 21058333 | D23: 0 | E23: 554166.67 | F23: =C23+E23-D23 -> 21612500
A24: Accumulated Depreciation - Machinery & Equipment | B24: 15210 | C24: =Mar_2025!F24 -> 13075483 | D24: 0 | E24: 1828151 | F24: =C24+E24-D24 -> 14903634
A25: Accumulated Depreciation - Office & Facility Equipment | B25: 15310 | C25: =Mar_2025!F25 -> 0 | F25: =C25+E25-D25 -> 0
A26: Accumulated Depreciation - Electrical & Utility Systems | B26: 15410 | C26: =Mar_2025!F26 -> 1862133.3 | D26: 0 | E26: 406462 | F26: =C26+E26-D26 -> 2268595.3
A27: Accumulated Depreciation - Motor Vehicles | B27: 15610 | C27: =Mar_2025!F27 -> 0 | F27: =C27+E27-D27 -> 0
A28: Deferred Preliminary Expenses | B28: 14000 | C28: =Mar_2025!F28 -> 0 | F28: =C28+D28-E28 -> 0
A29: Accounts Payable | B29: 20000 | C29: =Mar_2025!F29 -> 0 | F29: =C29+E29-D29 -> 0
A30: Short-term Loans | B30: 21000 | C30: =Mar_2025!F30 -> 0 | F30: =C30+E30-D30 -> 0
A31: Utility Bills | B31: 22000 | C31: =Mar_2025!F31 -> 0 | F31: =C31+E31-D31 -> 0
A32: Provision for Managment Compensation | B32: 22100 | C32: =Mar_2025!F32 -> 0 | F32: =C32+E32-D32 -> 0
A33: Wages Payable | B33: 22200 | C33: =Mar_2025!F33 -> 0 | F33: =C33+E33-D33 -> 0
A34: Bank Loan | B34: 25000 | C34: =Mar_2025!F34 -> 0 | F34: =C34+E34-D34 -> 0
A35: Paid-up Capital | B35: 31000 | C35: =Mar_2025!F35 -> 839530823 | F35: =C35+E35-D35 -> 839530823
A36: Retained Earnings | B36: 32000 | C36: =Mar_2025!F36 -> 0 | F36: =C36+E36-D36 -> 0
A37: Sales Revenue | B37: 40000 | D37: 0 | E37: 52160000 | F37: =C37+E37-D37 -> 52160000
A38: Opening Inventory - Raw Materials | B38: 50000 | D38: 8136940.8 | E38: 0 | F38: =C38+D38-E38 -> 8136940.8
A39: Opening Inventory - Packaging | B39: 50100 | D39: 24876371 | E39: 0 | F39: =C39+D39-E39 -> 24876371
A40: Opening Inventory - Finished Goods | B40: 50200 | D40: 52480613 | E40: 0 | F40: =C40+D40-E40 -> 52480613
A41: Purchases Raw Materials | B41: 50010 | D41: 3821200 | E41: 0 | F41: =C41+D41-E41 -> 3821200
A42: Purchases Packaging | B42: 50110 | D42: 14210300 | E42: 0 | F42: =C42+D42-E42 -> 14210300
...

Sheet May_2025
B1: Period | C1: =TEXT(C3,"MMMM-YYY") -> May-2025
B2: Start | C2: 45778 | E2: Balance Check | F2: =IF(SUM(D:D) = SUM(E:E), "✅ Balanced", "⚠️ Unbalanced") -> ✅ Balanced
B3: End | C3: =EOMONTH(C2,0) -> 45808
D5: =SUM(D8:D1001) -> 2.7191759e+08 | E5: =SUM(E8:E1001) -> 2.7191759e+08 | F5: =D5-E5 -> 0
A7: Account Name | B7: COA Account Number | C7: Opening Balance (MMK) | D7: Debits (MMK) | E7: Credits (MMK) | F7: Ending Balance (MMK)
A8: Cash in hand | B8: 10000 | C8: =April_2025!F8 -> 0 | F8: =C8+D8-E8 -> 0
A9: Cash at Bank | B9: 10100 | C9: =April_2025!F9 -> 57533472 | D9: 57481000 | E9: 87879470 | F9: =C9+D9-E9 -> 27135002
A10: Accounts Receivable | B10: 11000 | C10: =April_2025!F10 -> 0 | F10: =C10+D10-E10 -> 0
A11: Inventory - Raw Material | B11: 12000 | C11: =April_2025!F11 -> 8212071.9 | D11: 5597336.1 | E11: 8212072.4 | F11: =C11+D11-E11 -> 5597335.7
A12: Inventory - Packaging | B12: 12100 | C12: =April_2025!F12 -> 23855351 | D12: 22235469 | E12: 23855351 | F12: =C12+D12-E12 -> 22235469
A13: Inventory - Finished Goods | B13: 12200 | C13: =April_2025!F13 -> 29756984 | D13: 34185619 | E13: 29756984 | F13: =C13+D13-E13 -> 34185619
A14: Inventory Adjustments | B14: 12300 | C14: =April_2025!F14 -> 0 | F14: =C14+D14-E14 -> 0
A15: Advanced Payments | B15: 13000 | C15: =April_2025!F15 -> 0 | F15: =C15+D15-E15 -> 0
A16: Land | B16: 15000 | C16: =April_2025!F16 -> 429290000 | F16: =C16+D16-E16 -> 429290000
A17: Buildings & Structures | B17: 15100 | C17: =April_2025!F17 -> 133000000 | F17: =C17+D17-E17 -> 133000000
A18: Machinery & Equipment | B18: 15200 | C18: =April_2025!F18 -> 67920000 | F18: =C18+D18-E18 -> 67920000
A19: Office & Facility Equipment | B19: 15300 | C19: =April_2025!F19 -> 0 | F19: =C19+D19-E19 -> 0
A20: Electrical & Utility Systems | B20: 15400 | C20: =April_2025!F20 -> 14056000 | F20: =C20+D20-E20 -> 14056000
A21: Construction in Progress | B21: 15500 | C21: =April_2025!F21 -> 120619800 | D21: 40000000 | E21: 0 | F21: =C21+D21-E21 -> 160619800
A22: Motor Vehicles | B22: 15600 | C22: =April_2025!F22 -> 0 | F22: =C22+D22-E22 -> 0
A23: Accumulated Depreciation - Buildings & Structures | B23: 15110 | C23: =April_2025!F23 -> 21612500 | D23: 0 | E23: 554166.67 | F23: =C23+E23-D23 -> 22166667
A24: Accumulated Depreciation - Machinery & Equipment | B24: 15210 | C24: =April_2025!F24 -> 14903634 | D24: 0 | E24: 1767212 | F24: =C24+E24-D24 -> 16670846
A25: Accumulated Depreciation - Office & Facility Equipment | B25: 15310 | C25: =April_2025!F25 -> 0 | F25: =C25+E25-D25 -> 0
A26: Accumulated Depreciation - Electrical & Utility Systems | B26: 15410 | C26: =April_2025!F26 -> 2268595.3 | D26: 0 | E26: 392913 | F26: =C26+E26-D26 -> 2661508.3
A27: Accumulated Depreciation - Motor Vehicles | B27: 15610 | C27: =April_2025!F27 -> 0 | F27: =C27+E27-D27 -> 0
A28: Deferred Preliminary Expenses | B28: 14000 | C28: =April_2025!F28 -> 0 | F28: =C28+D28-E28 -> 0
A29: Accounts Payable | B29: 20000 | C29: =April_2025!F29 -> 0 | F29: =C29+E29-D29 -> 0
A30: Short-term Loans | B30: 21000 | C30: =April_2025!F30 -> 0 | F30: =C30+E30-D30 -> 0
A31: Utility Bills | B31: 22000 | C31: =April_2025!F31 -> 0 | F31: =C31+E31-D31 -> 0
A32: Provision for Managment Compensation | B32: 22100 | C32: =April_2025!F32 -> 0 | F32: =C32+E32-D32 -> 0
A33: Wages Payable | B33: 22200 | C33: =April_2025!F33 -> 0 | F33: =C33+E33-D33 -> 0
A34: Bank Loan | B34: 25000 | C34: =April_2025!F34 -> 0 | F34: =C34+E34-D34 -> 0
A35: Paid-up Capital | B35: 31000 | C35: =April_2025!F35 -> 839530823 | F35: =C35+E35-D35 -> 839530823
A36: Retained Earnings | B36: 32000 | C36: =April_2025!F36 -> 0 | F36: =C36+E36-D36 -> 0
A37: Sales Revenue | B37: 40000 | C37: =April_2025!F37 -> 52160000 | D37: 0 | E37: 57481000 | F37: =C37+E37-D37 -> 109641000
A38: Opening Inventory - Raw Materials | B38: 50000 | C38: =April_2025!F38 -> 8136940.8 | D38: 8212072.4 | E38: 0 | F38: =C38+D38-E38 -> 16349013
A39: Opening Inventory - Packaging | B39: 50100 | C39: =April_2025!F39 -> 24876371 | D39: 23855351 | E39: 0 | F39: =C39+D39-E39 -> 48731722
A40: Opening Inventory - Finished Goods | B40: 50200 | C40: =April_2025!F40 -> 52480613 | D40: 29756984 | E40: 0 | F40: =C40+D40-E40 -> 82237597
A41: Purchases Raw Materials | B41: 50010 | C41: =April_2025!F41 -> 3821200 | D41: 7719100 | E41: 0 | F41: =C41+D41-E41 -> 11540300
A42: Purchases Packaging | B42: 50110 | C42: =April_2025!F42 -> 14210300 | D42: 37619370 | F42: =C42+D42-E42 -> 51829670
...

Sheet June_2025
B1: Period | C1: =TEXT(C3,"MMMM-YYY") -> June-2025
B2: Start | C2: 45809 | E2: Balance Check | F2: =IF(SUM(D:D) = SUM(E:E), "✅ Balanced", "⚠️ Unbalanced") -> ⚠️ Unbalanced
B3: End | C3: =EOMONTH(C2,0) -> 45838
D5: =SUM(D8:D1001) -> 3.6132406e+08 | E5: =SUM(E8:E1001) -> 3.6132356e+08 | F5: =D5-E5 -> 500
A7: Account Name | B7: COA Account Number | C7: Opening Balance (MMK) | D7: Debits (MMK) | E7: Credits (MMK) | F7: Ending Balance (MMK)
A8: Cash in hand | B8: 10000 | C8: =May_2025!F8 -> 0 | F8: =C8+D8-E8 -> 0
A9: Cash at Bank | B9: 10100 | C9: =May_2025!F9 -> 27135002 | D9: 183478500 | E9: 64330860 | F9: =C9+D9-E9 -> 1.4628264e+08
A10: Accounts Receivable | B10: 11000 | C10: =May_2025!F10 -> 0 | F10: =C10+D10-E10 -> 0
A11: Inventory - Raw Material | B11: 12000 | C11: =May_2025!F11 -> 5597335.7 | D11: 5914124.1 | E11: 5597336.1 | F11: =C11+D11-E11 -> 5914123.6
A12: Inventory - Packaging | B12: 12100 | C12: =May_2025!F12 -> 22235469 | D12: 9216388.4 | E12: 22235469 | F12: =C12+D12-E12 -> 9216388.4
A13: Inventory - Finished Goods | B13: 12200 | C13: =May_2025!F13 -> 34185619 | D13: 33723472 | E13: 34185619 | F13: =C13+D13-E13 -> 33723472
A14: Inventory Adjustments | B14: 12300 | C14: =May_2025!F14 -> 0 | F14: =C14+D14-E14 -> 0
A15: Advanced Payments | B15: 13000 | C15: =May_2025!F15 -> 0 | F15: =C15+D15-E15 -> 0
A16: Land | B16: 15000 | C16: =May_2025!F16 -> 429290000 | F16: =C16+D16-E16 -> 429290000
A17: Buildings & Structures | B17: 15100 | C17: =May_2025!F17 -> 133000000 | F17: =C17+D17-E17 -> 133000000
A18: Machinery & Equipment | B18: 15200 | C18: =May_2025!F18 -> 67920000 | F18: =C18+D18-E18 -> 67920000
A19: Office & Facility Equipment | B19: 15300 | C19: =May_2025!F19 -> 0 | F19: =C19+D19-E19 -> 0
A20: Electrical & Utility Systems | B20: 15400 | C20: =May_2025!F20 -> 14056000 | F20: =C20+D20-E20 -> 14056000
A21: Construction in Progress | B21: 15500 | C21: =May_2025!F21 -> 160619800 | D21: 50000000 | F21: =C21+D21-E21 -> 210619800
A22: Motor Vehicles | B22: 15600 | C22: =May_2025!F22 -> 0 | F22: =C22+D22-E22 -> 0
A23: Accumulated Depreciation - Buildings & Structures | B23: 15110 | C23: =May_2025!F23 -> 22166667 | E23: 554167 | F23: =C23+E23-D23 -> 22720834
A24: Accumulated Depreciation - Machinery & Equipment | B24: 15210 | C24: =May_2025!F24 -> 16670846 | E24: 1708305 | F24: =C24+E24-D24 -> 18379151
A25: Accumulated Depreciation - Office & Facility Equipment | B25: 15310 | C25: =May_2025!F25 -> 0 | F25: =C25+E25-D25 -> 0
A26: Accumulated Depreciation - Electrical & Utility Systems | B26: 15410 | C26: =May_2025!F26 -> 2661508.3 | E26: 379816 | F26: =C26+E26-D26 -> 3041324.3
A27: Accumulated Depreciation - Motor Vehicles | B27: 15610 | C27: =May_2025!F27 -> 0 | F27: =C27+E27-D27 -> 0
A28: Deferred Preliminary Expenses | B28: 14000 | C28: =May_2025!F28 -> 0 | F28: =C28+D28-E28 -> 0
A29: Accounts Payable | B29: 20000 | C29: =May_2025!F29 -> 0 | F29: =C29+E29-D29 -> 0
A30: Short-term Loans | B30: 21000 | C30: =May_2025!F30 -> 0 | F30: =C30+E30-D30 -> 0
A31: Utility Bills | B31: 22000 | C31: =May_2025!F31 -> 0 | F31: =C31+E31-D31 -> 0
A32: Provision for Managment Compensation | B32: 22100 | C32: =May_2025!F32 -> 0 | F32: =C32+E32-D32 -> 0
A33: Wages Payable | B33: 22200 | C33: =May_2025!F33 -> 0 | F33: =C33+E33-D33 -> 0
A34: Bank Loan | B34: 25000 | C34: =May_2025!F34 -> 0 | F34: =C34+E34-D34 -> 0
A35: Paid-up Capital | B35: 31000 | C35: =May_2025!F35 -> 839530823 | D35: 0 | E35: 150000000 | F35: =C35+E35-D35 -> 989530823
A36: Retained Earnings | B36: 32000 | C36: =May_2025!F36 -> 0 | F36: =C36+E36-D36 -> 0
A37: Sales Revenue | B37: 40000 | C37: =May_2025!F37 -> 109641000 | D37: 0 | E37: 33478000 | F37: =C37+E37-D37 -> 143119000
A38: Opening Inventory - Raw Materials | B38: 50000 | C38: =May_2025!F38 -> 16349013 | D38: 5597336.1 | F38: =C38+D38-E38 -> 21946349
A39: Opening Inventory - Packaging | B39: 50100 | C39: =May_2025!F39 -> 48731722 | D39: 22235469 | F39: =C39+D39-E39 -> 70967191
A40: Opening Inventory - Finished Goods | B40: 50200 | C40: =May_2025!F40 -> 82237597 | D40: 34185619 | F40: =C40+D40-E40 -> 1.1642322e+08
A41: Purchases Raw Materials | B41: 50010 | C41: =May_2025!F41 -> 11540300 | D41: 5392060 | F41: =C41+D41-E41 -> 16932360
A42: Purchases Packaging | B42: 50110 | C42: =May_2025!F42 -> 51829670 | D42: 7693800 | F42: =C42+D42-E42 -> 59523470
...

Sheet July_2025
B1: Period | C1: =TEXT(C3,"MMMM-YYY") -> July-2025
B2: Start | C2: 45839 | E2: Balance Check | F2: =IF(SUM(D:D) = SUM(E:E), "✅ Balanced", "⚠️ Unbalanced") -> ✅ Balanced
B3: End | C3: =EOMONTH(C2,0) -> 45869
D5: =SUM(D8:D1001) -> 8.7809733e+08 | E5: =SUM(E8:E1001) -> 8.7809733e+08 | F5: =D5-E5 -> 0
A7: Account Name | B7: COA Account Number | C7: Opening Balance (MMK) | D7: Debits (MMK) | E7: Credits (MMK) | F7: Ending Balance (MMK)
A8: Cash in hand | B8: 10000 | C8: =June_2025!F8 -> 0 | F8: =C8+D8-E8 -> 0
A9: Cash at Bank | B9: 10100 | C9: =June_2025!F9 -> 1.4628264e+08 | D9: 469774500 | E9: 307186620 | F9: =C9+D9-E9 -> 3.0887052e+08
A10: Accounts Receivable | B10: 11000 | C10: =June_2025!F10 -> 0 | F10: =C10+D10-E10 -> 0
A11: Inventory - Raw Material | B11: 12000 | C11: =June_2025!F11 -> 5914123.6 | D11: 4790395.1 | E11: 5914124 | F11: =C11+D11-E11 -> 4790394.7
A12: Inventory - Packaging | B12: 12100 | C12: =June_2025!F12 -> 9216388.4 | D12: 7452014.8 | E12: 9216388 | F12: =C12+D12-E12 -> 7452015.2
A13: Inventory - Finished Goods | B13: 12200 | C13: =June_2025!F13 -> 33723472 | D13: 37467131 | E13: 33723472 | F13: =C13+D13-E13 -> 37467131
A14: Inventory Adjustments | B14: 12300 | C14: =June_2025!F14 -> 0 | F14: =C14+D14-E14 -> 0
A15: Advanced Payments | B15: 13000 | C15: =June_2025!F15 -> 0 | F15: =C15+D15-E15 -> 0
A16: Land | B16: 15000 | C16: =June_2025!F16 -> 429290000 | F16: =C16+D16-E16 -> 429290000
A17: Buildings & Structures | B17: 15100 | C17: =June_2025!F17 -> 133000000 | F17: =C17+D17-E17 -> 133000000
A18: Machinery & Equipment | B18: 15200 | C18: =June_2025!F18 -> 67920000 | D18: 68000000 | F18: =C18+D18-E18 -> 135920000
A19: Office & Facility Equipment | B19: 15300 | C19: =June_2025!F19 -> 0 | F19: =C19+D19-E19 -> 0
A20: Electrical & Utility Systems | B20: 15400 | C20: =June_2025!F20 -> 14056000 | D20: 92025000 | F20: =C20+D20-E20 -> 106081000
A21: Construction in Progress | B21: 15500 | C21: =June_2025!F21 -> 210619800 | D21: 130033000 | F21: =C21+D21-E21 -> 340652800
A22: Motor Vehicles | B22: 15600 | C22: =June_2025!F22 -> 0 | F22: =C22+D22-E22 -> 0
A23: Accumulated Depreciation - Buildings & Structures | B23: 15110 | C23: =June_2025!F23 -> 22720834 | E23: 554167 | F23: =C23+E23-D23 -> 23275001
A24: Accumulated Depreciation - Machinery & Equipment | B24: 15210 | C24: =June_2025!F24 -> 18379151 | E24: 1651362 | F24: =C24+E24-D24 -> 20030513
A25: Accumulated Depreciation - Office & Facility Equipment | B25: 15310 | C25: =June_2025!F25 -> 0 | F25: =C25+E25-D25 -> 0
A26: Accumulated Depreciation - Electrical & Utility Systems | B26: 15410 | C26: =June_2025!F26 -> 3041324.3 | E26: 367156 | F26: =C26+E26-D26 -> 3408480.3
A27: Accumulated Depreciation - Motor Vehicles | B27: 15610 | C27: =June_2025!F27 -> 0 | F27: =C27+E27-D27 -> 0
A28: Deferred Preliminary Expenses | B28: 14000 | C28: =June_2025!F28 -> 0 | F28: =C28+D28-E28 -> 0
A29: Accounts Payable | B29: 20000 | C29: =June_2025!F29 -> 0 | F29: =C29+E29-D29 -> 0
A30: Short-term Loans | B30: 21000 | C30: =June_2025!F30 -> 0 | F30: =C30+E30-D30 -> 0
A31: Utility Bills | B31: 22000 | C31: =June_2025!F31 -> 0 | F31: =C31+E31-D31 -> 0
A32: Provision for Managment Compensation | B32: 22100 | C32: =June_2025!F32 -> 0 | F32: =C32+E32-D32 -> 0
A33: Wages Payable | B33: 22200 | C33: =June_2025!F33 -> 0 | F33: =C33+E33-D33 -> 0
A34: Bank Loan | B34: 25000 | C34: =June_2025!F34 -> 0 | F34: =C34+E34-D34 -> 0
A35: Paid-up Capital | B35: 31000 | C35: =June_2025!F35 -> 989530823 | E35: 450000000 | F35: =C35+E35-D35 -> 1439530823
A36: Retained Earnings | B36: 32000 | C36: =June_2025!F36 -> 0 | F36: =C36+E36-D36 -> 0
A37: Sales Revenue | B37: 40000 | C37: =June_2025!F37 -> 143119000 | D37: 0 | E37: 19774500 | F37: =C37+E37-D37 -> 162893500
A38: Opening Inventory - Raw Materials | B38: 50000 | C38: =June_2025!F38 -> 21946349 | D38: 5914124 | F38: =C38+D38-E38 -> 27860473
A39: Opening Inventory - Packaging | B39: 50100 | C39: =June_2025!F39 -> 70967191 | D39: 9216388 | F39: =C39+D39-E39 -> 80183579
A40: Opening Inventory - Finished Goods | B40: 50200 | C40: =June_2025!F40 -> 1.1642322e+08 | D40: 33723472 | F40: =C40+D40-E40 -> 1.5014669e+08
A41: Purchases Raw Materials | B41: 50010 | C41: =June_2025!F41 -> 16932360 | D41: 2408379 | F41: =C41+D41-E41 -> 19340739
A42: Purchases Packaging | B42: 50110 | C42: =June_2025!F42 -> 59523470 | D42: 12550941 | F42: =C42+D42-E42 -> 72074411
...

Sheet Aug_2025
B1: Period | C1: =TEXT(C3,"MMMM-YYY") -> August-2025
B2: Start | C2: 45870 | E2: Balance Check | F2: =IF(SUM(D:D) = SUM(E:E), "✅ Balanced", "⚠️ Unbalanced") -> ✅ Balanced
B3: End | C3: =EOMONTH(C2,0) -> 45900
D5: =SUM(D8:D1001) -> 7.2709892e+08 | E5: =SUM(E8:E1001) -> 7.2709892e+08 | F5: =D5-E5 -> 0
A7: Account Name | B7: COA Account Number | C7: Opening Balance (MMK) | D7: Debits (MMK) | E7: Credits (MMK) | F7: Ending Balance (MMK)
A8: Cash in hand | B8: 10000 | C8: =July_2025!F8 -> 0 | F8: =C8+D8-E8 -> 0
A9: Cash at Bank | B9: 10100 | C9: =July_2025!F9 -> 3.0887052e+08 | D9: 19759500 | E9: 284621580 | F9: =C9+D9-E9 -> 44008442
A10: Accounts Receivable | B10: 11000 | C10: =July_2025!F10 -> 0 | F10: =C10+D10-E10 -> 0
A11: Inventory - Raw Material | B11: 12000 | C11: =July_2025!F11 -> 4790394.7 | D11: 7190701.1 | E11: 4790395.1 | F11: =C11+D11-E11 -> 7190700.7
A12: Inventory - Packaging | B12: 12100 | C12: =July_2025!F12 -> 7452015.2 | D12: 12692758 | E12: 7452014.8 | F12: =C12+D12-E12 -> 12692759
A13: Inventory - Finished Goods | B13: 12200 | C13: =July_2025!F13 -> 37467131 | D13: 32444705 | E13: 37467131 | F13: =C13+D13-E13 -> 32444705
A14: Inventory Adjustments | B14: 12300 | C14: =July_2025!F14 -> 0 | F14: =C14+D14-E14 -> 0
A15: Advanced Payments | B15: 13000 | C15: =July_2025!F15 -> 0 | D15: 261063780 | F15: =C15+D15-E15 -> 261063780
A16: Land | B16: 15000 | C16: =July_2025!F16 -> 429290000 | F16: =C16+D16-E16 -> 429290000
A17: Buildings & Structures | B17: 15100 | C17: =July_2025!F17 -> 133000000 | D17: 316445000 | F17: =C17+D17-E17 -> 449445000
A18: Machinery & Equipment | B18: 15200 | C18: =July_2025!F18 -> 135920000 | F18: =C18+D18-E18 -> 135920000
A19: Office & Facility Equipment | B19: 15300 | C19: =July_2025!F19 -> 0 | F19: =C19+D19-E19 -> 0
A20: Electrical & Utility Systems | B20: 15400 | C20: =July_2025!F20 -> 106081000 | F20: =C20+D20-E20 -> 106081000
A21: Construction in Progress | B21: 15500 | C21: =July_2025!F21 -> 340652800 | D21: 640000 | E21: 316445000 | F21: =C21+D21-E21 -> 24847800
A22: Motor Vehicles | B22: 15600 | C22: =July_2025!F22 -> 0 | F22: =C22+D22-E22 -> 0
A23: Accumulated Depreciation - Buildings & Structures | B23: 15110 | C23: =July_2025!F23 -> 23275001 | E23: 554167 | F23: =C23+E23-D23 -> 23829168
A24: Accumulated Depreciation - Machinery & Equipment | B24: 15210 | C24: =July_2025!F24 -> 20030513 | E24: 1596316 | F24: =C24+E24-D24 -> 21626829
A25: Accumulated Depreciation - Office & Facility Equipment | B25: 15310 | C25: =July_2025!F25 -> 0 | F25: =C25+E25-D25 -> 0
A26: Accumulated Depreciation - Electrical & Utility Systems | B26: 15410 | C26: =July_2025!F26 -> 3408480.3 | E26: 354917 | F26: =C26+E26-D26 -> 3763397.3
A27: Accumulated Depreciation - Motor Vehicles | B27: 15610 | C27: =July_2025!F27 -> 0 | F27: =C27+E27-D27 -> 0
A28: Deferred Preliminary Expenses | B28: 14000 | C28: =July_2025!F28 -> 0 | F28: =C28+D28-E28 -> 0
A29: Accounts Payable | B29: 20000 | C29: =July_2025!F29 -> 0 | F29: =C29+E29-D29 -> 0
A30: Short-term Loans | B30: 21000 | C30: =July_2025!F30 -> 0 | F30: =C30+E30-D30 -> 0
A31: Utility Bills | B31: 22000 | C31: =July_2025!F31 -> 0 | F31: =C31+E31-D31 -> 0
A32: Provision for Managment Compensation | B32: 22100 | C32: =July_2025!F32 -> 0 | F32: =C32+E32-D32 -> 0
A33: Wages Payable | B33: 22200 | C33: =July_2025!F33 -> 0 | F33: =C33+E33-D33 -> 0
A34: Bank Loan | B34: 25000 | C34: =July_2025!F34 -> 0 | F34: =C34+E34-D34 -> 0
A35: Paid-up Capital | B35: 31000 | C35: =July_2025!F35 -> 1439530823 | F35: =C35+E35-D35 -> 1439530823
A36: Retained Earnings | B36: 32000 | C36: =July_2025!F36 -> 0 | F36: =C36+E36-D36 -> 0
A37: Sales Revenue | B37: 40000 | C37: =July_2025!F37 -> 162893500 | D37: 0 | E37: 19759500 | F37: =C37+E37-D37 -> 182653000
A38: Opening Inventory - Raw Materials | B38: 50000 | C38: =July_2025!F38 -> 27860473 | D38: 4790395.1 | F38: =C38+D38-E38 -> 32650868
A39: Opening Inventory - Packaging | B39: 50100 | C39: =July_2025!F39 -> 80183579 | D39: 7452014.8 | F39: =C39+D39-E39 -> 87635594
A40: Opening Inventory - Finished Goods | B40: 50200 | C40: =July_2025!F40 -> 1.5014669e+08 | D40: 37467131 | F40: =C40+D40-E40 -> 1.8761382e+08
A41: Purchases Raw Materials | B41: 50010 | C41: =July_2025!F41 -> 19340739 | D41: 5239371 | F41: =C41+D41-E41 -> 24580110
A42: Purchases Packaging | B42: 50110 | C42: =July_2025!F42 -> 72074411 | D42: 16236429 | F42: =C42+D42-E42 -> 88310840
...

Sheet Sep_2025
B1: Period | C1: =TEXT(C3,"MMMM-YYY") -> September-2025
B2: Start | C2: 45901 | E2: Balance Check | F2: =IF(SUM(D:D) = SUM(E:E), "✅ Balanced", "⚠️ Unbalanced") -> ✅ Balanced
B3: End | C3: =EOMONTH(C2,0) -> 45930
D5: =SUM(D8:D1001) -> 1.4425375e+08 | E5: =SUM(E8:E1001) -> 1.4425375e+08 | F5: =D5-E5 -> 0
A7: Account Name | B7: COA Account Number | C7: Opening Balance (MMK) | D7: Debits (MMK) | E7: Credits (MMK) | F7: Ending Balance (MMK)
A8: Cash in hand | B8: 10000 | C8: =Aug_2025!F8 -> 0 | F8: =C8+D8-E8 -> 0
A9: Cash at Bank | B9: 10100 | C9: =Aug_2025!F9 -> 44008442 | D9: 25669100 | E9: 22620550 | F9: =C9+D9-E9 -> 47056992
A10: Accounts Receivable | B10: 11000 | C10: =Aug_2025!F10 -> 0 | F10: =C10+D10-E10 -> 0
A11: Inventory - Raw Material | B11: 12000 | C11: =Aug_2025!F11 -> 7190700.7 | D11: 6515831.8 | E11: 7190701 | F11: =C11+D11-E11 -> 6515831.5
A12: Inventory - Packaging | B12: 12100 | C12: =Aug_2025!F12 -> 12692759 | D12: 15343618 | E12: 12692758 | F12: =C12+D12-E12 -> 15343619
A13: Inventory - Finished Goods | B13: 12200 | C13: =Aug_2025!F13 -> 32444705 | D13: 17720747 | E13: 32444705 | F13: =C13+D13-E13 -> 17720747
A14: Inventory Adjustments | B14: 12300 | C14: =Aug_2025!F14 -> 0 | F14: =C14+D14-E14 -> 0
A15: Advanced Payments | B15: 13000 | C15: =Aug_2025!F15 -> 261063780 | D15: 6970000 | E15: 274898 | F15: =C15+D15-E15 -> 267758882
A16: Land | B16: 15000 | C16: =Aug_2025!F16 -> 429290000 | F16: =C16+D16-E16 -> 429290000
A17: Buildings & Structures | B17: 15100 | C17: =Aug_2025!F17 -> 449445000 | F17: =C17+D17-E17 -> 449445000
A18: Machinery & Equipment | B18: 15200 | C18: =Aug_2025!F18 -> 135920000 | D18: 2054300 | F18: =C18+D18-E18 -> 137974300
A19: Office & Facility Equipment | B19: 15300 | C19: =Aug_2025!F19 -> 0 | F19: =C19+D19-E19 -> 0
A20: Electrical & Utility Systems | B20: 15400 | C20: =Aug_2025!F20 -> 106081000 | F20: =C20+D20-E20 -> 106081000
A21: Construction in Progress | B21: 15500 | C21: =Aug_2025!F21 -> 24847800 | F21: =C21+D21-E21 -> 24847800
A22: Motor Vehicles | B22: 15600 | C22: =Aug_2025!F22 -> 0 | F22: =C22+D22-E22 -> 0
A23: Accumulated Depreciation - Buildings & Structures | B23: 15110 | C23: =Aug_2025!F23 -> 23829168 | E23: 554167 | F23: =C23+E23-D23 -> 24383335
A24: Accumulated Depreciation - Machinery & Equipment | B24: 15210 | C24: =Aug_2025!F24 -> 21626829 | E24: 1543106 | F24: =C24+E24-D24 -> 23169935
A25: Accumulated Depreciation - Office & Facility Equipment | B25: 15310 | C25: =Aug_2025!F25 -> 0 | F25: =C25+E25-D25 -> 0
A26: Accumulated Depreciation - Electrical & Utility Systems | B26: 15410 | C26: =Aug_2025!F26 -> 3763397.3 | E26: 343087 | F26: =C26+E26-D26 -> 4106484.3
A27: Accumulated Depreciation - Motor Vehicles | B27: 15610 | C27: =Aug_2025!F27 -> 0 | F27: =C27+E27-D27 -> 0
A28: Deferred Preliminary Expenses | B28: 14000 | C28: =Aug_2025!F28 -> 0 | F28: =C28+D28-E28 -> 0
A29: Accounts Payable | B29: 20000 | C29: =Aug_2025!F29 -> 0 | F29: =C29+E29-D29 -> 0
A30: Short-term Loans | B30: 21000 | C30: =Aug_2025!F30 -> 0 | F30: =C30+E30-D30 -> 0
A31: Utility Bills | B31: 22000 | C31: =Aug_2025!F31 -> 0 | F31: =C31+E31-D31 -> 0
A32: Provision for Managment Compensation | B32: 22100 | C32: =Aug_2025!F32 -> 0 | F32: =C32+E32-D32 -> 0
A33: Wages Payable | B33: 22200 | C33: =Aug_2025!F33 -> 0 | F33: =C33+E33-D33 -> 0
A34: Bank Loan | B34: 25000 | C34: =Aug_2025!F34 -> 0 | F34: =C34+E34-D34 -> 0
A35: Paid-up Capital | B35: 31000 | C35: =Aug_2025!F35 -> 1439530823 | F35: =C35+E35-D35 -> 1439530823
A36: Retained Earnings | B36: 32000 | C36: =Aug_2025!F36 -> 0 | F36: =C36+E36-D36 -> 0
A37: Sales Revenue | B37: 40000 | C37: =Aug_2025!F37 -> 182653000 | D37: 0 | E37: 25669100 | F37: =C37+E37-D37 -> 208322100
A38: Opening Inventory - Raw Materials | B38: 50000 | C38: =Aug_2025!F38 -> 32650868 | D38: 7190701 | F38: =C38+D38-E38 -> 39841569
A39: Opening Inventory - Packaging | B39: 50100 | C39: =Aug_2025!F39 -> 87635594 | D39: 12692758 | F39: =C39+D39-E39 -> 1.0032835e+08
A40: Opening Inventory - Finished Goods | B40: 50200 | C40: =Aug_2025!F40 -> 1.8761382e+08 | D40: 32444705 | F40: =C40+D40-E40 -> 2.2005853e+08
A41: Purchases Raw Materials | B41: 50010 | C41: =Aug_2025!F41 -> 24580110 | D41: 318000 | F41: =C41+D41-E41 -> 24898110
A42: Purchases Packaging | B42: 50110 | C42: =Aug_2025!F42 -> 88310840 | D42: 9574250 | F42: =C42+D42-E42 -> 97885090
...

Sheet Oct_2025
B1: Period | C1: =TEXT(C3,"MMMM-YYY") -> October-2025
B2: Start | C2: 45931 | E2: Balance Check | F2: =IF(SUM(D:D) = SUM(E:E), "✅ Balanced", "⚠️ Unbalanced") -> ✅ Balanced
B3: End | C3: =EOMONTH(C2,0) -> 45961
D5: =SUM(D8:D1001) -> 8.1761189e+08 | E5: =SUM(E8:E1001) -> 8.1761189e+08 | F5: =D5-E5 -> 0
A7: Account Name | B7: COA Account Number | C7: Opening Balance (MMK) | D7: Debits (MMK) | E7: Credits (MMK) | F7: Ending Balance (MMK)
A8: Cash in hand | B8: 10000 | C8: =Sep_2025!F8 -> 0 | F8: =C8+D8-E8 -> 0
A9: Cash at Bank | B9: 10100 | C9: =Sep_2025!F9 -> 47056992 | D9: 4.7271273e+08 | E9: 261851550 | F9: =C9+D9-E9 -> 2.5791817e+08
A10: Accounts Receivable | B10: 11000 | C10: =Sep_2025!F10 -> 0 | F10: =C10+D10-E10 -> 0
A11: Inventory - Raw Material | B11: 12000 | C11: =Sep_2025!F11 -> 6515831.5 | D11: 8507511.8 | E11: 6515831.8 | F11: =C11+D11-E11 -> 8507511.5
A12: Inventory - Packaging | B12: 12100 | C12: =Sep_2025!F12 -> 15343619 | D12: 8810565.5 | E12: 15343618 | F12: =C12+D12-E12 -> 8810566.1
A13: Inventory - Finished Goods | B13: 12200 | C13: =Sep_2025!F13 -> 17720747 | D13: 23496954 | E13: 17720747 | F13: =C13+D13-E13 -> 23496954
A14: Inventory Adjustments | B14: 12300 | C14: =Sep_2025!F14 -> 0 | F14: =C14+D14-E14 -> 0
A15: Advanced Payments | B15: 13000 | C15: =Sep_2025!F15 -> 267758882 | D15: 186900000 | E15: 274898 | F15: =C15+D15-E15 -> 454383984
A16: Land | B16: 15000 | C16: =Sep_2025!F16 -> 429290000 | F16: =C16+D16-E16 -> 429290000
A17: Buildings & Structures | B17: 15100 | C17: =Sep_2025!F17 -> 449445000 | F17: =C17+D17-E17 -> 449445000
A18: Machinery & Equipment | B18: 15200 | C18: =Sep_2025!F18 -> 137974300 | D18: 128000 | F18: =C18+D18-E18 -> 138102300
A19: Office & Facility Equipment | B19: 15300 | C19: =Sep_2025!F19 -> 0 | F19: =C19+D19-E19 -> 0
A20: Electrical & Utility Systems | B20: 15400 | C20: =Sep_2025!F20 -> 106081000 | F20: =C20+D20-E20 -> 106081000
A21: Construction in Progress | B21: 15500 | C21: =Sep_2025!F21 -> 24847800 | D21: 50945000 | F21: =C21+D21-E21 -> 75792800
A22: Motor Vehicles | B22: 15600 | C22: =Sep_2025!F22 -> 0 | F22: =C22+D22-E22 -> 0
A23: Accumulated Depreciation - Buildings & Structures | B23: 15110 | C23: =Sep_2025!F23 -> 24383335 | E23: 554167 | F23: =C23+E23-D23 -> 24937502
A24: Accumulated Depreciation - Machinery & Equipment | B24: 15210 | C24: =Sep_2025!F24 -> 23169935 | E24: 1491669 | F24: =C24+E24-D24 -> 24661604
A25: Accumulated Depreciation - Office & Facility Equipment | B25: 15310 | C25: =Sep_2025!F25 -> 0 | F25: =C25+E25-D25 -> 0
A26: Accumulated Depreciation - Electrical & Utility Systems | B26: 15410 | C26: =Sep_2025!F26 -> 4106484.3 | E26: 331650 | F26: =C26+E26-D26 -> 4438134.3
A27: Accumulated Depreciation - Motor Vehicles | B27: 15610 | C27: =Sep_2025!F27 -> 0 | F27: =C27+E27-D27 -> 0
A28: Deferred Preliminary Expenses | B28: 14000 | C28: =Sep_2025!F28 -> 0 | D28: 2034100 | F28: =C28+D28-E28 -> 2034100
A29: Accounts Payable | B29: 20000 | C29: =Sep_2025!F29 -> 0 | F29: =C29+E29-D29 -> 0
A30: Short-term Loans | B30: 21000 | C30: =Sep_2025!F30 -> 0 | F30: =C30+E30-D30 -> 0
A31: Utility Bills | B31: 22000 | C31: =Sep_2025!F31 -> 0 | F31: =C31+E31-D31 -> 0
A32: Provision for Managment Compensation | B32: 22100 | C32: =Sep_2025!F32 -> 0 | F32: =C32+E32-D32 -> 0
A33: Wages Payable | B33: 22200 | C33: =Sep_2025!F33 -> 0 | F33: =C33+E33-D33 -> 0
A34: Bank Loan | B34: 25000 | C34: =Sep_2025!F34 -> 0 | F34: =C34+E34-D34 -> 0
A35: Paid-up Capital | B35: 31000 | C35: =Sep_2025!F35 -> 1439530823 | E35: 450000000 | F35: =C35+E35-D35 -> 1889530823
A36: Retained Earnings | B36: 32000 | C36: =Sep_2025!F36 -> 0 | F36: =C36+E36-D36 -> 0
A37: Sales Revenue | B37: 40000 | C37: =Sep_2025!F37 -> 208322100 | D37: 0 | E37: 21894000 | F37: =C37+E37-D37 -> 230216100
A38: Opening Inventory - Raw Materials | B38: 50000 | C38: =Sep_2025!F38 -> 39841569 | D38: 6515831.8 | F38: =C38+D38-E38 -> 46357401
A39: Opening Inventory - Packaging | B39: 50100 | C39: =Sep_2025!F39 -> 1.0032835e+08 | D39: 15343618 | F39: =C39+D39-E39 -> 1.1567197e+08
A40: Opening Inventory - Finished Goods | B40: 50200 | C40: =Sep_2025!F40 -> 2.2005853e+08 | D40: 17720747 | F40: =C40+D40-E40 -> 2.3777927e+08
A41: Purchases Raw Materials | B41: 50010 | C41: =Sep_2025!F41 -> 24898110 | D41: 6671900 | F41: =C41+D41-E41 -> 31570010
A42: Purchases Packaging | B42: 50110 | C42: =Sep_2025!F42 -> 97885090 | D42: 11393950 | F42: =C42+D42-E42 -> 109279040
...
