Workbook

Sheet MR_Fixed_Asset_Register_List
M2: Accounts | N2: Prior Net Book Value ($) | O2: =O11 -> Net Book Value Apr-25 | P2: =P11 -> Net Book Value May-25 | Q2: =Q11 -> Net Book Value Jun-25 | R2: =R11 -> Net Book Value Jul-25 | S2: =S11 -> Net Book Value Aug-25 | T2: =T11 -> Net Book Value Sep-25 | U2: =U11 -> Net Book Value Oct-25 | V2: =V11 -> Net Book Value Nov-25 | W2: =W10 | X2: =X10 | Y2: =Y10 | Z2: =Z10 | AA2: =AA10 | AB2: =AB10 | AC2: =AC10 | AD2: =AD10 | ... CT2: =CT10
M3: Land | N3: =SUMIF($C$12:$C$29,$M3,L$12:L$29) -> 429290000 | O3: =SUMIF($C:$C,$M3,O:O) -> 429290000 | P3: =SUMIF($C:$C,$M3,P:P) -> 429290000 | Q3: =SUMIF($C:$C,$M3,Q:Q) -> 429290000 | R3: =SUMIF($C:$C,$M3,R:R) -> 429290000 | S3: =SUMIF($C:$C,$M3,S:S) -> 429290000 | T3: =SUMIF($C:$C,$M3,T:T) -> 429290000 | U3: =SUMIF($C$12:$C$29,$M3,U$12:U$29) -> 429290000 | V3: =SUMIF($C$11:$C$25,#REF!,V$11:V$25) -> 0 | X3: =SUMIF($C$11:$C$25,#REF!,X$11:X$25) -> 0 | Y3: =SUMIF($C$11:$C$25,#REF!,Y$11:Y$25) -> 0 | Z3: =SUMIF($C$11:$C$25,#REF!,Z$11:Z$25) -> 0 | AA3: =SUMIF($C$11:$C$25,#REF!,AA$11:AA$25) -> 0 | AB3: =SUMIF($C$11:$C$25,#REF!,AB$11:AB$25) -> 0 | AC3: =SUMIF($C$11:$C$25,#REF!,AC$11:AC$25) -> 0 | AD3: =SUMIF($C$11:$C$25,#REF!,AD$11:AD$25) -> 0 | AE3: =SUMIF($C$11:$C$25,#REF!,AE$11:AE$25) -> 0 | ... CT3: =SUMIF($C$11:$C$25,#REF!,CT$11:CT$25) -> 0
M4: Buildings & Structures | N4: =SUMIF($C$12:$C$29,$M4,L$12:L$29) -> 1.1194167e+08 | O4: =SUMIF($C:$C,$M4,O:O) -> 111387500 | P4: =SUMIF($C:$C,$M4,P:P) -> 1.1083333e+08 | Q4: =SUMIF($C:$C,$M4,Q:Q) -> 1.1027917e+08 | R4: =SUMIF($C:$C,$M4,R:R) -> 109725000 | S4: =SUMIF($C:$C,$M4,$S:$S) -> 4.2561583e+08 | T4: =SUMIF($C:$C,$M4,T:T) -> 4.2506167e+08 | U4: =SUMIF($C$12:$C$29,$M4,U$12:U$29) -> 108062500 | V4: =SUMIF($C$11:$C$25,#REF!,V$11:V$25) -> 0 | W4: =SUMIF($C$11:$C$25,#REF!,W$11:W$25) -> 0 | X4: =SUMIF($C$11:$C$25,#REF!,X$11:X$25) -> 0 | Y4: =SUMIF($C$11:$C$25,#REF!,Y$11:Y$25) -> 0 | Z4: =SUMIF($C$11:$C$25,#REF!,Z$11:Z$25) -> 0 | AA4: =SUMIF($C$11:$C$25,#REF!,AA$11:AA$25) -> 0 | AB4: =SUMIF($C$11:$C$25,#REF!,AB$11:AB$25) -> 0 | AC4: =SUMIF($C$11:$C$25,#REF!,AC$11:AC$25) -> 0 | ... CT4: =SUMIF($C$11:$C$25,#REF!,CT$11:CT$25) -> 0
M5: Machinery & Equipment | N5: =SUMIF($C$12:$C$29,$M5,L$12:L$29) -> 54844517 | O5: =SUMIF($C:$C,$M5,O:O) -> 53016366 | P5: =SUMIF($C:$C,$M5,P:P) -> 51249154 | Q5: =SUMIF($C:$C,$M5,Q:Q) -> 49540849 | R5: =SUMIF($C:$C,$M5,R:R) -> 1.1588949e+08 | S5: =SUMIF($C:$C,$M5,$S:$S) -> 1.1429317e+08 | T5: =SUMIF($C:$C,$M5,T:T) -> 1.1493237e+08 | U5: =SUMIF($C$12:$C$29,$M5,U$12:U$29) -> 1.112584e+08 | V5: =SUMIF($C$11:$C$25,#REF!,V$11:V$25) -> 0 | W5: =SUMIF($C$11:$C$25,#REF!,W$11:W$25) -> 0 | X5: =SUMIF($C$11:$C$25,#REF!,X$11:X$25) -> 0 | Y5: =SUMIF($C$11:$C$25,#REF!,Y$11:Y$25) -> 0 | Z5: =SUMIF($C$11:$C$25,#REF!,Z$11:Z$25) -> 0 | AA5: =SUMIF($C$11:$C$25,#REF!,AA$11:AA$25) -> 0 | AB5: =SUMIF($C$11:$C$25,#REF!,AB$11:AB$25) -> 0 | AC5: =SUMIF($C$11:$C$25,#REF!,AC$11:AC$25) -> 0 | ... CT5: =SUMIF($C$11:$C$25,#REF!,CT$11:CT$25) -> 0
M6: Office & Facility Equipment | N6: =SUMIF($C$12:$C$29,$M6,L$12:L$29) -> 0 | O6: =SUMIF($C:$C,$M6,O:O) -> 0 | P6: =SUMIF($C:$C,$M6,P:P) -> 0 | Q6: =SUMIF($C:$C,$M6,Q:Q) -> 0 | R6: =SUMIF($C:$C,$M6,R:R) -> 0 | S6: =SUMIF($C:$C,$M6,$S:$S) -> 0 | T6: =SUMIF($C:$C,$M6,T:T) -> 0 | U6: =SUMIF($C$12:$C$29,$M6,U$12:U$29) -> 0 | V6: =SUMIF($C$11:$C$25,#REF!,V$11:V$25) -> 0 | W6: =SUMIF($C$11:$C$25,#REF!,W$11:W$25) -> 0 | X6: =SUMIF($C$11:$C$25,#REF!,X$11:X$25) -> 0 | Y6: =SUMIF($C$11:$C$25,#REF!,Y$11:Y$25) -> 0 | Z6: =SUMIF($C$11:$C$25,#REF!,Z$11:Z$25) -> 0 | AA6: =SUMIF($C$11:$C$25,#REF!,AA$11:AA$25) -> 0 | AB6: =SUMIF($C$11:$C$25,#REF!,AB$11:AB$25) -> 0 | AC6: =SUMIF($C$11:$C$25,#REF!,AC$11:AC$25) -> 0 | ... CT6: =SUMIF($C$11:$C$25,#REF!,CT$11:CT$25) -> 0
M7: Electrical & Utility Systems | N7: =SUMIF($C$12:$C$29,$M7,L$12:L$29) -> 12193867 | O7: =SUMIF($C:$C,$M7,O:O) -> 11787404 | P7: =SUMIF($C:$C,$M7,P:P) -> 11394491 | Q7: =SUMIF($C:$C,$M7,Q:Q) -> 11014675 | R7: =SUMIF($C:$C,$M7,R:R) -> 1.0264752e+08 | S7: =SUMIF($C:$C,$M7,$S:$S) -> 1.022926e+08 | T7: =SUMIF($C:$C,$M7,T:T) -> 1.0194951e+08 | U7: =SUMIF($C$12:$C$29,$M7,U$12:U$29) -> 1.0161786e+08 | V7: =SUMIF($C$11:$C$25,#REF!,V$11:V$25) -> 0 | W7: =SUMIF($C$11:$C$25,#REF!,W$11:W$25) -> 0 | X7: =SUMIF($C$11:$C$25,#REF!,X$11:X$25) -> 0 | Y7: =SUMIF($C$11:$C$25,#REF!,Y$11:Y$25) -> 0 | Z7: =SUMIF($C$11:$C$25,#REF!,Z$11:Z$25) -> 0 | AA7: =SUMIF($C$11:$C$25,#REF!,AA$11:AA$25) -> 0 | AB7: =SUMIF($C$11:$C$25,#REF!,AB$11:AB$25) -> 0 | AC7: =SUMIF($C$11:$C$25,#REF!,AC$11:AC$25) -> 0 | ... CT7: =SUMIF($C$11:$C$25,#REF!,CT$11:CT$25) -> 0
M8: Total Value | N8: =SUM(N3:N7) -> 608270050 | O8: =SUM(O3:O7) -> 6.0548127e+08 | P8: =SUM(P3:P7) -> 6.0276698e+08 | Q8: =SUM(Q3:Q7) -> 600124690 | R8: =SUM(R3:R7) -> 7.5755201e+08 | S8: =SUM(S3:S7) -> 1071491606 | T8: =SUM(T3:T7) -> 1071233547 | U8: =SUM(U3:U7) -> 7.5022876e+08 | ... CT8: =SUM(CT3:CT7) -> 0
A11: Asset ID | B11: Asset Name | C11: Accounts | D11: COA | E11: Purchase Date | F11: Opening Balance Date | G11: Cost (MMK) | H11: Useful Life (Years) | I11: Depreciation Rate | J11: Depreciation Method | K11: Prior Accumulated Depreciation (MMK) | L11: Prior Net Book Value Mar-25 (MMK) | M11: Status | N11: Location | O11: ="Net Book Value" &" "& Text(MR_Depreciation_Schedule!N11,"MMM-YY") -> Net Book Value Apr-25 | P11: ="Net Book Value" &" "& Text(MR_Depreciation_Schedule!O11,"MMM-YY") -> Net Book Value May-25 | Q11: ="Net Book Value" &" "& Text(MR_Depreciation_Schedule!P11,"MMM-YY") -> Net Book Value Jun-25 | R11: ="Net Book Value" &" "& Text(MR_Depreciation_Schedule!Q11,"MMM-YY") -> Net Book Value Jul-25 | S11: ="Net Book Value" &" "& Text(MR_Depreciation_Schedule!R11,"MMM-YY") -> Net Book Value Aug-25 | T11: ="Net Book Value" &" "& Text(MR_Depreciation_Schedule!S11,"MMM-YY") -> Net Book Value Sep-25 | U11: ="Net Book Value" &" "& Text(MR_Depreciation_Schedule!T11,"MMM-YY") -> Net Book Value Oct-25 | V11: ="Net Book Value" &" "& Text(MR_Depreciation_Schedule!U11,"MMM-YY") -> Net Book Value Nov-25 | W11: ="Net Book Value" &" "& Text(MR_Depreciation_Schedule!V11,"MMM-YY") -> Net Book Value Dec-25
A12: ="FA-"&TEXT(ROW($A$1),"000") -> FA-001 | B12: ၁၀၇ ပေ x ၁၀၀ ပေ အုတ်ခြံစည်းရိုးနှစ်ဖက်ပါ မြေကွက် | C12: Land | D12: 14000 | E12: 44621 | F12: 45697 | G12: 219000000 | K12: =G12-L12 -> 0 | L12: =IRD_Fixed_Asset_Register_List!Q14 -> 219000000 | M12: Active | N12: သူဌေးကုန်းစက်ရုံ | O12: =L12-0 -> 219000000 | P12: =O12-0 -> 219000000 | Q12: =P12-0 -> 219000000 | R12: =Q12-0 -> 219000000 | S12: =R12-0 -> 219000000 | T12: =S12-0 -> 219000000 | U12: =T12-0 -> 219000000 | V12: =U12-0 -> 219000000 | W12: =V12-0 -> 219000000
A13: ="FA-"&TEXT(ROW(A2),"000") -> FA-002 | B13: စက်ရုံပင်မအဆောက်အဦး ၄၅ ပေ x ၆၀ ပေ | C13: Buildings & Structures | D13: 14100 | E13: 44621 | F13: 45697 | G13: 80000000 | H13: 20 | I13: 0.05 | J13: Straight-Line | K13: =G13-L13 -> 12666667 | L13: =IRD_Fixed_Asset_Register_List!Q15 -> 67333333 | M13: Active | N13: သူဌေးကုန်းစက်ရုံ | O13: =L13-MR_Depreciation_Schedule!N13 -> 67000000 | P13: =O13-IRD_Depreciation_Schedule!P13 -> 66666667 | Q13: =P13-IRD_Depreciation_Schedule!Q13 -> 66333333 | R13: =Q13-IRD_Depreciation_Schedule!S13 -> 66000000 | S13: =R13-IRD_Depreciation_Schedule!T13 -> 65666667 | T13: =S13-IRD_Depreciation_Schedule!U13 -> 65333333 | U13: =T13-IRD_Depreciation_Schedule!V13 -> 65000000 | V13: =U13-IRD_Depreciation_Schedule!W13 -> 64666667 | W13: =V13-IRD_Depreciation_Schedule!X13 -> 64333333
A14: ="FA-"&TEXT(ROW(A3),"000") -> FA-003 | B14: ဝန်ထမ်းအဆောက်အဦး ၃၀ ပေ x ၂၀ ပေ | C14: Buildings & Structures | D14: 14101 | E14: 44621 | F14: 45697 | G14: 30000000 | H14: 20 | I14: 0.05 | J14: Straight-Line | K14: =G14-L14 -> 4750000 | L14: =IRD_Fixed_Asset_Register_List!Q16 -> 25250000 | M14: Active | N14: သူဌေးကုန်းစက်ရုံ | O14: =L14-MR_Depreciation_Schedule!N14 -> 25125000 | P14: =O14-IRD_Depreciation_Schedule!P14 -> 25000000 | Q14: =P14-IRD_Depreciation_Schedule!Q14 -> 24875000 | R14: =Q14-IRD_Depreciation_Schedule!S14 -> 24750000 | S14: =R14-IRD_Depreciation_Schedule!T14 -> 24625000 | T14: =S14-IRD_Depreciation_Schedule!U14 -> 24500000 | U14: =T14-IRD_Depreciation_Schedule!V14 -> 24375000 | V14: =U14-IRD_Depreciation_Schedule!W14 -> 24250000 | W14: =V14-IRD_Depreciation_Schedule!X14 -> 24125000
A15: ="FA-"&TEXT(ROW(A4),"000") -> FA-004 | B15: ရေသန့်စက် ၂ထပ်အဆောက်အဦး နှင့် အုပ်ကန်ကြီး | C15: Buildings & Structures | D15: 14102 | E15: 44621 | F15: 45697 | G15: 15000000 | H15: 20 | I15: 0.05 | J15: Straight-Line | K15: =G15-L15 -> 2375000 | L15: =IRD_Fixed_Asset_Register_List!Q17 -> 12625000 | M15: Active | N15: သူဌေးကုန်းစက်ရုံ | O15: =L15-MR_Depreciation_Schedule!N15 -> 12562500 | P15: =O15-IRD_Depreciation_Schedule!P15 -> 12500000 | Q15: =P15-IRD_Depreciation_Schedule!Q15 -> 12437500 | R15: =Q15-IRD_Depreciation_Schedule!S15 -> 12375000 | S15: =R15-IRD_Depreciation_Schedule!T15 -> 12312500 | T15: =S15-IRD_Depreciation_Schedule!U15 -> 12250000 | U15: =T15-IRD_Depreciation_Schedule!V15 -> 12187500 | V15: =U15-IRD_Depreciation_Schedule!W15 -> 12125000 | W15: =V15-IRD_Depreciation_Schedule!X15 -> 12062500
A16: ="FA-"&TEXT(ROW(A5),"000") -> FA-005 | B16: အုတ်ခြံစည်းရိုးနှစ်ဖက် | C16: Buildings & Structures | D16: 14103 | E16: 44621 | F16: 45697 | G16: 8000000 | H16: 20 | I16: 0.05 | J16: Straight-Line | K16: =G16-L16 -> 1266666.7 | L16: =IRD_Fixed_Asset_Register_List!Q18 -> 6733333.3 | M16: Active | N16: သူဌေးကုန်းစက်ရုံ | O16: =L16-MR_Depreciation_Schedule!N16 -> 6700000 | P16: =O16-IRD_Depreciation_Schedule!P16 -> 6666666.7 | Q16: =P16-IRD_Depreciation_Schedule!Q16 -> 6633333.3 | R16: =Q16-IRD_Depreciation_Schedule!S16 -> 6600000 | S16: =R16-IRD_Depreciation_Schedule!T16 -> 6566666.7 | T16: =S16-IRD_Depreciation_Schedule!U16 -> 6533333.3 | U16: =T16-IRD_Depreciation_Schedule!V16 -> 6500000 | V16: =U16-IRD_Depreciation_Schedule!W16 -> 6466666.7 | W16: =V16-IRD_Depreciation_Schedule!X16 -> 6433333.3
A17: ="FA-"&TEXT(ROW(A6),"000") -> FA-006 | B17: ၁ တန်ကျ ရေသန့်စက် (၁)လုံး ပစ္စည်းအစုံ | C17: Machinery & Equipment | D17: 14200 | E17: 44621 | F17: 45697 | G17: 14800000 | H17: 5 | I17: =2*(1/H17) -> 0.4 | J17: Double-Declining Method | K17: =G17-L17 -> 2905733.3 | L17: =IRD_Fixed_Asset_Register_List!Q19 -> 11894267 | M17: Active | N17: သူဌေးကုန်းစက်ရုံ | O17: =$L17-MR_Depreciation_Schedule!N17 -> 11497791 | P17: =O17-MR_Depreciation_Schedule!O17 -> 11114531 | Q17: =P17-MR_Depreciation_Schedule!P17 -> 10744047 | R17: =Q17-MR_Depreciation_Schedule!Q17 -> 10385912 | S17: =R17-MR_Depreciation_Schedule!R17 -> 10039715 | T17: =S17-MR_Depreciation_Schedule!S17 -> 9705057.9 | U17: =T17-MR_Depreciation_Schedule!T17 -> 9381556 | V17: =U17-MR_Depreciation_Schedule!U17 -> 9068837.4 | W17: =V17-MR_Depreciation_Schedule!V17 -> 8766542.8
A18: ="FA-"&TEXT(ROW(A7),"000") -> FA-007 | B18: မီတာ (၂) လုံး - Soft Drink Factory | C18: Electrical & Utility Systems | D18: 14201 | E18: 44621 | F18: 45697 | G18: 2000000 | H18: 5 | I18: =2*(1/H18) -> 0.4 | J18: Double-Declining Method | K18: =G18-L18 -> 633333.33 | L18: =IRD_Fixed_Asset_Register_List!Q20 -> 1366666.7 | M18: Active | N18: သူဌေးကုန်းစက်ရုံ | O18: =$L18-MR_Depreciation_Schedule!N18 -> 1321111.1 | P18: =O18-MR_Depreciation_Schedule!O18 -> 1277074.1 | Q18: =P18-MR_Depreciation_Schedule!P18 -> 1234504.9 | R18: =Q18-MR_Depreciation_Schedule!Q18 -> 1193354.8 | S18: =R18-MR_Depreciation_Schedule!R18 -> 1153576.3 | T18: =S18-MR_Depreciation_Schedule!S18 -> 1115123.7 | U18: =T18-MR_Depreciation_Schedule!T18 -> 1077952.9 | V18: =U18-MR_Depreciation_Schedule!U18 -> 1042021.2 | W18: =V18-MR_Depreciation_Schedule!V18 -> 1007287.1
A19: ="FA-"&TEXT(ROW(A8),"000") -> FA-008 | B19: မီးအားမြှင့်စက် (15 KV) - ၂ လုံး | C19: Electrical & Utility Systems | D19: 14202 | E19: 44621 | F19: 45697 | G19: 4000000 | H19: 5 | I19: =2*(1/H19) -> 0.4 | J19: Double-Declining Method | K19: =G19-L19 -> 791666.67 | L19: =IRD_Fixed_Asset_Register_List!Q21 -> 3208333.3 | M19: Active | N19: သူဌေးကုန်းစက်ရုံ | O19: =$L19-MR_Depreciation_Schedule!N19 -> 3101388.9 | P19: =O19-MR_Depreciation_Schedule!O19 -> 2998009.3 | Q19: =P19-MR_Depreciation_Schedule!P19 -> 2898075.6 | R19: =Q19-MR_Depreciation_Schedule!Q19 -> 2801473.1 | S19: =R19-MR_Depreciation_Schedule!R19 -> 2708090.7 | T19: =S19-MR_Depreciation_Schedule!S19 -> 2617821 | U19: =T19-MR_Depreciation_Schedule!T19 -> 2530560.3 | V19: =U19-MR_Depreciation_Schedule!U19 -> 2446208.3 | W19: =V19-MR_Depreciation_Schedule!V19 -> 2364668
A20: ="FA-"&TEXT(ROW(A9),"000") -> FA-009 | B20: အချိုရည် (၂)လုံးကျ စက်ပစ္စည်းစုံ - ၂ စက် | C20: Machinery & Equipment | D20: 14203 | E20: 44621 | F20: 45697 | G20: 50000000 | H20: 5 | I20: =2*(1/H20) -> 0.4 | J20: Double-Declining Method | K20: =G20-L20 -> 9816666.7 | L20: =IRD_Fixed_Asset_Register_List!Q22 -> 40183333 | M20: Active | N20: သူဌေးကုန်းစက်ရုံ | O20: =$L20-MR_Depreciation_Schedule!N20 -> 38843889 | P20: =O20-MR_Depreciation_Schedule!O20 -> 37549093 | Q20: =P20-MR_Depreciation_Schedule!P20 -> 36297456 | R20: =Q20-MR_Depreciation_Schedule!Q20 -> 35087541 | S20: =R20-MR_Depreciation_Schedule!R20 -> 33917956 | T20: =S20-MR_Depreciation_Schedule!S20 -> 32787358 | U20: =T20-MR_Depreciation_Schedule!T20 -> 31694446 | V20: =U20-MR_Depreciation_Schedule!U20 -> 30637964 | W20: =V20-MR_Depreciation_Schedule!V20 -> 29616699
A21: ="FA-"&TEXT(ROW(A10),"000") -> FA-010 | B21: အဲယားကွန်း | C21: Electrical & Utility Systems | D21: 14204 | E21: 44621 | F21: 45697 | G21: 1200000 | H21: 5 | I21: =2*(1/H21) -> 0.4 | J21: Double-Declining Method | K21: =G21-L21 -> 380000 | L21: =IRD_Fixed_Asset_Register_List!Q23 -> 820000 | M21: Active | N21: သူဌေးကုန်းစက်ရုံ | O21: =$L21-MR_Depreciation_Schedule!N21 -> 792666.67 | P21: =O21-MR_Depreciation_Schedule!O21 -> 766244.44 | Q21: =P21-MR_Depreciation_Schedule!P21 -> 740702.96 | R21: =Q21-MR_Depreciation_Schedule!Q21 -> 716012.86 | S21: =R21-MR_Depreciation_Schedule!R21 -> 692145.77 | T21: =S21-MR_Depreciation_Schedule!S21 -> 669074.24 | U21: =T21-MR_Depreciation_Schedule!T21 -> 646771.77 | V21: =U21-MR_Depreciation_Schedule!U21 -> 625212.71 | W21: =V21-MR_Depreciation_Schedule!V21 -> 604372.29
A22: ="FA-"&TEXT(ROW(A11),"000") -> FA-011 | B22: ရေမော်တာ ၃ လုံး | C22: Machinery & Equipment | D22: 14205 | E22: 44621 | F22: 45697 | G22: 600000 | H22: 5 | I22: =2*(1/H22) -> 0.4 | J22: Double-Declining Method | K22: =G22-L22 -> 118750 | L22: =IRD_Fixed_Asset_Register_List!Q24 -> 481250 | M22: Active | N22: သူဌေးကုန်းစက်ရုံ | O22: =$L22-MR_Depreciation_Schedule!N22 -> 465208.33 | P22: =O22-MR_Depreciation_Schedule!O22 -> 449701.39 | Q22: =P22-MR_Depreciation_Schedule!P22 -> 434711.34 | R22: =Q22-MR_Depreciation_Schedule!Q22 -> 420220.96 | S22: =R22-MR_Depreciation_Schedule!R22 -> 406213.6 | T22: =S22-MR_Depreciation_Schedule!S22 -> 392673.15 | U22: =T22-MR_Depreciation_Schedule!T22 -> 379584.04 | V22: =U22-MR_Depreciation_Schedule!U22 -> 366931.24 | W22: =V22-MR_Depreciation_Schedule!V22 -> 354700.2
A23: ="FA-"&TEXT(ROW(A12),"000") -> FA-012 | B23: ရေနွေးကျို စတီးလ်အိုးကြီး | C23: Machinery & Equipment | D23: 14206 | E23: 44621 | F23: 45697 | G23: 200000 | H23: 5 | I23: =2*(1/H23) -> 0.4 | J23: Double-Declining Method | K23: =G23-L23 -> 63333.333 | L23: =IRD_Fixed_Asset_Register_List!Q25 -> 136666.67 | M23: Active | N23: သူဌေးကုန်းစက်ရုံ | O23: =$L23-MR_Depreciation_Schedule!N23 -> 132111.11 | P23: =O23-MR_Depreciation_Schedule!O23 -> 127707.41 | Q23: =P23-MR_Depreciation_Schedule!P23 -> 123450.49 | R23: =Q23-MR_Depreciation_Schedule!Q23 -> 119335.48 | S23: =R23-MR_Depreciation_Schedule!R23 -> 115357.63 | T23: =S23-MR_Depreciation_Schedule!S23 -> 111512.37 | U23: =T23-MR_Depreciation_Schedule!T23 -> 107795.29 | V23: =U23-MR_Depreciation_Schedule!U23 -> 104202.12 | W23: =V23-MR_Depreciation_Schedule!V23 -> 100728.71
A24: ="FA-"&TEXT(ROW(A13),"000") -> FA-013 | B24: ၂ ကောင်အား ရေမော်တာ နှင့် Compressor | C24: Machinery & Equipment | D24: 14207 | E24: 44621 | F24: 45697 | G24: 800000 | H24: 5 | I24: =2*(1/H24) -> 0.4 | J24: Double-Declining Method | K24: =G24-L24 -> 158333.33 | L24: =IRD_Fixed_Asset_Register_List!Q26 -> 641666.67 | M24: Active | N24: သူဌေးကုန်းစက်ရုံ | O24: =$L24-MR_Depreciation_Schedule!N24 -> 620277.78 | P24: =O24-MR_Depreciation_Schedule!O24 -> 599601.85 | Q24: =P24-MR_Depreciation_Schedule!P24 -> 579615.12 | R24: =Q24-MR_Depreciation_Schedule!Q24 -> 560294.62 | S24: =R24-MR_Depreciation_Schedule!R24 -> 541618.13 | T24: =S24-MR_Depreciation_Schedule!S24 -> 523564.19 | U24: =T24-MR_Depreciation_Schedule!T24 -> 506112.05 | V24: =U24-MR_Depreciation_Schedule!U24 -> 489241.65 | W24: =V24-MR_Depreciation_Schedule!V24 -> 472933.6
A25: ="FA-"&TEXT(ROW(A14),"000") -> FA-014 | B25: Yankin Land | C25: Land | D25: 14208 | E25: 45695 | F25: 45695 | G25: 210290000 | K25: =G25-L25 -> 0 | L25: =IRD_Fixed_Asset_Register_List!Q27 -> 210290000 | M25: Active | N25: ရန်ကင်းစက်ရုံ | O25: =$L25-MR_Depreciation_Schedule!N25 -> 210290000 | P25: =O25-MR_Depreciation_Schedule!O25 -> 210290000 | Q25: =P25-MR_Depreciation_Schedule!P25 -> 210290000 | R25: =Q25-MR_Depreciation_Schedule!Q25 -> 210290000 | S25: =R25-MR_Depreciation_Schedule!R25 -> 210290000 | T25: =S25-MR_Depreciation_Schedule!S25 -> 210290000 | U25: =T25-MR_Depreciation_Schedule!T25 -> 210290000 | V25: =U25-MR_Depreciation_Schedule!U25 -> 210290000 | W25: =V25-MR_Depreciation_Schedule!V25 -> 210290000
A26: ="FA-"&TEXT(ROW(A15),"000") -> FA-015 | B26: မီတာ (၂) လုံး - Yankin Drinking Water Facility | C26: Electrical & Utility Systems | D26: 14209 | E26: 45703 | F26: 45703 | G26: 6856000 | H26: 5 | I26: =2*(1/H26) -> 0.4 | J26: Double-Declining Method | K26: =G26-L26 -> 57133.333 | L26: =IRD_Fixed_Asset_Register_List!Q28 -> 6798866.7 | M26: Active | N26: ရန်ကင်းစက်ရုံ | O26: =$L26-MR_Depreciation_Schedule!N26 -> 6572237.8 | P26: =O26-MR_Depreciation_Schedule!O26 -> 6353163.2 | Q26: =P26-MR_Depreciation_Schedule!P26 -> 6141391.1 | R26: =Q26-MR_Depreciation_Schedule!Q26 -> 5936678 | S26: =R26-MR_Depreciation_Schedule!R26 -> 5738788.8 | T26: =S26-MR_Depreciation_Schedule!S26 -> 5547495.8 | U26: =T26-MR_Depreciation_Schedule!T26 -> 5362579.3 | V26: =U26-MR_Depreciation_Schedule!U26 -> 5183826.6 | W26: =V26-MR_Depreciation_Schedule!V26 -> 5011032.4
A27: ="FA-"&TEXT(ROW(A16),"000") -> FA-016 | B27: 1000 လီတာ စတီးအိုး လဲး | C27: Machinery & Equipment | D27: 14210 | E27: 45724 | F27: =E27 -> 45724 | G27: 1520000 | H27: 5 | I27: =2*(1/H27) -> 0.4 | J27: Double-Declining Method | K27: =G27-L27 -> 12666.667 | L27: =IRD_Fixed_Asset_Register_List!Q29 -> 1507333.3 | M27: Active | N27: ရန်ကင်းစက်ရုံ | O27: =$L27-MR_Depreciation_Schedule!N27 -> 1457088.9 | P27: =O27-MR_Depreciation_Schedule!O27 -> 1408519.3 | Q27: =P27-MR_Depreciation_Schedule!P27 -> 1361568.6 | R27: =Q27-MR_Depreciation_Schedule!Q27 -> 1316183 | S27: =R27-MR_Depreciation_Schedule!R27 -> 1272310.2 | T27: =S27-MR_Depreciation_Schedule!S27 -> 1229899.9 | U27: =T27-MR_Depreciation_Schedule!T27 -> 1188903.2 | V27: =U27-MR_Depreciation_Schedule!U27 -> 1149273.1 | W27: =V27-MR_Depreciation_Schedule!V27 -> 1110964
A28: ="FA-"&TEXT(ROW(A17),"000") -> FA-017 | B28: 200 KVA Transformer | C28: Electrical & Utility Systems | D28: =D27+1 -> 14211 | E28: 45866 | F28: =E28 -> 45866 | G28: 92000000 | H28: 5 | I28: =2*(1/H28) -> 0.4 | J28: Double-Declining Method | K28: 0 | L28: 0 | M28: Active | N28: ရန်ကင်းစက်ရုံ | O28: =$L28-MR_Depreciation_Schedule!N28 -> 0 | P28: =$L28-MR_Depreciation_Schedule!O28 -> 0 | Q28: =$L28-MR_Depreciation_Schedule!P28 -> 0 | R28: =G28 -> 92000000 | S28: =G28 -> 92000000 | T28: =G28 -> 92000000 | U28: =G28 -> 92000000 | V28: =U28-MR_Depreciation_Schedule!U28 -> 92000000 | W28: =V28-MR_Depreciation_Schedule!V28 -> 88933333
A29: ="FA-"&TEXT(ROW(A18),"000") -> FA-018 | B29: R.O Water Treatment System-5 Tons/HR | C29: Machinery & Equipment | D29: =D28+1 -> 14212 | E29: 45868 | F29: =E29 -> 45868 | G29: 68000000 | H29: 5 | I29: =2*(1/H29) -> 0.4 | J29: Double-Declining Method | K29: 0 | L29: 0 | M29: Active | N29: ရန်ကင်းစက်ရုံ | O29: =$L29-MR_Depreciation_Schedule!N29 -> 0 | P29: =$L29-MR_Depreciation_Schedule!O29 -> 0 | Q29: =$L29-MR_Depreciation_Schedule!P29 -> 0 | R29: =S29 -> 68000000 | S29: =G29 -> 68000000 | T29: =S29 -> 68000000 | U29: =T29 -> 68000000 | V29: =U29-MR_Depreciation_Schedule!U29 -> 68000000 | W29: =V29-MR_Depreciation_Schedule!V29 -> 65733333
A30: ="FA-"&TEXT(ROW(A19),"000") -> FA-019 | B30: 120' x 50' Main Factory Building and 15' x 50' Two-storey building | C30: Buildings & Structures | D30: =D29+1 -> 14213 | E30: 45900 | F30: =E30 -> 45900 | G30: 316445000 | H30: 20 | I30: 0.05 | J30: Straight-Line | K30: 0 | L30: 0 | M30: Active | N30: ရန်ကင်းစက်ရုံ | O30: =$L30-MR_Depreciation_Schedule!N30 -> 0 | P30: =$L30-MR_Depreciation_Schedule!O30 -> 0 | Q30: =$L30-MR_Depreciation_Schedule!P30 -> 0 | R30: =$L30-MR_Depreciation_Schedule!Q30 -> 0 | S30: =G30 -> 316445000 | T30: =G30 -> 316445000 | U30: =G30 -> 316445000 | V30: =U30-MR_Depreciation_Schedule!U30 -> 316445000 | W30: =V30-MR_Depreciation_Schedule!V30 -> 3.1512648e+08
A31: ="FA-"&TEXT(ROW(A20),"000") -> FA-020 | B31: Pressure pumps with accessories | C31: Machinery & Equipment | D31: =D30+1 -> 14214 | E31: 45908 | F31: =E31 -> 45908 | G31: 2182300 | H31: 5 | I31: =2*(1/H31) -> 0.4 | J31: Double-Declining Method | K31: 0 | L31: 0 | M31: Active | N31: ရန်ကင်းစက်ရုံ | O31: =$L31-MR_Depreciation_Schedule!N31 -> 0 | P31: =$L31-MR_Depreciation_Schedule!O31 -> 0 | Q31: =$L31-MR_Depreciation_Schedule!P31 -> 0 | R31: =$L31-MR_Depreciation_Schedule!Q31 -> 0 | S31: =$L31-MR_Depreciation_Schedule!R31 -> 0 | T31: =G31 -> 2182300 | U31: =G31 -> 2182300 | V31: =U31-MR_Depreciation_Schedule!U31 -> 2182300 | W31: =V31-MR_Depreciation_Schedule!V31 -> 2109556.7
A32: ="FA-"&TEXT(ROW(A21),"000") -> FA-021

Sheet MR_Depreciation_Schedule
M2: Accounts | N2: =N11 -> Apr-2025 | O2: =O11 -> May-2025 | P2: =P11 -> Jun-2025 | Q2: =Q11 -> Jul-2025 | R2: =R11 -> Aug-2025 | S2: =S11 -> Sep-2025 | T2: =T11 -> Oct-2025 | U2: =U11 -> Nov-2025 | ... CS2: =CS11 -> Mar-2032
M3: Land | N3: =SUMIF($C:$C,$M3,N:N) -> 0 | O3: =SUMIF($C:$C,$M3,O:O) -> 0 | P3: =SUMIF($C:$C,$M3,P:P) -> 0 | Q3: =SUMIF($C:$C,$M3,Q:Q) -> 0 | R3: =SUMIF($C:$C,$M3,R:R) -> 0 | S3: =SUMIF($C:$C,$M3,S:S) -> 0 | T3: =SUMIF($C:$C,$M3,T:T) -> 0 | U3: =SUMIF($C:$C,$M3,U:U) -> 0 | V3: =SUMIF($C:$C,$M3,V:V) -> 0 | W3: =SUMIF($C:$C,$M3,W:W) -> 0 | X3: =SUMIF($C:$C,$M3,X:X) -> 0 | Y3: =SUMIF($C:$C,$M3,Y:Y) -> 0 | Z3: =SUMIF($C:$C,$M3,Z:Z) -> 0 | AA3: =SUMIF($C:$C,$M3,AA:AA) -> 0 | AB3: =SUMIF($C:$C,$M3,AB:AB) -> 0 | AC3: =SUMIF($C:$C,$M3,AC:AC) -> 0 | AD3: =SUMIF($C:$C,$M3,AD:AD) -> 0 | AE3: =SUMIF($C:$C,$M3,AE:AE) -> 0 | AF3: =SUMIF($C:$C,$M3,AF:AF) -> 0 | AG3: =SUMIF($C:$C,$M3,AG:AG) -> 0 | AH3: =SUMIF($C:$C,$M3,AH:AH) -> 0 | AI3: =SUMIF($C:$C,$M3,AI:AI) -> 0 | AJ3: =SUMIF($C:$C,$M3,AJ:AJ) -> 0 | AK3: =SUMIF($C:$C,$M3,AK:AK) -> 0 | AL3: =SUMIF($C:$C,$M3,AL:AL) -> 0 | AM3: =SUMIF($C:$C,$M3,AM:AM) -> 0 | AN3: =SUMIF($C:$C,$M3,AN:AN) -> 0 | AO3: =SUMIF($C:$C,$M3,AO:AO) -> 0 | AP3: =SUMIF($C:$C,$M3,AP:AP) -> 0 | AQ3: =SUMIF($C:$C,$M3,AQ:AQ) -> 0 | AR3: =SUMIF($C:$C,$M3,AR:AR) -> 0 | AS3: =SUMIF($C:$C,$M3,AS:AS) -> 0 | AT3: =SUMIF($C:$C,$M3,AT:AT) -> 0 | AU3: =SUMIF($C:$C,$M3,AU:AU) -> 0 | AV3: =SUMIF($C:$C,$M3,AV:AV) -> 0 | AW3: =SUMIF($C:$C,$M3,AW:AW) -> 0 | AX3: =SUMIF($C:$C,$M3,AX:AX) -> 0 | AY3: =SUMIF($C:$C,$M3,AY:AY) -> 0 | AZ3: =SUMIF($C:$C,$M3,AZ:AZ) -> 0 | BA3: =SUMIF($C:$C,$M3,BA:BA) -> 0 | BB3: =SUMIF($C:$C,$M3,BB:BB) -> 0 | BC3: =SUMIF($C:$C,$M3,BC:BC) -> 0 | BD3: =SUMIF($C:$C,$M3,BD:BD) -> 0 | BE3: =SUMIF($C:$C,$M3,BE:BE) -> 0 | BF3: =SUMIF($C:$C,$M3,BF:BF) -> 0 | BG3: =SUMIF($C:$C,$M3,BG:BG) -> 0 | BH3: =SUMIF($C:$C,$M3,BH:BH) -> 0 | BI3: =SUMIF($C:$C,$M3,BI:BI) -> 0 | BJ3: =SUMIF($C:$C,$M3,BJ:BJ) -> 0 | BK3: =SUMIF($C:$C,$M3,BK:BK) -> 0 | BL3: =SUMIF($C:$C,$M3,BL:BL) -> 0 | BM3: =SUMIF($C:$C,$M3,BM:BM) -> 0 | BN3: =SUMIF($C:$C,$M3,BN:BN) -> 0 | BO3: =SUMIF($C:$C,$M3,BO:BO) -> 0 | BP3: =SUMIF($C:$C,$M3,BP:BP) -> 0 | BQ3: =SUMIF($C:$C,$M3,BQ:BQ) -> 0 | BR3: =SUMIF($C:$C,$M3,BR:BR) -> 0 | BS3: =SUMIF($C:$C,$M3,BS:BS) -> 0 | BT3: =SUMIF($C:$C,$M3,BT:BT) -> 0 | BU3: =SUMIF($C:$C,$M3,BU:BU) -> 0 | BV3: =SUMIF($C:$C,$M3,BV:BV) -> 0 | BW3: =SUMIF($C:$C,$M3,BW:BW) -> 0 | BX3: =SUMIF($C:$C,$M3,BX:BX) -> 0 | BY3: =SUMIF($C:$C,$M3,BY:BY) -> 0 | BZ3: =SUMIF($C:$C,$M3,BZ:BZ) -> 0 | CA3: =SUMIF($C:$C,$M3,CA:CA) -> 0 | CB3: =SUMIF($C:$C,$M3,CB:CB) -> 0 | CC3: =SUMIF($C:$C,$M3,CC:CC) -> 0 | CD3: =SUMIF($C:$C,$M3,CD:CD) -> 0 | CE3: =SUMIF($C:$C,$M3,CE:CE) -> 0 | CF3: =SUMIF($C:$C,$M3,CF:CF) -> 0 | CG3: =SUMIF($C:$C,$M3,CG:CG) -> 0 | CH3: =SUMIF($C:$C,$M3,CH:CH) -> 0 | CI3: =SUMIF($C:$C,$M3,CI:CI) -> 0 | CJ3: =SUMIF($C:$C,$M3,CJ:CJ) -> 0 | CK3: =SUMIF($C:$C,$M3,CK:CK) -> 0 | CL3: =SUMIF($C:$C,$M3,CL:CL) -> 0 | CM3: =SUMIF($C:$C,$M3,CM:CM) -> 0 | CN3: =SUMIF($C:$C,$M3,CN:CN) -> 0 | CO3: =SUMIF($C:$C,$M3,CO:CO) -> 0 | CP3: =SUMIF($C:$C,$M3,CP:CP) -> 0 | CQ3: =SUMIF($C:$C,$M3,CQ:CQ) -> 0 | CR3: =SUMIF($C:$C,$M3,CR:CR) -> 0 | CS3: =SUMIF($C:$C,$M3,CS:CS) -> 0
M4: Buildings & Structures | N4: =SUMIF($C:$C,$M4,N:N) -> 554166.67 | O4: =SUMIF($C:$C,$M4,O:O) -> 554166.67 | P4: =SUMIF($C:$C,$M4,P:P) -> 554166.67 | Q4: =SUMIF($C:$C,$M4,Q:Q) -> 554166.67 | R4: =SUMIF($C:$C,$M4,R:R) -> 554166.67 | S4: =SUMIF($C:$C,$M4,S:S) -> 554166.67 | T4: =SUMIF($C:$C,$M4,T:T) -> 554166.67 | U4: =SUMIF($C:$C,$M4,U:U) -> 554166.67 | V4: =SUMIF($C:$C,$M4,V:V) -> 1872687.5 | W4: =SUMIF($C:$C,$M4,W:W) -> 1867193.7 | X4: =SUMIF($C:$C,$M4,X:X) -> 554166.67 | Y4: =SUMIF($C:$C,$M4,Y:Y) -> 554166.67 | Z4: =SUMIF($C:$C,$M4,Z:Z) -> 554166.67 | AA4: =SUMIF($C:$C,$M4,AA:AA) -> 554166.67 | AB4: =SUMIF($C:$C,$M4,AB:AB) -> 554166.67 | AC4: =SUMIF($C:$C,$M4,AC:AC) -> 554166.67 | AD4: =SUMIF($C:$C,$M4,AD:AD) -> 554166.67 | AE4: =SUMIF($C:$C,$M4,AE:AE) -> 554166.67 | AF4: =SUMIF($C:$C,$M4,AF:AF) -> 554166.67 | AG4: =SUMIF($C:$C,$M4,AG:AG) -> 554166.67 | AH4: =SUMIF($C:$C,$M4,AH:AH) -> 554166.67 | AI4: =SUMIF($C:$C,$M4,AI:AI) -> 554166.67 | AJ4: =SUMIF($C:$C,$M4,AJ:AJ) -> 554166.67 | AK4: =SUMIF($C:$C,$M4,AK:AK) -> 554166.67 | AL4: =SUMIF($C:$C,$M4,AL:AL) -> 554166.67 | AM4: =SUMIF($C:$C,$M4,AM:AM) -> 554166.67 | AN4: =SUMIF($C:$C,$M4,AN:AN) -> 554166.67 | AO4: =SUMIF($C:$C,$M4,AO:AO) -> 554166.67 | AP4: =SUMIF($C:$C,$M4,AP:AP) -> 554166.67 | AQ4: =SUMIF($C:$C,$M4,AQ:AQ) -> 554166.67 | AR4: =SUMIF($C:$C,$M4,AR:AR) -> 554166.67 | AS4: =SUMIF($C:$C,$M4,AS:AS) -> 554166.67 | AT4: =SUMIF($C:$C,$M4,AT:AT) -> 554166.67 | AU4: =SUMIF($C:$C,$M4,AU:AU) -> 554166.67 | AV4: =SUMIF($C:$C,$M4,AV:AV) -> 554166.67 | AW4: =SUMIF($C:$C,$M4,AW:AW) -> 554166.67 | AX4: =SUMIF($C:$C,$M4,AX:AX) -> 554166.67 | AY4: =SUMIF($C:$C,$M4,AY:AY) -> 554166.67 | AZ4: =SUMIF($C:$C,$M4,AZ:AZ) -> 554166.67 | BA4: =SUMIF($C:$C,$M4,BA:BA) -> 554166.67 | BB4: =SUMIF($C:$C,$M4,BB:BB) -> 554166.67 | BC4: =SUMIF($C:$C,$M4,BC:BC) -> 554166.67 | BD4: =SUMIF($C:$C,$M4,BD:BD) -> 554166.67 | BE4: =SUMIF($C:$C,$M4,BE:BE) -> 554166.67 | BF4: =SUMIF($C:$C,$M4,BF:BF) -> 554166.67 | BG4: =SUMIF($C:$C,$M4,BG:BG) -> 554166.67 | BH4: =SUMIF($C:$C,$M4,BH:BH) -> 554166.67 | BI4: =SUMIF($C:$C,$M4,BI:BI) -> 554166.67 | BJ4: =SUMIF($C:$C,$M4,BJ:BJ) -> 554166.67 | BK4: =SUMIF($C:$C,$M4,BK:BK) -> 554166.67 | BL4: =SUMIF($C:$C,$M4,BL:BL) -> 554166.67 | BM4: =SUMIF($C:$C,$M4,BM:BM) -> 554166.67 | BN4: =SUMIF($C:$C,$M4,BN:BN) -> 554166.67 | BO4: =SUMIF($C:$C,$M4,BO:BO) -> 554166.67 | BP4: =SUMIF($C:$C,$M4,BP:BP) -> 554166.67 | BQ4: =SUMIF($C:$C,$M4,BQ:BQ) -> 554166.67 | BR4: =SUMIF($C:$C,$M4,BR:BR) -> 554166.67 | BS4: =SUMIF($C:$C,$M4,BS:BS) -> 554166.67 | BT4: =SUMIF($C:$C,$M4,BT:BT) -> 554166.67 | BU4: =SUMIF($C:$C,$M4,BU:BU) -> 554166.67 | BV4: =SUMIF($C:$C,$M4,BV:BV) -> 554166.67 | BW4: =SUMIF($C:$C,$M4,BW:BW) -> 554166.67 | BX4: =SUMIF($C:$C,$M4,BX:BX) -> 554166.67 | BY4: =SUMIF($C:$C,$M4,BY:BY) -> 554166.67 | BZ4: =SUMIF($C:$C,$M4,BZ:BZ) -> 554166.67 | CA4: =SUMIF($C:$C,$M4,CA:CA) -> 554166.67 | CB4: =SUMIF($C:$C,$M4,CB:CB) -> 554166.67 | CC4: =SUMIF($C:$C,$M4,CC:CC) -> 554166.67 | CD4: =SUMIF($C:$C,$M4,CD:CD) -> 554166.67 | CE4: =SUMIF($C:$C,$M4,CE:CE) -> 554166.67 | CF4: =SUMIF($C:$C,$M4,CF:CF) -> 554166.67 | CG4: =SUMIF($C:$C,$M4,CG:CG) -> 554166.67 | CH4: =SUMIF($C:$C,$M4,CH:CH) -> 554166.67 | CI4: =SUMIF($C:$C,$M4,CI:CI) -> 554166.67 | CJ4: =SUMIF($C:$C,$M4,CJ:CJ) -> 554166.67 | CK4: =SUMIF($C:$C,$M4,CK:CK) -> 554166.67 | CL4: =SUMIF($C:$C,$M4,CL:CL) -> 554166.67 | CM4: =SUMIF($C:$C,$M4,CM:CM) -> 554166.67 | CN4: =SUMIF($C:$C,$M4,CN:CN) -> 554166.67 | CO4: =SUMIF($C:$C,$M4,CO:CO) -> 554166.67 | CP4: =SUMIF($C:$C,$M4,CP:CP) -> 554166.67 | CQ4: =SUMIF($C:$C,$M4,CQ:CQ) -> 554166.67 | CR4: =SUMIF($C:$C,$M4,CR:CR) -> 554166.67 | CS4: =SUMIF($C:$C,$M4,CS:CS) -> 554166.67
M5: Machinery & Equipment | N5: =SUMIF($C:$C,$M5,N:N) -> 1828150.6 | O5: =SUMIF($C:$C,$M5,O:O) -> 1767212.2 | P5: =SUMIF($C:$C,$M5,P:P) -> 1708305.1 | Q5: =SUMIF($C:$C,$M5,Q:Q) -> 1651361.6 | R5: =SUMIF($C:$C,$M5,R:R) -> 1596316.2 | S5: =SUMIF($C:$C,$M5,S:S) -> 1543105.7 | T5: =SUMIF($C:$C,$M5,T:T) -> 1491668.8 | U5: =SUMIF($C:$C,$M5,U:U) -> 1441946.5 | V5: =SUMIF($C:$C,$M5,V:V) -> 3733291.7 | W5: =SUMIF($C:$C,$M5,W:W) -> 3608848.6 | X5: =SUMIF($C:$C,$M5,X:X) -> 0 | Y5: =SUMIF($C:$C,$M5,Y:Y) -> 0 | Z5: =SUMIF($C:$C,$M5,Z:Z) -> 0 | AA5: =SUMIF($C:$C,$M5,AA:AA) -> 0 | AB5: =SUMIF($C:$C,$M5,AB:AB) -> 0 | AC5: =SUMIF($C:$C,$M5,AC:AC) -> 0 | AD5: =SUMIF($C:$C,$M5,AD:AD) -> 0 | AE5: =SUMIF($C:$C,$M5,AE:AE) -> 0 | AF5: =SUMIF($C:$C,$M5,AF:AF) -> 0 | AG5: =SUMIF($C:$C,$M5,AG:AG) -> 0 | AH5: =SUMIF($C:$C,$M5,AH:AH) -> 0 | AI5: =SUMIF($C:$C,$M5,AI:AI) -> 0 | AJ5: =SUMIF($C:$C,$M5,AJ:AJ) -> 0 | AK5: =SUMIF($C:$C,$M5,AK:AK) -> 0 | AL5: =SUMIF($C:$C,$M5,AL:AL) -> 0 | AM5: =SUMIF($C:$C,$M5,AM:AM) -> 0 | AN5: =SUMIF($C:$C,$M5,AN:AN) -> 0 | AO5: =SUMIF($C:$C,$M5,AO:AO) -> 0 | AP5: =SUMIF($C:$C,$M5,AP:AP) -> 0 | AQ5: =SUMIF($C:$C,$M5,AQ:AQ) -> 0 | AR5: =SUMIF($C:$C,$M5,AR:AR) -> 0 | AS5: =SUMIF($C:$C,$M5,AS:AS) -> 0 | AT5: =SUMIF($C:$C,$M5,AT:AT) -> 0 | AU5: =SUMIF($C:$C,$M5,AU:AU) -> 0 | AV5: =SUMIF($C:$C,$M5,AV:AV) -> 0 | AW5: =SUMIF($C:$C,$M5,AW:AW) -> 0 | AX5: =SUMIF($C:$C,$M5,AX:AX) -> 0 | AY5: =SUMIF($C:$C,$M5,AY:AY) -> 0 | AZ5: =SUMIF($C:$C,$M5,AZ:AZ) -> 0 | BA5: =SUMIF($C:$C,$M5,BA:BA) -> 0 | BB5: =SUMIF($C:$C,$M5,BB:BB) -> 0 | BC5: =SUMIF($C:$C,$M5,BC:BC) -> 0 | BD5: =SUMIF($C:$C,$M5,BD:BD) -> 0 | BE5: =SUMIF($C:$C,$M5,BE:BE) -> 0 | BF5: =SUMIF($C:$C,$M5,BF:BF) -> 0 | BG5: =SUMIF($C:$C,$M5,BG:BG) -> 0 | BH5: =SUMIF($C:$C,$M5,BH:BH) -> 0 | BI5: =SUMIF($C:$C,$M5,BI:BI) -> 0 | BJ5: =SUMIF($C:$C,$M5,BJ:BJ) -> 0 | BK5: =SUMIF($C:$C,$M5,BK:BK) -> 0 | BL5: =SUMIF($C:$C,$M5,BL:BL) -> 0 | BM5: =SUMIF($C:$C,$M5,BM:BM) -> 0 | BN5: =SUMIF($C:$C,$M5,BN:BN) -> 0 | BO5: =SUMIF($C:$C,$M5,BO:BO) -> 0 | BP5: =SUMIF($C:$C,$M5,BP:BP) -> 0 | BQ5: =SUMIF($C:$C,$M5,BQ:BQ) -> 0 | BR5: =SUMIF($C:$C,$M5,BR:BR) -> 0 | BS5: =SUMIF($C:$C,$M5,BS:BS) -> 0 | BT5: =SUMIF($C:$C,$M5,BT:BT) -> 0 | BU5: =SUMIF($C:$C,$M5,BU:BU) -> 0 | BV5: =SUMIF($C:$C,$M5,BV:BV) -> 0 | BW5: =SUMIF($C:$C,$M5,BW:BW) -> 0 | BX5: =SUMIF($C:$C,$M5,BX:BX) -> 0 | BY5: =SUMIF($C:$C,$M5,BY:BY) -> 0 | BZ5: =SUMIF($C:$C,$M5,BZ:BZ) -> 0 | CA5: =SUMIF($C:$C,$M5,CA:CA) -> 0 | CB5: =SUMIF($C:$C,$M5,CB:CB) -> 0 | CC5: =SUMIF($C:$C,$M5,CC:CC) -> 0 | CD5: =SUMIF($C:$C,$M5,CD:CD) -> 0 | CE5: =SUMIF($C:$C,$M5,CE:CE) -> 0 | CF5: =SUMIF($C:$C,$M5,CF:CF) -> 0 | CG5: =SUMIF($C:$C,$M5,CG:CG) -> 0 | CH5: =SUMIF($C:$C,$M5,CH:CH) -> 0 | CI5: =SUMIF($C:$C,$M5,CI:CI) -> 0 | CJ5: =SUMIF($C:$C,$M5,CJ:CJ) -> 0 | CK5: =SUMIF($C:$C,$M5,CK:CK) -> 0 | CL5: =SUMIF($C:$C,$M5,CL:CL) -> 0 | CM5: =SUMIF($C:$C,$M5,CM:CM) -> 0 | CN5: =SUMIF($C:$C,$M5,CN:CN) -> 0 | CO5: =SUMIF($C:$C,$M5,CO:CO) -> 0 | CP5: =SUMIF($C:$C,$M5,CP:CP) -> 0 | CQ5: =SUMIF($C:$C,$M5,CQ:CQ) -> 0 | CR5: =SUMIF($C:$C,$M5,CR:CR) -> 0 | CS5: =SUMIF($C:$C,$M5,CS:CS) -> 0
M6: Office & Facility Equipment | N6: =SUMIF($C:$C,$M6,N:N) -> 0 | O6: =SUMIF($C:$C,$M6,O:O) -> 0 | P6: =SUMIF($C:$C,$M6,P:P) -> 0 | Q6: =SUMIF($C:$C,$M6,Q:Q) -> 0 | R6: =SUMIF($C:$C,$M6,R:R) -> 0 | S6: =SUMIF($C:$C,$M6,S:S) -> 0 | T6: =SUMIF($C:$C,$M6,T:T) -> 0 | U6: =SUMIF($C:$C,$M6,U:U) -> 0 | V6: =SUMIF($C:$C,$M6,V:V) -> 0 | W6: =SUMIF($C:$C,$M6,W:W) -> 0 | X6: =SUMIF($C:$C,$M6,X:X) -> 0 | Y6: =SUMIF($C:$C,$M6,Y:Y) -> 0 | Z6: =SUMIF($C:$C,$M6,Z:Z) -> 0 | AA6: =SUMIF($C:$C,$M6,AA:AA) -> 0 | AB6: =SUMIF($C:$C,$M6,AB:AB) -> 0 | AC6: =SUMIF($C:$C,$M6,AC:AC) -> 0 | AD6: =SUMIF($C:$C,$M6,AD:AD) -> 0 | AE6: =SUMIF($C:$C,$M6,AE:AE) -> 0 | AF6: =SUMIF($C:$C,$M6,AF:AF) -> 0 | AG6: =SUMIF($C:$C,$M6,AG:AG) -> 0 | AH6: =SUMIF($C:$C,$M6,AH:AH) -> 0 | AI6: =SUMIF($C:$C,$M6,AI:AI) -> 0 | AJ6: =SUMIF($C:$C,$M6,AJ:AJ) -> 0 | AK6: =SUMIF($C:$C,$M6,AK:AK) -> 0 | AL6: =SUMIF($C:$C,$M6,AL:AL) -> 0 | AM6: =SUMIF($C:$C,$M6,AM:AM) -> 0 | AN6: =SUMIF($C:$C,$M6,AN:AN) -> 0 | AO6: =SUMIF($C:$C,$M6,AO:AO) -> 0 | AP6: =SUMIF($C:$C,$M6,AP:AP) -> 0 | AQ6: =SUMIF($C:$C,$M6,AQ:AQ) -> 0 | AR6: =SUMIF($C:$C,$M6,AR:AR) -> 0 | AS6: =SUMIF($C:$C,$M6,AS:AS) -> 0 | AT6: =SUMIF($C:$C,$M6,AT:AT) -> 0 | AU6: =SUMIF($C:$C,$M6,AU:AU) -> 0 | AV6: =SUMIF($C:$C,$M6,AV:AV) -> 0 | AW6: =SUMIF($C:$C,$M6,AW:AW) -> 0 | AX6: =SUMIF($C:$C,$M6,AX:AX) -> 0 | AY6: =SUMIF($C:$C,$M6,AY:AY) -> 0 | AZ6: =SUMIF($C:$C,$M6,AZ:AZ) -> 0 | BA6: =SUMIF($C:$C,$M6,BA:BA) -> 0 | BB6: =SUMIF($C:$C,$M6,BB:BB) -> 0 | BC6: =SUMIF($C:$C,$M6,BC:BC) -> 0 | BD6: =SUMIF($C:$C,$M6,BD:BD) -> 0 | BE6: =SUMIF($C:$C,$M6,BE:BE) -> 0 | BF6: =SUMIF($C:$C,$M6,BF:BF) -> 0 | BG6: =SUMIF($C:$C,$M6,BG:BG) -> 0 | BH6: =SUMIF($C:$C,$M6,BH:BH) -> 0 | BI6: =SUMIF($C:$C,$M6,BI:BI) -> 0 | BJ6: =SUMIF($C:$C,$M6,BJ:BJ) -> 0 | BK6: =SUMIF($C:$C,$M6,BK:BK) -> 0 | BL6: =SUMIF($C:$C,$M6,BL:BL) -> 0 | BM6: =SUMIF($C:$C,$M6,BM:BM) -> 0 | BN6: =SUMIF($C:$C,$M6,BN:BN) -> 0 | BO6: =SUMIF($C:$C,$M6,BO:BO) -> 0 | BP6: =SUMIF($C:$C,$M6,BP:BP) -> 0 | BQ6: =SUMIF($C:$C,$M6,BQ:BQ) -> 0 | BR6: =SUMIF($C:$C,$M6,BR:BR) -> 0 | BS6: =SUMIF($C:$C,$M6,BS:BS) -> 0 | BT6: =SUMIF($C:$C,$M6,BT:BT) -> 0 | BU6: =SUMIF($C:$C,$M6,BU:BU) -> 0 | BV6: =SUMIF($C:$C,$M6,BV:BV) -> 0 | BW6: =SUMIF($C:$C,$M6,BW:BW) -> 0 | BX6: =SUMIF($C:$C,$M6,BX:BX) -> 0 | BY6: =SUMIF($C:$C,$M6,BY:BY) -> 0 | BZ6: =SUMIF($C:$C,$M6,BZ:BZ) -> 0 | CA6: =SUMIF($C:$C,$M6,CA:CA) -> 0 | CB6: =SUMIF($C:$C,$M6,CB:CB) -> 0 | CC6: =SUMIF($C:$C,$M6,CC:CC) -> 0 | CD6: =SUMIF($C:$C,$M6,CD:CD) -> 0 | CE6: =SUMIF($C:$C,$M6,CE:CE) -> 0 | CF6: =SUMIF($C:$C,$M6,CF:CF) -> 0 | CG6: =SUMIF($C:$C,$M6,CG:CG) -> 0 | CH6: =SUMIF($C:$C,$M6,CH:CH) -> 0 | CI6: =SUMIF($C:$C,$M6,CI:CI) -> 0 | CJ6: =SUMIF($C:$C,$M6,CJ:CJ) -> 0 | CK6: =SUMIF($C:$C,$M6,CK:CK) -> 0 | CL6: =SUMIF($C:$C,$M6,CL:CL) -> 0 | CM6: =SUMIF($C:$C,$M6,CM:CM) -> 0 | CN6: =SUMIF($C:$C,$M6,CN:CN) -> 0 | CO6: =SUMIF($C:$C,$M6,CO:CO) -> 0 | CP6: =SUMIF($C:$C,$M6,CP:CP) -> 0 | CQ6: =SUMIF($C:$C,$M6,CQ:CQ) -> 0 | CR6: =SUMIF($C:$C,$M6,CR:CR) -> 0 | CS6: =SUMIF($C:$C,$M6,CS:CS) -> 0
M7: Electrical & Utility Systems | N7: =SUMIF($C:$C,$M7,N:N) -> 406462.22 | O7: =SUMIF($C:$C,$M7,O:O) -> 392913.48 | P7: =SUMIF($C:$C,$M7,P:P) -> 379816.37 | Q7: =SUMIF($C:$C,$M7,Q:Q) -> 367155.82 | R7: =SUMIF($C:$C,$M7,R:R) -> 354917.29 | S7: =SUMIF($C:$C,$M7,S:S) -> 343086.72 | T7: =SUMIF($C:$C,$M7,T:T) -> 331650.49 | U7: =SUMIF($C:$C,$M7,U:U) -> 320595.48 | V7: =SUMIF($C:$C,$M7,V:V) -> 3376575.6 | W7: =SUMIF($C:$C,$M7,W:W) -> 3264023.1 | X7: =SUMIF($C:$C,$M7,X:X) -> 0 | Y7: =SUMIF($C:$C,$M7,Y:Y) -> 0 | Z7: =SUMIF($C:$C,$M7,Z:Z) -> 0 | AA7: =SUMIF($C:$C,$M7,AA:AA) -> 0 | AB7: =SUMIF($C:$C,$M7,AB:AB) -> 0 | AC7: =SUMIF($C:$C,$M7,AC:AC) -> 0 | AD7: =SUMIF($C:$C,$M7,AD:AD) -> 0 | AE7: =SUMIF($C:$C,$M7,AE:AE) -> 0 | AF7: =SUMIF($C:$C,$M7,AF:AF) -> 0 | AG7: =SUMIF($C:$C,$M7,AG:AG) -> 0 | AH7: =SUMIF($C:$C,$M7,AH:AH) -> 0 | AI7: =SUMIF($C:$C,$M7,AI:AI) -> 0 | AJ7: =SUMIF($C:$C,$M7,AJ:AJ) -> 0 | AK7: =SUMIF($C:$C,$M7,AK:AK) -> 0 | AL7: =SUMIF($C:$C,$M7,AL:AL) -> 0 | AM7: =SUMIF($C:$C,$M7,AM:AM) -> 0 | AN7: =SUMIF($C:$C,$M7,AN:AN) -> 0 | AO7: =SUMIF($C:$C,$M7,AO:AO) -> 0 | AP7: =SUMIF($C:$C,$M7,AP:AP) -> 0 | AQ7: =SUMIF($C:$C,$M7,AQ:AQ) -> 0 | AR7: =SUMIF($C:$C,$M7,AR:AR) -> 0 | AS7: =SUMIF($C:$C,$M7,AS:AS) -> 0 | AT7: =SUMIF($C:$C,$M7,AT:AT) -> 0 | AU7: =SUMIF($C:$C,$M7,AU:AU) -> 0 | AV7: =SUMIF($C:$C,$M7,AV:AV) -> 0 | AW7: =SUMIF($C:$C,$M7,AW:AW) -> 0 | AX7: =SUMIF($C:$C,$M7,AX:AX) -> 0 | AY7: =SUMIF($C:$C,$M7,AY:AY) -> 0 | AZ7: =SUMIF($C:$C,$M7,AZ:AZ) -> 0 | BA7: =SUMIF($C:$C,$M7,BA:BA) -> 0 | BB7: =SUMIF($C:$C,$M7,BB:BB) -> 0 | BC7: =SUMIF($C:$C,$M7,BC:BC) -> 0 | BD7: =SUMIF($C:$C,$M7,BD:BD) -> 0 | BE7: =SUMIF($C:$C,$M7,BE:BE) -> 0 | BF7: =SUMIF($C:$C,$M7,BF:BF) -> 0 | BG7: =SUMIF($C:$C,$M7,BG:BG) -> 0 | BH7: =SUMIF($C:$C,$M7,BH:BH) -> 0 | BI7: =SUMIF($C:$C,$M7,BI:BI) -> 0 | BJ7: =SUMIF($C:$C,$M7,BJ:BJ) -> 0 | BK7: =SUMIF($C:$C,$M7,BK:BK) -> 0 | BL7: =SUMIF($C:$C,$M7,BL:BL) -> 0 | BM7: =SUMIF($C:$C,$M7,BM:BM) -> 0 | BN7: =SUMIF($C:$C,$M7,BN:BN) -> 0 | BO7: =SUMIF($C:$C,$M7,BO:BO) -> 0 | BP7: =SUMIF($C:$C,$M7,BP:BP) -> 0 | BQ7: =SUMIF($C:$C,$M7,BQ:BQ) -> 0 | BR7: =SUMIF($C:$C,$M7,BR:BR) -> 0 | BS7: =SUMIF($C:$C,$M7,BS:BS) -> 0 | BT7: =SUMIF($C:$C,$M7,BT:BT) -> 0 | BU7: =SUMIF($C:$C,$M7,BU:BU) -> 0 | BV7: =SUMIF($C:$C,$M7,BV:BV) -> 0 | BW7: =SUMIF($C:$C,$M7,BW:BW) -> 0 | BX7: =SUMIF($C:$C,$M7,BX:BX) -> 0 | BY7: =SUMIF($C:$C,$M7,BY:BY) -> 0 | BZ7: =SUMIF($C:$C,$M7,BZ:BZ) -> 0 | CA7: =SUMIF($C:$C,$M7,CA:CA) -> 0 | CB7: =SUMIF($C:$C,$M7,CB:CB) -> 0 | CC7: =SUMIF($C:$C,$M7,CC:CC) -> 0 | CD7: =SUMIF($C:$C,$M7,CD:CD) -> 0 | CE7: =SUMIF($C:$C,$M7,CE:CE) -> 0 | CF7: =SUMIF($C:$C,$M7,CF:CF) -> 0 | CG7: =SUMIF($C:$C,$M7,CG:CG) -> 0 | CH7: =SUMIF($C:$C,$M7,CH:CH) -> 0 | CI7: =SUMIF($C:$C,$M7,CI:CI) -> 0 | CJ7: =SUMIF($C:$C,$M7,CJ:CJ) -> 0 | CK7: =SUMIF($C:$C,$M7,CK:CK) -> 0 | CL7: =SUMIF($C:$C,$M7,CL:CL) -> 0 | CM7: =SUMIF($C:$C,$M7,CM:CM) -> 0 | CN7: =SUMIF($C:$C,$M7,CN:CN) -> 0 | CO7: =SUMIF($C:$C,$M7,CO:CO) -> 0 | CP7: =SUMIF($C:$C,$M7,CP:CP) -> 0 | CQ7: =SUMIF($C:$C,$M7,CQ:CQ) -> 0 | CR7: =SUMIF($C:$C,$M7,CR:CR) -> 0 | CS7: =SUMIF($C:$C,$M7,CS:CS) -> 0
M8: Total Depreciation Expenses for the Period | N8: =SUM(N3:N7) -> 2788779.4 | O8: =SUM(O3:O7) -> 2714292.4 | P8: =SUM(P3:P7) -> 2642288.2 | Q8: =SUM(Q3:Q7) -> 2572684.1 | R8: =SUM(R3:R7) -> 2505400.2 | S8: =SUM(S3:S7) -> 2440359.1 | T8: =SUM(T3:T7) -> 2377486 | U8: =SUM(U3:U7) -> 2316708.7 | ... CS8: =SUM(CS3:CS7) -> 554166.67
A11: Asset ID | B11: Asset Name | C11: Accounts | D11: COA | E11: Purchase Date | F11: Cost (MMK) | G11: Useful Life (Years) | H11: Yearly Depreciation Rate | I11: Monthly Depreciation Rate | J11: Used Years | K11: Used Months | L11: Prior Net Book Value | M11: Monthly Depreciation Expense | N11: =text("28/4/2025","MMM-YYYY") -> Apr-2025 | O11: =text(EOMONTH(N11,1),"MMM-YYYY") -> May-2025 | P11: =text(EOMONTH(O11,1),"MMM-YYYY") -> Jun-2025 | Q11: =text(EOMONTH(P11,1),"MMM-YYYY") -> Jul-2025 | R11: =text(EOMONTH(Q11,1),"MMM-YYYY") -> Aug-2025 | S11: =text(EOMONTH(R11,1),"MMM-YYYY") -> Sep-2025 | T11: =text(EOMONTH(S11,1),"MMM-YYYY") -> Oct-2025 | U11: =text(EOMONTH(T11,1),"MMM-YYYY") -> Nov-2025 | V11: =text(EOMONTH(U11,1),"MMM-YYYY") -> Dec-2025 | ... CS11: =text(EOMONTH(CR11,1),"MMM-YYYY") -> Mar-2032 | CT11: Total Accumulated Depreciation
A12: {=MR_Fixed_Asset_Register_List!A12:A50} -> FA-001 | B12: {=MR_Fixed_Asset_Register_List!B12:B50} -> ၁၀၇ ပေ x ၁၀၀ ပေ အုတ်ခြံစည်းရိုးနှစ်ဖက်ပါ မြေကွက် | C12: Land | D12: {=MR_Fixed_Asset_Register_List!D12:D50} -> 14000 | E12: {=MR_Fixed_Asset_Register_List!E12:E50} -> 44621 | F12: {=MR_Fixed_Asset_Register_List!G12:G56} -> 219000000 | G12: {=MR_Fixed_Asset_Register_List!H12:H54} | H12: {=MR_Fixed_Asset_Register_List!I12:I54} | I12: =H12/12 -> 0 | J12: =YEAR(MR_Fixed_Asset_Register_List!F12) - YEAR(E12) -> 3 | K12: =J12*12 -> 36 | L12: =MR_Fixed_Asset_Register_List!L12 -> 219000000 | M12: =I12*F12 -> 0 | N12: =IF(YEAR(TODAY())-YEAR($E12)+1>$G12,0,$M12) -> 0 | O12: =IF(YEAR(TODAY())-YEAR($E$12)+1>$G$12,0,$M$12) -> 0 | P12: =IF(YEAR(TODAY())-YEAR($E$12)+1>$G$12,0,$M$12) -> 0 | Q12: =IF(YEAR(TODAY())-YEAR($E$12)+1>$G$12,0,$M$12) -> 0 | R12: =IF(YEAR(TODAY())-YEAR($E$12)+1>$G$12,0,$M$12) -> 0 | S12: =IF(YEAR(TODAY())-YEAR($E$12)+1>$G$12,0,$M$12) -> 0 | T12: =IF(YEAR(TODAY())-YEAR(K12)+1>L12,0,S12) -> 0 | U12: =IF(YEAR(TODAY())-YEAR(L12)+1>M12,0,T12) -> 0 | V12: =IF(YEAR(TODAY())-YEAR(M12)+1>N12,0,U12) -> 0 | W12: =IF(YEAR(TODAY())-YEAR(N12)+1>O12,0,V12) -> 0 | X12: =IF(YEAR(TODAY())-YEAR(O12)+1>P12,0,W12) -> 0 | Y12: =IF(YEAR(TODAY())-YEAR(P12)+1>Q12,0,X12) -> 0 | Z12: =IF(YEAR(TODAY())-YEAR(Q12)+1>R12,0,Y12) -> 0 | AA12: =IF(YEAR(TODAY())-YEAR(R12)+1>S12,0,Z12) -> 0 | ... CS12: =IF(YEAR(TODAY())-YEAR(CJ12)+1>CK12,0,CR12) -> 0
A13: FA-002 | B13: စက်ရုံပင်မအဆောက်အဦး ၄၅ ပေ x ၆၀ ပေ | C13: Buildings & Structures | D13: 14100 | E13: 44621 | F13: 80000000 | G13: 20 | H13: 0.05 | I13: =H13/12 -> 0.0041666667 | J13: =YEAR(MR_Fixed_Asset_Register_List!F13) - YEAR(E13) -> 3 | K13: =J13*12 -> 36 | L13: =MR_Fixed_Asset_Register_List!L13 -> 67333333 | M13: =I13*F13 -> 333333.33 | N13: =IF(YEAR(TODAY())-YEAR($E13)+1>$G13,0,$M13) -> 333333.33 | O13: =IF(YEAR(TODAY())-YEAR($E13)+1>$G13,0,$M13) -> 333333.33 | P13: =IF(YEAR(TODAY())-YEAR($E13)+1>$G13,0,$M13) -> 333333.33 | Q13: =IF(YEAR(TODAY())-YEAR($E13)+1>$G13,0,$M13) -> 333333.33 | R13: =IF(YEAR(TODAY())-YEAR($E13)+1>$G13,0,$M13) -> 333333.33 | S13: =IF(YEAR(TODAY())-YEAR($E13)+1>$G13,0,$M13) -> 333333.33 | T13: =IF(YEAR(TODAY())-YEAR($E13)+1>$G13,0,$M13) -> 333333.33 | U13: =IF(YEAR(TODAY())-YEAR($E13)+1>$G13,0,$M13) -> 333333.33 | ... CS13: =IF(YEAR(TODAY())-YEAR($E13)+1>$G13,0,$M13) -> 333333.33
A14: FA-003 | B14: ဝန်ထမ်းအဆောက်အဦး ၃၀ ပေ x ၂၀ ပေ | C14: Buildings & Structures | D14: 14101 | E14: 44621 | F14: 30000000 | G14: 20 | H14: 0.05 | I14: =H14/12 -> 0.0041666667 | J14: =YEAR(MR_Fixed_Asset_Register_List!F14) - YEAR(E14) -> 3 | K14: =J14*12 -> 36 | L14: =MR_Fixed_Asset_Register_List!L14 -> 25250000 | M14: =I14*F14 -> 125000 | N14: =IF(YEAR(TODAY())-YEAR($E14)+1>$G14,0,$M14) -> 125000 | O14: =IF(YEAR(TODAY())-YEAR($E14)+1>$G14,0,$M14) -> 125000 | P14: =IF(YEAR(TODAY())-YEAR($E14)+1>$G14,0,$M14) -> 125000 | Q14: =IF(YEAR(TODAY())-YEAR($E14)+1>$G14,0,$M14) -> 125000 | R14: =IF(YEAR(TODAY())-YEAR($E14)+1>$G14,0,$M14) -> 125000 | S14: =IF(YEAR(TODAY())-YEAR($E14)+1>$G14,0,$M14) -> 125000 | T14: =IF(YEAR(TODAY())-YEAR($E14)+1>$G14,0,$M14) -> 125000 | U14: =IF(YEAR(TODAY())-YEAR($E14)+1>$G14,0,$M14) -> 125000 | ... CS14: =IF(YEAR(TODAY())-YEAR($E14)+1>$G14,0,$M14) -> 125000
A15: FA-004 | B15: ရေသန့်စက် ၂ထပ်အဆောက်အဦး နှင့် အုပ်ကန်ကြီး | C15: Buildings & Structures | D15: 14102 | E15: 44621 | F15: 15000000 | G15: 20 | H15: 0.05 | I15: =H15/12 -> 0.0041666667 | J15: =YEAR(MR_Fixed_Asset_Register_List!F15) - YEAR(E15) -> 3 | K15: =J15*12 -> 36 | L15: =MR_Fixed_Asset_Register_List!L15 -> 12625000 | M15: =I15*F15 -> 62500 | N15: =IF(YEAR(TODAY())-YEAR($E15)+1>$G15,0,$M15) -> 62500 | O15: =IF(YEAR(TODAY())-YEAR($E15)+1>$G15,0,$M15) -> 62500 | P15: =IF(YEAR(TODAY())-YEAR($E15)+1>$G15,0,$M15) -> 62500 | Q15: =IF(YEAR(TODAY())-YEAR($E15)+1>$G15,0,$M15) -> 62500 | R15: =IF(YEAR(TODAY())-YEAR($E15)+1>$G15,0,$M15) -> 62500 | S15: =IF(YEAR(TODAY())-YEAR($E15)+1>$G15,0,$M15) -> 62500 | T15: =IF(YEAR(TODAY())-YEAR($E15)+1>$G15,0,$M15) -> 62500 | U15: =IF(YEAR(TODAY())-YEAR($E15)+1>$G15,0,$M15) -> 62500 | ... CS15: =IF(YEAR(TODAY())-YEAR($E15)+1>$G15,0,$M15) -> 62500
A16: FA-005 | B16: အုတ်ခြံစည်းရိုးနှစ်ဖက် | C16: Buildings & Structures | D16: 14103 | E16: 44621 | F16: 8000000 | G16: 20 | H16: 0.05 | I16: =H16/12 -> 0.0041666667 | J16: =YEAR(MR_Fixed_Asset_Register_List!F16) - YEAR(E16) -> 3 | K16: =J16*12 -> 36 | L16: =MR_Fixed_Asset_Register_List!L16 -> 6733333.3 | M16: =I16*F16 -> 33333.333 | N16: =IF(YEAR(TODAY())-YEAR($E16)+1>$G16,0,$M16) -> 33333.333 | O16: =IF(YEAR(TODAY())-YEAR($E16)+1>$G16,0,$M16) -> 33333.333 | P16: =IF(YEAR(TODAY())-YEAR($E16)+1>$G16,0,$M16) -> 33333.333 | Q16: =IF(YEAR(TODAY())-YEAR($E16)+1>$G16,0,$M16) -> 33333.333 | R16: =IF(YEAR(TODAY())-YEAR($E16)+1>$G16,0,$M16) -> 33333.333 | S16: =IF(YEAR(TODAY())-YEAR($E16)+1>$G16,0,$M16) -> 33333.333 | T16: =IF(YEAR(TODAY())-YEAR($E16)+1>$G16,0,$M16) -> 33333.333 | U16: =IF(YEAR(TODAY())-YEAR($E16)+1>$G16,0,$M16) -> 33333.333 | ... CS16: =IF(YEAR(TODAY())-YEAR($E16)+1>$G16,0,$M16) -> 33333.333
A17: FA-006 | B17: ၁ တန်ကျ ရေသန့်စက် (၁)လုံး ပစ္စည်းအစုံ | C17: Machinery & Equipment | D17: 14200 | E17: 44621 | F17: 14800000 | G17: 5 | H17: 0.4 | I17: =H17/12 -> 0.033333333 | J17: =YEAR(MR_Fixed_Asset_Register_List!F17) - YEAR(E17) -> 3 | K17: =J17*12 -> 36 | L17: =MR_Fixed_Asset_Register_List!L17 -> 11894267 | N17: =L17*$I17 -> 396475.56 | O17: =MR_Fixed_Asset_Register_List!O17*$I17 -> 383259.7 | P17: =MR_Fixed_Asset_Register_List!P17*$I17 -> 370484.38 | Q17: =MR_Fixed_Asset_Register_List!Q17*$I17 -> 358134.9 | R17: =MR_Fixed_Asset_Register_List!R17*$I17 -> 346197.07 | S17: =MR_Fixed_Asset_Register_List!S17*$I17 -> 334657.17 | T17: =MR_Fixed_Asset_Register_List!T17*$I17 -> 323501.93 | U17: =MR_Fixed_Asset_Register_List!U17*$I17 -> 312718.53 | V17: =MR_Fixed_Asset_Register_List!V17*$I17 -> 302294.58 | ... CS17: =MR_Fixed_Asset_Register_List!CS17*$I17 -> 0
A18: FA-007 | B18: မီတာ (၂) လုံး - Soft Drink Factory | C18: Electrical & Utility Systems | D18: 14201 | E18: 44621 | F18: 2000000 | G18: 5 | H18: 0.4 | I18: =H18/12 -> 0.033333333 | J18: =YEAR(MR_Fixed_Asset_Register_List!F18) - YEAR(E18) -> 3 | K18: =J18*12 -> 36 | L18: =MR_Fixed_Asset_Register_List!L18 -> 1366666.7 | N18: =L18*$I18 -> 45555.556 | O18: =MR_Fixed_Asset_Register_List!O18*$I18 -> 44037.037 | P18: =MR_Fixed_Asset_Register_List!P18*$I18 -> 42569.136 | Q18: =MR_Fixed_Asset_Register_List!Q18*$I18 -> 41150.165 | R18: =MR_Fixed_Asset_Register_List!R18*$I18 -> 39778.492 | S18: =MR_Fixed_Asset_Register_List!S18*$I18 -> 38452.543 | T18: =MR_Fixed_Asset_Register_List!T18*$I18 -> 37170.791 | U18: =MR_Fixed_Asset_Register_List!U18*$I18 -> 35931.765 | V18: =MR_Fixed_Asset_Register_List!V18*$I18 -> 34734.039 | ... CS18: =MR_Fixed_Asset_Register_List!CS18*$I18 -> 0
A19: FA-008 | B19: မီးအားမြှင့်စက် (15 KV) - ၂ လုံး | C19: Electrical & Utility Systems | D19: 14202 | E19: 44621 | F19: 4000000 | G19: 5 | H19: 0.4 | I19: =H19/12 -> 0.033333333 | J19: =YEAR(MR_Fixed_Asset_Register_List!F19) - YEAR(E19) -> 3 | K19: =J19*12 -> 36 | L19: =MR_Fixed_Asset_Register_List!L19 -> 3208333.3 | N19: =L19*$I19 -> 106944.44 | O19: =MR_Fixed_Asset_Register_List!O19*$I19 -> 103379.63 | P19: =MR_Fixed_Asset_Register_List!P19*$I19 -> 99933.642 | Q19: =MR_Fixed_Asset_Register_List!Q19*$I19 -> 96602.521 | R19: =MR_Fixed_Asset_Register_List!R19*$I19 -> 93382.437 | S19: =MR_Fixed_Asset_Register_List!S19*$I19 -> 90269.689 | T19: =MR_Fixed_Asset_Register_List!T19*$I19 -> 87260.699 | U19: =MR_Fixed_Asset_Register_List!U19*$I19 -> 84352.009 | V19: =MR_Fixed_Asset_Register_List!V19*$I19 -> 81540.275 | ... CS19: =MR_Fixed_Asset_Register_List!CS19*$I19 -> 0
A20: FA-009 | B20: အချိုရည် (၂)လုံးကျ စက်ပစ္စည်းစုံ - ၂ စက် | C20: Machinery & Equipment | D20: 14203 | E20: 44621 | F20: 50000000 | G20: 5 | H20: 0.4 | I20: =H20/12 -> 0.033333333 | J20: =YEAR(MR_Fixed_Asset_Register_List!F20) - YEAR(E20) -> 3 | K20: =J20*12 -> 36 | L20: =MR_Fixed_Asset_Register_List!L20 -> 40183333 | N20: =L20*$I20 -> 1339444.4 | O20: =MR_Fixed_Asset_Register_List!O20*$I20 -> 1294796.3 | P20: =MR_Fixed_Asset_Register_List!P20*$I20 -> 1251636.4 | Q20: =MR_Fixed_Asset_Register_List!Q20*$I20 -> 1209915.2 | R20: =MR_Fixed_Asset_Register_List!R20*$I20 -> 1169584.7 | S20: =MR_Fixed_Asset_Register_List!S20*$I20 -> 1130598.5 | T20: =MR_Fixed_Asset_Register_List!T20*$I20 -> 1092911.9 | U20: =MR_Fixed_Asset_Register_List!U20*$I20 -> 1056481.5 | V20: =MR_Fixed_Asset_Register_List!V20*$I20 -> 1021265.5 | ... CS20: =MR_Fixed_Asset_Register_List!CS20*$I20 -> 0
A21: FA-010 | B21: အဲယားကွန်း | C21: Electrical & Utility Systems | D21: 14204 | E21: 44621 | F21: 1200000 | G21: 5 | H21: 0.4 | I21: =H21/12 -> 0.033333333 | J21: =YEAR(MR_Fixed_Asset_Register_List!F21) - YEAR(E21) -> 3 | K21: =J21*12 -> 36 | L21: =MR_Fixed_Asset_Register_List!L21 -> 820000 | N21: =L21*$I21 -> 27333.333 | O21: =MR_Fixed_Asset_Register_List!O21*$I21 -> 26422.222 | P21: =MR_Fixed_Asset_Register_List!P21*$I21 -> 25541.481 | Q21: =MR_Fixed_Asset_Register_List!Q21*$I21 -> 24690.099 | R21: =MR_Fixed_Asset_Register_List!R21*$I21 -> 23867.095 | S21: =MR_Fixed_Asset_Register_List!S21*$I21 -> 23071.526 | T21: =MR_Fixed_Asset_Register_List!T21*$I21 -> 22302.475 | U21: =MR_Fixed_Asset_Register_List!U21*$I21 -> 21559.059 | V21: =MR_Fixed_Asset_Register_List!V21*$I21 -> 20840.424 | ... CS21: =MR_Fixed_Asset_Register_List!CS21*$I21 -> 0
A22: FA-011 | B22: ရေမော်တာ ၃ လုံး | C22: Machinery & Equipment | D22: 14205 | E22: 44621 | F22: 600000 | G22: 5 | H22: 0.4 | I22: =H22/12 -> 0.033333333 | J22: =YEAR(MR_Fixed_Asset_Register_List!F22) - YEAR(E22) -> 3 | K22: =J22*12 -> 36 | L22: =MR_Fixed_Asset_Register_List!L22 -> 481250 | N22: =L22*$I22 -> 16041.667 | O22: =MR_Fixed_Asset_Register_List!O22*$I22 -> 15506.944 | P22: =MR_Fixed_Asset_Register_List!P22*$I22 -> 14990.046 | Q22: =MR_Fixed_Asset_Register_List!Q22*$I22 -> 14490.378 | R22: =MR_Fixed_Asset_Register_List!R22*$I22 -> 14007.365 | S22: =MR_Fixed_Asset_Register_List!S22*$I22 -> 13540.453 | T22: =MR_Fixed_Asset_Register_List!T22*$I22 -> 13089.105 | U22: =MR_Fixed_Asset_Register_List!U22*$I22 -> 12652.801 | V22: =MR_Fixed_Asset_Register_List!V22*$I22 -> 12231.041 | ... CS22: =MR_Fixed_Asset_Register_List!CS22*$I22 -> 0
A23: FA-012 | B23: ရေနွေးကျို စတီးလ်အိုးကြီး | C23: Machinery & Equipment | D23: 14206 | E23: 44621 | F23: 200000 | G23: 5 | H23: 0.4 | I23: =H23/12 -> 0.033333333 | J23: =YEAR(MR_Fixed_Asset_Register_List!F23) - YEAR(E23) -> 3 | K23: =J23*12 -> 36 | L23: =MR_Fixed_Asset_Register_List!L23 -> 136666.67 | N23: =L23*$I23 -> 4555.5556 | O23: =MR_Fixed_Asset_Register_List!O23*$I23 -> 4403.7037 | P23: =MR_Fixed_Asset_Register_List!P23*$I23 -> 4256.9136 | Q23: =MR_Fixed_Asset_Register_List!Q23*$I23 -> 4115.0165 | R23: =MR_Fixed_Asset_Register_List!R23*$I23 -> 3977.8492 | S23: =MR_Fixed_Asset_Register_List!S23*$I23 -> 3845.2543 | T23: =MR_Fixed_Asset_Register_List!T23*$I23 -> 3717.0791 | U23: =MR_Fixed_Asset_Register_List!U23*$I23 -> 3593.1765 | V23: =MR_Fixed_Asset_Register_List!V23*$I23 -> 3473.4039 | ... CS23: =MR_Fixed_Asset_Register_List!CS23*$I23 -> 0
A24: FA-013 | B24: ၂ ကောင်အား ရေမော်တာ နှင့် Compressor | C24: Machinery & Equipment | D24: 14207 | E24: 44621 | F24: 800000 | G24: 5 | H24: 0.4 | I24: =H24/12 -> 0.033333333 | J24: =YEAR(MR_Fixed_Asset_Register_List!F24) - YEAR(E24) -> 3 | K24: =J24*12 -> 36 | L24: =MR_Fixed_Asset_Register_List!L24 -> 641666.67 | N24: =L24*$I24 -> 21388.889 | O24: =MR_Fixed_Asset_Register_List!O24*$I24 -> 20675.926 | P24: =MR_Fixed_Asset_Register_List!P24*$I24 -> 19986.728 | Q24: =MR_Fixed_Asset_Register_List!Q24*$I24 -> 19320.504 | R24: =MR_Fixed_Asset_Register_List!R24*$I24 -> 18676.487 | S24: =MR_Fixed_Asset_Register_List!S24*$I24 -> 18053.938 | T24: =MR_Fixed_Asset_Register_List!T24*$I24 -> 17452.14 | U24: =MR_Fixed_Asset_Register_List!U24*$I24 -> 16870.402 | V24: =MR_Fixed_Asset_Register_List!V24*$I24 -> 16308.055 | ... CS24: =MR_Fixed_Asset_Register_List!CS24*$I24 -> 0
A25: FA-014 | B25: Yankin Land | C25: Land | D25: 14208 | E25: 45695 | F25: 210290000 | L25: =MR_Fixed_Asset_Register_List!L25 -> 210290000 | N25: =L25*$I25 -> 0 | O25: =MR_Fixed_Asset_Register_List!O25*$I25 -> 0 | P25: =MR_Fixed_Asset_Register_List!P25*$I25 -> 0 | Q25: =MR_Fixed_Asset_Register_List!Q25*$I25 -> 0 | R25: =MR_Fixed_Asset_Register_List!R25*$I25 -> 0 | S25: =MR_Fixed_Asset_Register_List!S25*$I25 -> 0 | T25: =MR_Fixed_Asset_Register_List!T25*$I25 -> 0 | U25: =MR_Fixed_Asset_Register_List!U25*$I25 -> 0 | V25: =MR_Fixed_Asset_Register_List!V25*$I25 -> 0 | ... CS25: =MR_Fixed_Asset_Register_List!CS25*$I25 -> 0
A26: FA-015 | B26: မီတာ (၂) လုံး - Yankin Drinking Water Facility | C26: Electrical & Utility Systems | D26: 14209 | E26: 45703 | F26: 6856000 | G26: 5 | H26: 0.4 | I26: =H26/12 -> 0.033333333 | J26: =YEAR(MR_Fixed_Asset_Register_List!F26) - YEAR(E26) -> 0 | K26: =J26*12 -> 0 | L26: =MR_Fixed_Asset_Register_List!L26 -> 6798866.7 | N26: =L26*$I26 -> 226628.89 | O26: =MR_Fixed_Asset_Register_List!O26*$I26 -> 219074.59 | P26: =MR_Fixed_Asset_Register_List!P26*$I26 -> 211772.11 | Q26: =MR_Fixed_Asset_Register_List!Q26*$I26 -> 204713.04 | R26: =MR_Fixed_Asset_Register_List!R26*$I26 -> 197889.27 | S26: =MR_Fixed_Asset_Register_List!S26*$I26 -> 191292.96 | T26: =MR_Fixed_Asset_Register_List!T26*$I26 -> 184916.53 | U26: =MR_Fixed_Asset_Register_List!U26*$I26 -> 178752.64 | V26: =MR_Fixed_Asset_Register_List!V26*$I26 -> 172794.22 | ... CS26: =MR_Fixed_Asset_Register_List!CS26*$I26 -> 0
A27: FA-016 | B27: 1000 လီတာ စတီးအိုး လဲး | C27: Machinery & Equipment | D27: 14210 | E27: 45724 | F27: 1520000 | G27: 5 | H27: 0.4 | I27: =H27/12 -> 0.033333333 | J27: =YEAR(MR_Fixed_Asset_Register_List!F27) - YEAR(E27) -> 0 | K27: =J27*12 -> 0 | L27: =MR_Fixed_Asset_Register_List!L27 -> 1507333.3 | N27: =L27*$I27 -> 50244.444 | O27: =MR_Fixed_Asset_Register_List!O27*$I27 -> 48569.63 | P27: =MR_Fixed_Asset_Register_List!P27*$I27 -> 46950.642 | Q27: =MR_Fixed_Asset_Register_List!Q27*$I27 -> 45385.621 | R27: =MR_Fixed_Asset_Register_List!R27*$I27 -> 43872.767 | S27: =MR_Fixed_Asset_Register_List!S27*$I27 -> 42410.341 | T27: =MR_Fixed_Asset_Register_List!T27*$I27 -> 40996.663 | U27: =MR_Fixed_Asset_Register_List!U27*$I27 -> 39630.108 | V27: =MR_Fixed_Asset_Register_List!V27*$I27 -> 38309.104 | ... CS27: =MR_Fixed_Asset_Register_List!CS27*$I27 -> 0
A28: FA-017 | B28: 200 KVA Transformer | C28: Electrical & Utility Systems | D28: 14211 | E28: 45866 | F28: 92000000 | G28: 5 | H28: 0.4 | I28: =H28/12 -> 0.033333333 | J28: =YEAR(MR_Fixed_Asset_Register_List!F28) - YEAR(E28) -> 0 | K28: =J28*12 -> 0 | L28: =MR_Fixed_Asset_Register_List!L28 -> 0 | N28: =L28*$I28 -> 0 | O28: =MR_Fixed_Asset_Register_List!O28*$I28 -> 0 | P28: =MR_Fixed_Asset_Register_List!P28*$I28 -> 0 | Q28: =MR_Fixed_Asset_Register_List!Q28*$I28 -> 0 | V28: =MR_Fixed_Asset_Register_List!V28*$I28 -> 3066666.7 | W28: =MR_Fixed_Asset_Register_List!W28*$I28 -> 2964444.4 | X28: =MR_Fixed_Asset_Register_List!X28*$I28 -> 0 | Y28: =MR_Fixed_Asset_Register_List!Y28*$I28 -> 0 | Z28: =MR_Fixed_Asset_Register_List!Z28*$I28 -> 0 | AA28: =MR_Fixed_Asset_Register_List!AA28*$I28 -> 0 | AB28: =MR_Fixed_Asset_Register_List!AB28*$I28 -> 0 | AC28: =MR_Fixed_Asset_Register_List!AC28*$I28 -> 0 | ... CS28: =MR_Fixed_Asset_Register_List!CS28*$I28 -> 0
A29: FA-018 | B29: R.O Water Treatment System-5 Tons/HR | C29: Machinery & Equipment | D29: 14212 | E29: 45868 | F29: 68000000 | G29: 5 | H29: 0.4 | I29: =H29/12 -> 0.033333333 | J29: =YEAR(MR_Fixed_Asset_Register_List!F29) - YEAR(E29) -> 0 | K29: =J29*12 -> 0 | L29: =MR_Fixed_Asset_Register_List!L29 -> 0 | N29: =L29*$I29 -> 0 | O29: =MR_Fixed_Asset_Register_List!O29*$I29 -> 0 | P29: =MR_Fixed_Asset_Register_List!P29*$I29 -> 0 | Q29: =MR_Fixed_Asset_Register_List!Q29*$I29 -> 0 | V29: =MR_Fixed_Asset_Register_List!V29*$I29 -> 2266666.7 | W29: =MR_Fixed_Asset_Register_List!W29*$I29 -> 2191111.1 | X29: =MR_Fixed_Asset_Register_List!X29*$I29 -> 0 | Y29: =MR_Fixed_Asset_Register_List!Y29*$I29 -> 0 | Z29: =MR_Fixed_Asset_Register_List!Z29*$I29 -> 0 | AA29: =MR_Fixed_Asset_Register_List!AA29*$I29 -> 0 | AB29: =MR_Fixed_Asset_Register_List!AB29*$I29 -> 0 | AC29: =MR_Fixed_Asset_Register_List!AC29*$I29 -> 0 | ... CS29: =MR_Fixed_Asset_Register_List!CS29*$I29 -> 0
A30: FA-019 | B30: 120' x 50' Main Factory Building and 15' x 50' Two-storey building | C30: Buildings & Structures | D30: 14213 | E30: 45900 | F30: 316445000 | G30: 20 | H30: 0.05 | I30: =H30/12 -> 0.0041666667 | J30: =YEAR(MR_Fixed_Asset_Register_List!F30) - YEAR(E30) -> 0 | K30: =J30*12 -> 0 | L30: =MR_Fixed_Asset_Register_List!L30 -> 0 | M30: =I30*F30 -> 1318520.8 | N30: =L30*$I30 -> 0 | O30: =MR_Fixed_Asset_Register_List!O30*$I30 -> 0 | P30: =MR_Fixed_Asset_Register_List!P30*$I30 -> 0 | Q30: =MR_Fixed_Asset_Register_List!Q30*$I30 -> 0 | R30: =MR_Fixed_Asset_Register_List!R30*$I30 -> 0 | V30: =IF(YEAR(TODAY())-YEAR($E30)+1>$G30,0,$M30) -> 1318520.8 | W30: =MR_Fixed_Asset_Register_List!W30*$I30 -> 1313027 | X30: =MR_Fixed_Asset_Register_List!X30*$I30 -> 0 | Y30: =MR_Fixed_Asset_Register_List!Y30*$I30 -> 0 | Z30: =MR_Fixed_Asset_Register_List!Z30*$I30 -> 0 | AA30: =MR_Fixed_Asset_Register_List!AA30*$I30 -> 0 | AB30: =MR_Fixed_Asset_Register_List!AB30*$I30 -> 0 | AC30: =MR_Fixed_Asset_Register_List!AC30*$I30 -> 0 | AD30: =MR_Fixed_Asset_Register_List!AD30*$I30 -> 0 | ... CS30: =MR_Fixed_Asset_Register_List!CS30*$I30 -> 0
A31: FA-020 | B31: Pressure pumps with accessories | C31: Machinery & Equipment | D31: 14214 | E31: 45908 | F31: 2182300 | G31: 5 | H31: 0.4 | I31: =H31/12 -> 0.033333333 | J31: =YEAR(MR_Fixed_Asset_Register_List!F31) - YEAR(E31) -> 0 | K31: =J31*12 -> 0 | L31: =MR_Fixed_Asset_Register_List!L31 -> 0 | M31: =I31*F31 -> 72743.333 | V31: =MR_Fixed_Asset_Register_List!V31*$I31 -> 72743.333 | W31: =MR_Fixed_Asset_Register_List!W31*$I31 -> 70318.556
A32: FA-021

Sheet IRD_Fixed_Asset_Register_List
M2: Accounts | N2: Opening Balance | O2: Prior Net Book Value ($) | P2: =P13 -> Net Book Value for Feb-25 | Q2: =Q13 -> Net Book Value for Mar-25 | R2: =R13 -> Net Book Value for April-25 | S2: =S13 -> Net Book Value for May-25 | T2: =T12 | U2: =U12 | V2: =V12 | W2: =W12 | X2: =X12 | Y2: =Y12 | Z2: =Z12 | AA2: =AA12 | ... CU2: =CU12
M3: Land | N3: =SUMIF($C$14:$C$26,$M3,G$14:G$26) -> 219000000 | O3: =SUMIF($C$14:$C$26,$M3,L$14:L$26) -> 219000000 | P3: =SUMIF($C$14:$C$29,$M3,P$14:P$29) -> 429290000 | Q3: =SUMIF($C$14:$C$29,$M3,Q$14:Q$29) -> 429290000 | R3: =SUMIF($C$14:$C$29,$M3,R$14:R$29) -> 429290000 | S3: =SUMIF($C$14:$C$29,$M3,S$14:S$29) -> 429290000 | T3: =SUMIF($C$13:$C$27,#REF!,T$13:T$27) -> 0 | U3: =SUMIF($C$13:$C$27,#REF!,U$13:U$27) -> 0 | V3: =SUMIF($C$13:$C$27,#REF!,V$13:V$27) -> 0 | W3: =SUMIF($C$13:$C$27,#REF!,W$13:W$27) -> 0 | X3: =SUMIF($C$13:$C$27,#REF!,X$13:X$27) -> 0 | Y3: =SUMIF($C$13:$C$27,#REF!,Y$13:Y$27) -> 0 | Z3: =SUMIF($C$13:$C$27,#REF!,Z$13:Z$27) -> 0 | AA3: =SUMIF($C$13:$C$27,#REF!,AA$13:AA$27) -> 0 | ... CU3: =SUMIF($C$13:$C$27,#REF!,CU$13:CU$27) -> 0
M4: Buildings & Structures | N4: =SUMIF($C$14:$C$26,$M4,G$14:G$26) -> 133000000 | O4: =SUMIF($C$14:$C$26,$M4,L$14:L$26) -> 113050000 | P4: =SUMIF($C$14:$C$29,$M4,P$14:P$29) -> 1.1249583e+08 | Q4: =SUMIF($C$14:$C$29,$M4,Q$14:Q$29) -> 1.1194167e+08 | R4: =SUMIF($C$14:$C$29,$M4,R$14:R$29) -> 111387500 | S4: =SUMIF($C$14:$C$29,$M4,S$14:S$29) -> 1.1083333e+08 | T4: =SUMIF($C$13:$C$27,#REF!,T$13:T$27) -> 0 | U4: =SUMIF($C$13:$C$27,#REF!,U$13:U$27) -> 0 | V4: =SUMIF($C$13:$C$27,#REF!,V$13:V$27) -> 0 | W4: =SUMIF($C$13:$C$27,#REF!,W$13:W$27) -> 0 | X4: =SUMIF($C$13:$C$27,#REF!,X$13:X$27) -> 0 | Y4: =SUMIF($C$13:$C$27,#REF!,Y$13:Y$27) -> 0 | Z4: =SUMIF($C$13:$C$27,#REF!,Z$13:Z$27) -> 0 | AA4: =SUMIF($C$13:$C$27,#REF!,AA$13:AA$27) -> 0 | ... CU4: =SUMIF($C$13:$C$27,#REF!,CU$13:CU$27) -> 0
M5: Machinery & Equipment | N5: =SUMIF($C$14:$C$26,$M5,G$14:G$26) -> 66400000 | O5: =SUMIF($C$14:$C$26,$M5,L$14:L$26) -> 54024700 | P5: =SUMIF($C$14:$C$29,$M5,P$14:P$29) -> 53680942 | Q5: =SUMIF($C$14:$C$29,$M5,Q$14:Q$29) -> 54844517 | R5: =SUMIF($C$14:$C$29,$M5,R$14:R$29) -> 54488092 | S5: =SUMIF($C$14:$C$29,$M5,S$14:S$29) -> 54131667 | T5: =SUMIF($C$13:$C$27,#REF!,T$13:T$27) -> 0 | U5: =SUMIF($C$13:$C$27,#REF!,U$13:U$27) -> 0 | V5: =SUMIF($C$13:$C$27,#REF!,V$13:V$27) -> 0 | W5: =SUMIF($C$13:$C$27,#REF!,W$13:W$27) -> 0 | X5: =SUMIF($C$13:$C$27,#REF!,X$13:X$27) -> 0 | Y5: =SUMIF($C$13:$C$27,#REF!,Y$13:Y$27) -> 0 | Z5: =SUMIF($C$13:$C$27,#REF!,Z$13:Z$27) -> 0 | AA5: =SUMIF($C$13:$C$27,#REF!,AA$13:AA$27) -> 0 | ... CU5: =SUMIF($C$13:$C$27,#REF!,CU$13:CU$27) -> 0
