Workbook

Sheet Dashboard
A2: Live Dashboard | B2: =TEXT(D7,"MMMM-YY") -> #REF! | F2: Total Stock Value Before Production | J2: Total Closing Stock Value | K2: Total Cost of Production
F3: =SUM(Dashboard!$F$7:$F$24) -> #REF! | J3: =SUM(Dashboard!$J$7:$J$24) -> #REF! | K3: =SUM(Dashboard!$K$7:$K$24) -> #REF!
A6: Inventory Code | B6: Raw Material Name | C6: Unit Measure | D6: Latest Stock Date | E6: Total Stock Before Production | F6: Total Stock Value Before Production (MMK) | G6: Ground Stock | H6: Weighted Average Cost Per Unit (MMK) | I6: Stock Units Used in Production | J6: Closing Stock Value (MMK) | K6: Cost of Production | L6: Status
A7: =OBR_Feb_2025!A2 -> #REF! | B7: =OBR_Feb_2025!B2 -> #REF! | C7: pack | D7: {=IFNA((MAX(INDIRECT(A7&"!"&"A:A"))),OBR_Aug_2025!G4)} -> #REF! | E7: {=IF(D7=OBR_Aug_2025!G4,OBR_Aug_2025!D4, SUMIF(INDIRECT(A7&"!"&"A:A"),D7,INDIRECT(A7&"!"&"G:G")))} -> #REF! | F7: =E7*H7 -> #REF! | G7: ='12001'!J11 -> 114 | H7: {=IF(D7=OBR_May_2025!G2,OBR_May_2025!E2, SUMIF(INDIRECT(A7&"!"&"A:A"),D7,INDIRECT(A7&"!"&"H:H")))} -> #REF! | I7: =E7-G7 -> #REF! | J7: =G7*H7 -> #REF! | K7: =F7-J7 -> #REF! | L7: In stock | N7: =MONTH(D7)=10 -> #REF!
A8: =OBR_Feb_2025!A3 | B8: =OBR_Feb_2025!B3 | C8: Bag | D8: {=IFNA((MAX(INDIRECT(A8&"!"&"A:A"))),OBR_May_2025!G5)} -> #REF! | E8: {=IF(D8=OBR_Aug_2025!G5,OBR_Aug_2025!D5, SUMIF(INDIRECT(A8&"!"&"A:A"),D8,INDIRECT(A8&"!"&"G:G")))} -> #REF! | F8: =E8*H8 -> #REF! | G8: ='12002'!J11 -> 7.32 | H8: {=IF(D8=OBR_May_2025!G3,OBR_May_2025!E3, SUMIF(INDIRECT(A8&"!"&"A:A"),D8,INDIRECT(A8&"!"&"H:H")))} -> #REF! | I8: =E8-G8 -> #REF! | J8: =G8*H8 -> #REF! | K8: =F8-J8 -> #REF! | L8: In stock | N8: =MONTH(D8)=10 -> #REF!
A9: =OBR_Feb_2025!A4 | B9: =OBR_Feb_2025!B4 | C9: Bag | D9: {=IFNA((MAX(INDIRECT(A9&"!"&"A:A"))),OBR_May_2025!G6)} -> #REF! | E9: {=IF(D9=OBR_Aug_2025!G6,OBR_Aug_2025!D6, SUMIF(INDIRECT(A9&"!"&"A:A"),D9,INDIRECT(A9&"!"&"G:G")))} -> #REF! | F9: =E9*H9 -> #REF! | G9: ='12003'!J12 -> 1.7 | H9: {=IF(D9=OBR_May_2025!G4,OBR_May_2025!E4, SUMIF(INDIRECT(A9&"!"&"A:A"),D9,INDIRECT(A9&"!"&"H:H")))} -> #REF! | I9: =E9-G9 -> #REF! | J9: =G9*H9 -> #REF! | K9: =F9-J9 -> #REF! | L9: In stock | N9: =MONTH(D9)=10 -> #REF!
A10: =OBR_Feb_2025!A5 | B10: =OBR_Feb_2025!B5 | C10: Bag | D10: {=IFNA((MAX(INDIRECT(A10&"!"&"A:A"))),OBR_May_2025!G7)} -> #REF! | E10: {=IF(D10=OBR_Aug_2025!G7,OBR_Aug_2025!D7, SUMIF(INDIRECT(A10&"!"&"A:A"),D10,INDIRECT(A10&"!"&"G:G")))} -> #REF! | F10: =E10*H10 -> #REF! | G10: ='12004'!J13 -> 3.52 | H10: {=IF(D10=OBR_May_2025!G5,OBR_May_2025!E5, SUMIF(INDIRECT(A10&"!"&"A:A"),D10,INDIRECT(A10&"!"&"H:H")))} -> #REF! | I10: =E10-G10 -> #REF! | J10: =G10*H10 -> #REF! | K10: =F10-J10 -> #REF! | L10: In stock | N10: =MONTH(D10)=10 -> #REF!
A11: =OBR_Feb_2025!A6 | B11: =OBR_Feb_2025!B6 | C11: gram | D11: {=IFNA((MAX(INDIRECT(A11&"!"&"A:A"))),OBR_May_2025!G8)} -> #REF! | E11: {=IF(D11=OBR_Aug_2025!G8,OBR_Aug_2025!D8, SUMIF(INDIRECT(A11&"!"&"A:A"),D11,INDIRECT(A11&"!"&"G:G")))} -> #REF! | F11: =E11*H11 -> #REF! | G11: ='12005'!J10 -> 17068 | H11: {=IF(D11=OBR_May_2025!G6,OBR_May_2025!E6, SUMIF(INDIRECT(A11&"!"&"A:A"),D11,INDIRECT(A11&"!"&"H:H")))} -> #REF! | I11: =E11-G11 -> #REF! | J11: =G11*H11 -> #REF! | K11: =F11-J11 -> #REF! | L11: In stock | N11: =MONTH(D11)=10 -> #REF!
A12: =OBR_Feb_2025!A7 | B12: =OBR_Feb_2025!B7 | C12: gram | D12: {=IFNA((MAX(INDIRECT(A12&"!"&"A:A"))),OBR_May_2025!G9)} -> #REF! | E12: {=IF(D12=OBR_Aug_2025!G9,OBR_Aug_2025!D9, SUMIF(INDIRECT(A12&"!"&"A:A"),D12,INDIRECT(A12&"!"&"G:G")))} -> #REF! | F12: =E12*H12 -> #REF! | G12: ='12006'!J12 -> 1824 | H12: {=IF(D12=OBR_May_2025!G7,OBR_May_2025!E7, SUMIF(INDIRECT(A12&"!"&"A:A"),D12,INDIRECT(A12&"!"&"H:H")))} -> #REF! | I12: =E12-G12 -> #REF! | J12: =G12*H12 -> #REF! | K12: =F12-J12 -> #REF! | L12: In stock | N12: =MONTH(D12)=10 -> #REF!
A13: =OBR_Feb_2025!A8 | B13: =OBR_Feb_2025!B8 | C13: gram | D13: {=IFNA((MAX(INDIRECT(A13&"!"&"A:A"))),OBR_May_2025!G10)} -> #REF! | E13: {=IF(D13=OBR_Aug_2025!G10,OBR_Aug_2025!D10, SUMIF(INDIRECT(A13&"!"&"A:A"),D13,INDIRECT(A13&"!"&"G:G")))} -> #REF! | F13: =E13*H13 -> #REF! | G13: ='12007'!J10 -> 5158 | H13: {=IF(D13=OBR_May_2025!G8,OBR_May_2025!E8, SUMIF(INDIRECT(A13&"!"&"A:A"),D13,INDIRECT(A13&"!"&"H:H")))} -> #REF! | I13: =E13-G13 -> #REF! | J13: =G13*H13 -> #REF! | K13: =F13-J13 -> #REF! | L13: In stock | N13: =MONTH(D13)=10 -> #REF! | O13: =B13
A14: =OBR_Feb_2025!A9 | B14: =OBR_Feb_2025!B9 | C14: Bottles | D14: {=IFNA((MAX(INDIRECT(A14&"!"&"A:A"))),OBR_May_2025!G11)} -> #REF! | E14: {=IF(D14=OBR_Aug_2025!G11,OBR_Aug_2025!D11, SUMIF(INDIRECT(A14&"!"&"A:A"),D14,INDIRECT(A14&"!"&"G:G")))} -> #REF! | F14: =E14*H14 -> #REF! | G14: ='12008'!J10 -> 1.9 | H14: {=IF(D14=OBR_May_2025!G9,OBR_May_2025!E9, SUMIF(INDIRECT(A14&"!"&"A:A"),D14,INDIRECT(A14&"!"&"H:H")))} -> #REF! | I14: =E14-G14 -> #REF! | J14: =G14*H14 -> #REF! | K14: =F14-J14 -> #REF! | L14: In stock | N14: =MONTH(D14)=10 -> #REF!
A15: =OBR_Feb_2025!A10 | B15: =OBR_Feb_2025!B10 | C15: gram | D15: {=IFNA((MAX(INDIRECT(A15&"!"&"A:A"))),OBR_May_2025!G12)} -> #REF! | E15: {=IF(D15=OBR_Aug_2025!G12,OBR_Aug_2025!D12, SUMIF(INDIRECT(A15&"!"&"A:A"),D15,INDIRECT(A15&"!"&"G:G")))} -> #REF! | F15: =E15*H15 -> #REF! | G15: ='12009'!J10 -> 4654 | H15: {=IF(D15=OBR_May_2025!G10,OBR_May_2025!E10, SUMIF(INDIRECT(A15&"!"&"A:A"),D15,INDIRECT(A15&"!"&"H:H")))} -> #REF! | I15: =E15-G15 -> #REF! | J15: =G15*H15 -> #REF! | K15: =F15-J15 -> #REF! | L15: In stock | N15: =MONTH(D15)=10 -> #REF! | O15: =B15
A16: =OBR_Feb_2025!A11 | B16: =OBR_Feb_2025!B11 | C16: gram | D16: {=IFNA((MAX(INDIRECT(A16&"!"&"A:A"))),OBR_May_2025!G13)} -> #REF! | E16: {=IF(D16=OBR_Aug_2025!G13,OBR_Aug_2025!D13, SUMIF(INDIRECT(A16&"!"&"A:A"),D16,INDIRECT(A16&"!"&"G:G")))} -> #REF! | F16: =E16*H16 -> #REF! | G16: ='12010'!J10 -> 450 | H16: {=IF(D16=OBR_May_2025!G11,OBR_May_2025!E11, SUMIF(INDIRECT(A16&"!"&"A:A"),D16,INDIRECT(A16&"!"&"H:H")))} -> #REF! | I16: =E16-G16 -> #REF! | J16: =G16*H16 -> #REF! | K16: =F16-J16 -> #REF! | L16: In stock | N16: =MONTH(D16)=10 -> #REF!
A17: =OBR_Feb_2025!A12 | B17: =OBR_Feb_2025!B12 | C17: gram | D17: {=IFNA((MAX(INDIRECT(A17&"!"&"A:A"))),OBR_May_2025!G14)} -> #REF! | E17: {=IF(D17=OBR_Aug_2025!G14,OBR_Aug_2025!D14, SUMIF(INDIRECT(A17&"!"&"A:A"),D17,INDIRECT(A17&"!"&"G:G")))} -> #REF! | F17: =E17*H17 -> #REF! | G17: ='12011'!J10 -> 8400 | H17: {=IF(D17=OBR_May_2025!G12,OBR_May_2025!E12, SUMIF(INDIRECT(A17&"!"&"A:A"),D17,INDIRECT(A17&"!"&"H:H")))} -> #REF! | I17: =E17-G17 -> #REF! | J17: =G17*H17 -> #REF! | K17: =F17-J17 -> #REF! | L17: In stock | N17: =MONTH(D17)=10 -> #REF!
A18: =OBR_Feb_2025!A13 | B18: =OBR_Feb_2025!B13 | C18: gram | D18: {=IFNA((MAX(INDIRECT(A18&"!"&"A:A"))),OBR_May_2025!G15)} -> #REF! | E18: {=IF(D18=OBR_Aug_2025!G15,OBR_Aug_2025!D15, SUMIF(INDIRECT(A18&"!"&"A:A"),D18,INDIRECT(A18&"!"&"G:G")))} -> #REF! | F18: =E18*H18 -> #REF! | G18: ='12012'!J10 -> 780 | H18: {=IF(D18=OBR_May_2025!G13,OBR_May_2025!E13, SUMIF(INDIRECT(A18&"!"&"A:A"),D18,INDIRECT(A18&"!"&"H:H")))} -> #REF! | I18: =E18-G18 -> #REF! | J18: =G18*H18 -> #REF! | K18: =F18-J18 -> #REF! | L18: In stock | N18: =MONTH(D18)=10 -> #REF!
A19: =OBR_Feb_2025!A14 | B19: =OBR_Feb_2025!B14 | C19: gram | D19: {=IFNA((MAX(INDIRECT(A19&"!"&"A:A"))),OBR_May_2025!G16)} -> #REF! | E19: {=IF(D19=OBR_Aug_2025!G16,OBR_Aug_2025!D16, SUMIF(INDIRECT(A19&"!"&"A:A"),D19,INDIRECT(A19&"!"&"G:G")))} -> #REF! | F19: =E19*H19 -> #REF! | G19: ='12013'!J10 -> 11152 | H19: {=IF(D19=OBR_May_2025!G14,OBR_May_2025!E14, SUMIF(INDIRECT(A19&"!"&"A:A"),D19,INDIRECT(A19&"!"&"H:H")))} -> #REF! | I19: =E19-G19 -> #REF! | J19: =G19*H19 -> #REF! | K19: =F19-J19 -> #REF! | L19: In stock | N19: =MONTH(D19)=10 -> #REF!
A20: =OBR_Feb_2025!A15 | B20: =OBR_Feb_2025!B15 | C20: gram | D20: {=IFNA((MAX(INDIRECT(A20&"!"&"A:A"))),OBR_May_2025!G17)} -> #REF! | E20: {=IF(D20=OBR_Aug_2025!G17,OBR_Aug_2025!D17, SUMIF(INDIRECT(A20&"!"&"A:A"),D20,INDIRECT(A20&"!"&"G:G")))} -> #REF! | F20: =E20*H20 -> #REF! | G20: ='12014'!J10 -> 382 | H20: {=IF(D20=OBR_May_2025!G15,OBR_May_2025!E15, SUMIF(INDIRECT(A20&"!"&"A:A"),D20,INDIRECT(A20&"!"&"H:H")))} -> #REF! | I20: =E20-G20 -> #REF! | J20: =G20*H20 -> #REF! | K20: =F20-J20 -> #REF! | L20: In stock | N20: =MONTH(D20)=10 -> #REF! | O20: =B20
A21: =OBR_Feb_2025!A16 | B21: =OBR_Feb_2025!B16 | C21: gram | D21: {=IFNA((MAX(INDIRECT(A21&"!"&"A:A"))),OBR_May_2025!G18)} -> #REF! | E21: {=IF(D21=OBR_Aug_2025!G18,OBR_Aug_2025!D18, SUMIF(INDIRECT(A21&"!"&"A:A"),D21,INDIRECT(A21&"!"&"G:G")))} -> #REF! | F21: =E21*H21 -> #REF! | G21: ='12015'!J10 -> 5000 | H21: {=IF(D21=OBR_May_2025!G16,OBR_May_2025!E16, SUMIF(INDIRECT(A21&"!"&"A:A"),D21,INDIRECT(A21&"!"&"H:H")))} -> #REF! | I21: =E21-G21 -> #REF! | J21: =G21*H21 -> #REF! | K21: =F21-J21 -> #REF! | L21: In stock | N21: =MONTH(D21)=10 -> #REF! | O21: =B21
A22: =OBR_Feb_2025!A17 | B22: =OBR_Feb_2025!B17 | C22: gram | D22: {=IFNA((MAX(INDIRECT(A22&"!"&"A:A"))),OBR_May_2025!G19)} -> #REF! | E22: {=IF(D22=OBR_Aug_2025!G19,OBR_Aug_2025!D19, SUMIF(INDIRECT(A22&"!"&"A:A"),D22,INDIRECT(A22&"!"&"G:G")))} -> #REF! | F22: =E22*H22 -> #REF! | G22: 450 | H22: {=IF(D22=OBR_May_2025!G17,OBR_May_2025!E17, SUMIF(INDIRECT(A22&"!"&"A:A"),D22,INDIRECT(A22&"!"&"H:H")))} -> #REF! | I22: =E22-G22 -> #REF! | J22: =G22*H22 -> #REF! | K22: =F22-J22 -> #REF! | L22: In stock | N22: =MONTH(D22)=10 -> #REF! | O22: =B22
A23: =OBR_Feb_2025!A18 | B23: =OBR_Feb_2025!B18 | C23: bag | D23: {=IFNA((MAX(INDIRECT(A23&"!"&"A:A"))),OBR_May_2025!G20)} -> #REF! | E23: {=IF(D23=OBR_Aug_2025!G20,OBR_Aug_2025!D20, SUMIF(INDIRECT(A23&"!"&"A:A"),D23,INDIRECT(A23&"!"&"G:G")))} -> #REF! | F23: =E23*H23 -> #REF! | G23: ='12017'!J15 -> 0.548 | H23: {=IF(D23=OBR_May_2025!G18,OBR_May_2025!E18, SUMIF(INDIRECT(A23&"!"&"A:A"),D23,INDIRECT(A23&"!"&"H:H")))} -> #REF! | I23: =E23-G23 -> #REF! | J23: =G23*H23 -> #REF! | K23: =F23-J23 -> #REF! | L23: In stock | N23: =MONTH(D23)=10 -> #REF!
A24: =OBR_Feb_2025!A19 | B24: =OBR_Feb_2025!B19 | C24: bag | D24: {=IFNA((MAX(INDIRECT(A24&"!"&"A:A"))),OBR_May_2025!G21)} -> #REF! | E24: {=IF(D24=OBR_Aug_2025!G21,OBR_Aug_2025!D21, SUMIF(INDIRECT(A24&"!"&"A:A"),D24,INDIRECT(A24&"!"&"G:G")))} -> #REF! | F24: =E24*H24 -> #REF! | G24: ='12018'!J18 -> 1.06 | H24: {=IF(D24=OBR_May_2025!G19,OBR_May_2025!E19, SUMIF(INDIRECT(A24&"!"&"A:A"),D24,INDIRECT(A24&"!"&"H:H")))} -> #REF! | I24: =E24-G24 -> #REF! | J24: =G24*H24 -> #REF! | K24: =F24-J24 -> #REF! | L24: In stock | N24: =MONTH(D24)=10 -> #REF!

Sheet COP & Purchases Tracker
D1: 200 | E1: 20 | F1: 1 | G1: 3 | H1: 5000 | I1: 750 | J1: 0 | K1: 0 | L1: 0 | M1: 0 | N1: 0 | O1: 0 | P1: 0 | Q1: 0 | R1: 0 | S1: 0 | T1: 2 | U1: 10 | W1: 4021000 | X1: 2717140.7 | Y1: 226090.44 | Z1: 480568.91 | AA1: 352954.55 | AB1: 35295.455 | AC1: 0 | AD1: 0 | AE1: 0 | AF1: 0 | AG1: 0 | AH1: 0 | AI1: 0 | AJ1: 0 | AK1: 0 | AL1: 0 | AM1: 30000 | AN1: 153000 | BK1: 224236.17 | BL1: 159459.76 | BM1: 64.956121 | BN1: 46.998638 | BO1: 62.5 | BP1: 60000 | BQ1: 50 | BR1: 46.666667 | BS1: 55.2 | BT1: 46.666667 | BU1: 70 | BV1: 91.111111 | BW1: 57.6 | BX1: 77.777778 | BY1: 15000 | BZ1: 15300 | CB1: 1565631.2 | CC1: 1221917.4 | CD1: 224236.17 | CE1: 318919.51 | CF1: 144202.59 | CG1: 28293.18 | CH1: 77500 | CI1: 9000 | CJ1: 119100 | CK1: 14746.667 | CL1: 57408 | CM1: 6253.3333 | CN1: 223300 | CO1: 12755.556 | CP1: 0 | CQ1: 0 | CR1: 15000 | CS1: 99450
D4: Purchase Quantity | W4: Total Cost ( Purchase + Carriage Inward) | AP4: Stock Units Used in Production | BI4: Weighted Average Unit Cost | CB4: Cost of Production
B5: Period | D5: 12001 | E5: 12002 | F5: 12003 | G5: 12004 | H5: 12005 | I5: 12006 | J5: 12007 | K5: 12008 | L5: 12009 | M5: 12010 | N5: 12011 | O5: 12012 | P5: 12013 | Q5: 12014 | R5: 12015 | S5: 12016 | T5: 12017 | U5: 12018 | W5: 12001 | X5: 12002 | Y5: 12003 | Z5: 12004 | AA5: 12005 | AB5: 12006 | AC5: 12007 | AD5: 12008 | AE5: 12009 | AF5: 12010 | AG5: 12011 | AH5: 12012 | AI5: 12013 | AJ5: 12014 | AK5: 12015 | AL5: 12016 | AM5: 12017 | AN5: 12018 | AP5: {=TRANSPOSE(Dashboard!$A$7:$A$24)} -> #REF! | BI5: 12001 | BJ5: 12002 | BK5: 12003 | BL5: 12004 | BM5: 12005 | BN5: 12006 | BO5: 12007 | BP5: 12008 | BQ5: 12009 | BR5: 12010 | BS5: 12011 | BT5: 12012 | BU5: 12013 | BV5: 12014 | BW5: 12015 | BX5: 12016 | BY5: 12017 | BZ5: 12018 | CB5: 12001 | CC5: 12002 | CD5: 12003 | CE5: 12004 | CF5: 12005 | CG5: 12006 | CH5: 12007 | CI5: 12008 | CJ5: 12009 | CK5: 12010 | CL5: 12011 | CM5: 12012 | CN5: 12013 | CO5: 12014 | CP5: 12015 | CQ5: 12016 | CR5: 12017 | CS5: 12018 | CU5: Total Cost of Production
B6: 45716 | D6: =SUMIF(INDIRECT(D5&"!"&"A:A"),"<="&$B$6,INDIRECT(D5&"!"&"D:D")) -> 0 | E6: =SUMIF(INDIRECT(E5&"!"&"A:A"),"<="&$B$6,INDIRECT(E5&"!"&"D:D")) -> 0 | F6: {=SUMIF(INDIRECT(F$5&"!"&"A:A"),"<="&$B$6,INDIRECT(F$5&"!"&"D:D"))} -> 0 | G6: =SUMIF(INDIRECT(G5&"!"&"A:A"),"<="&$B$6,INDIRECT(G5&"!"&"D:D")) -> 0 | H6: =SUMIF(INDIRECT(H5&"!"&"A:A"),"<="&$B$6,INDIRECT(H5&"!"&"D:D")) -> 0 | I6: =SUMIF(INDIRECT(I5&"!"&"A:A"),"<="&$B$6,INDIRECT(I5&"!"&"D:D")) -> 0 | J6: =SUMIF(INDIRECT(J5&"!"&"A:A"),"<="&$B$6,INDIRECT(J5&"!"&"D:D")) -> 0 | K6: =SUMIF(INDIRECT(K5&"!"&"A:A"),"<="&$B$6,INDIRECT(K5&"!"&"D:D")) -> 0 | L6: =SUMIF(INDIRECT(L5&"!"&"A:A"),"<="&$B$6,INDIRECT(L5&"!"&"D:D")) -> 0 | M6: =SUMIF(INDIRECT(M5&"!"&"A:A"),"<="&$B$6,INDIRECT(M5&"!"&"D:D")) -> 0 | N6: =SUMIF(INDIRECT(N5&"!"&"A:A"),"<="&$B$6,INDIRECT(N5&"!"&"D:D")) -> 0 | ... U6: =SUMIF(INDIRECT(U5&"!"&"A:A"),"<="&$B$6,INDIRECT(U5&"!"&"D:D")) -> 0 | W6: =SUMIF(INDIRECT(W$5&"!"&"A:A"),"<="&$B$6,INDIRECT(D$5&"!"&"F:F")) -> 0 | X6: =SUMIF(INDIRECT(X$5&"!"&"A:A"),"<="&$B$6,INDIRECT(E$5&"!"&"F:F")) -> 0 | Y6: =SUMIF(INDIRECT(Y$5&"!"&"A:A"),"<="&$B$6,INDIRECT(F$5&"!"&"F:F")) -> 0 | Z6: =SUMIF(INDIRECT(Z$5&"!"&"A:A"),"<="&$B$6,INDIRECT(G$5&"!"&"F:F")) -> 0 | AA6: =SUMIF(INDIRECT(AA$5&"!"&"A:A"),"<="&$B$6,INDIRECT(H$5&"!"&"F:F")) -> 0 | AB6: =SUMIF(INDIRECT(AB$5&"!"&"A:A"),"<="&$B$6,INDIRECT(I$5&"!"&"F:F")) -> 0 | AC6: =SUMIF(INDIRECT(AC$5&"!"&"A:A"),"<="&$B$6,INDIRECT(J$5&"!"&"F:F")) -> 0 | AD6: =SUMIF(INDIRECT(AD$5&"!"&"A:A"),"<="&$B$6,INDIRECT(K$5&"!"&"F:F")) -> 0 | ... AN6: =SUMIF(INDIRECT(AN$5&"!"&"A:A"),"<="&$B$6,INDIRECT(U$5&"!"&"F:F")) -> 0 | AP6: =SUMIF(INDIRECT(AP$5&"!"&"A:A"),"<="&$B$6,INDIRECT(AP$5&"!"&"I:I")) -> #N/A | AQ6: =SUMIF(INDIRECT(AQ$5&"!"&"A:A"),"<="&$B$6,INDIRECT(AQ$5&"!"&"I:I")) -> 0 | AR6: =SUMIF(INDIRECT(AR$5&"!"&"A:A"),"<="&$B$6,INDIRECT(AR$5&"!"&"I:I")) -> 0 | AS6: =SUMIF(INDIRECT(AS$5&"!"&"A:A"),"<="&$B$6,INDIRECT(AS$5&"!"&"I:I")) -> 0 | AT6: =SUMIF(INDIRECT(AT$5&"!"&"A:A"),"<="&$B$6,INDIRECT(AT$5&"!"&"I:I")) -> 0 | AU6: =SUMIF(INDIRECT(AU$5&"!"&"A:A"),"<="&$B$6,INDIRECT(AU$5&"!"&"I:I")) -> 0 | AV6: =SUMIF(INDIRECT(AV$5&"!"&"A:A"),"<="&$B$6,INDIRECT(AV$5&"!"&"I:I")) -> 0 | AW6: =SUMIF(INDIRECT(AW$5&"!"&"A:A"),"<="&$B$6,INDIRECT(AW$5&"!"&"I:I")) -> 0 | ... BG6: =SUMIF(INDIRECT(BG$5&"!"&"A:A"),"<="&$B$6,INDIRECT(BG$5&"!"&"I:I")) -> 0 | BI6: {=TRANSPOSE(OBR_Mar_2025!$E$4:$E$21)} -> 20875.083 | BJ6: 135768.6 | BK6: 224236.17 | BL6: 159459.76 | BM6: 64.956121 | BN6: 46.998638 | BO6: 62.5 | BP6: 60000 | BQ6: 50 | BR6: 46.666667 | BS6: 55.2 | BT6: 46.666667 | BU6: 70 | BV6: 91.111111 | BW6: 57.6 | BX6: 77.777778 | BY6: 15000 | BZ6: 153000 | CB6: =SUMIF(INDIRECT(CB$5&"!"&"A:A"),"<="&$B$6,INDIRECT(CB$5&"!"&"L:L")) -> 0 | CC6: =SUMIF(INDIRECT(CC$5&"!"&"A:A"),"<="&$B$6,INDIRECT(CC$5&"!"&"L:L")) -> 0 | CD6: =SUMIF(INDIRECT(CD$5&"!"&"A:A"),"<="&$B$6,INDIRECT(CD$5&"!"&"L:L")) -> 0 | CE6: =SUMIF(INDIRECT(CE$5&"!"&"A:A"),"<="&$B$6,INDIRECT(CE$5&"!"&"L:L")) -> 0 | CF6: =SUMIF(INDIRECT(CF$5&"!"&"A:A"),"<="&$B$6,INDIRECT(CF$5&"!"&"L:L")) -> 0 | CG6: =SUMIF(INDIRECT(CG$5&"!"&"A:A"),"<="&$B$6,INDIRECT(CG$5&"!"&"L:L")) -> 0 | CH6: =SUMIF(INDIRECT(CH$5&"!"&"A:A"),"<="&$B$6,INDIRECT(CH$5&"!"&"L:L")) -> 0 | CI6: =SUMIF(INDIRECT(CI$5&"!"&"A:A"),"<="&$B$6,INDIRECT(CI$5&"!"&"L:L")) -> 0 | ... CS6: =SUMIF(INDIRECT(CS$5&"!"&"A:A"),"<="&$B$6,INDIRECT(CS$5&"!"&"L:L")) -> 0 | CU6: =SUM(CB6:CS6) -> 0
B7: 45747 | D7: =SUMIF(INDIRECT(D$5&"!"&"A:A"),"<="&$B$7,INDIRECT(D$5&"!"&"D:D"))-SUM(D$6:D6) -> 0 | E7: =SUMIF(INDIRECT(E$5&"!"&"A:A"),"<="&$B$7,INDIRECT(E$5&"!"&"D:D"))-SUM(E$6:E6) -> 0 | F7: =SUMIF(INDIRECT(F$5&"!"&"A:A"),"<="&$B$7,INDIRECT(F$5&"!"&"D:D"))-SUM(F$6:F6) -> 0 | G7: =SUMIF(INDIRECT(G$5&"!"&"A:A"),"<="&$B$7,INDIRECT(G$5&"!"&"D:D"))-SUM(G$6:G6) -> 0 | H7: =SUMIF(INDIRECT(H$5&"!"&"A:A"),"<="&$B$7,INDIRECT(H$5&"!"&"D:D"))-SUM(H$6:H6) -> 0 | I7: =SUMIF(INDIRECT(I$5&"!"&"A:A"),"<="&$B$7,INDIRECT(I$5&"!"&"D:D"))-SUM(I$6:I6) -> 0 | J7: =SUMIF(INDIRECT(J$5&"!"&"A:A"),"<="&$B$7,INDIRECT(J$5&"!"&"D:D"))-SUM(J$6:J6) -> 0 | K7: =SUMIF(INDIRECT(K$5&"!"&"A:A"),"<="&$B$7,INDIRECT(K$5&"!"&"D:D"))-SUM(K$6:K6) -> 0 | ... U7: =SUMIF(INDIRECT(U$5&"!"&"A:A"),"<="&$B$7,INDIRECT(U$5&"!"&"D:D"))-SUM(U$6:U6) -> 0 | W7: =SUMIF(INDIRECT(W$5&"!"&"A:A"),"<="&$B$7,INDIRECT(D$5&"!"&"F:F"))-SUM(W$6:W6) -> 0 | X7: =SUMIF(INDIRECT(X$5&"!"&"A:A"),"<="&$B$7,INDIRECT(E$5&"!"&"F:F"))-SUM(X$6:X6) -> 0 | Y7: =SUMIF(INDIRECT(Y$5&"!"&"A:A"),"<="&$B$7,INDIRECT(F$5&"!"&"F:F"))-SUM(Y$6:Y6) -> 0 | Z7: =SUMIF(INDIRECT(Z$5&"!"&"A:A"),"<="&$B$7,INDIRECT(G$5&"!"&"F:F"))-SUM(Z$6:Z6) -> 0 | AA7: =SUMIF(INDIRECT(AA$5&"!"&"A:A"),"<="&$B$7,INDIRECT(H$5&"!"&"F:F"))-SUM(AA$6:AA6) -> 0 | AB7: =SUMIF(INDIRECT(AB$5&"!"&"A:A"),"<="&$B$7,INDIRECT(I$5&"!"&"F:F"))-SUM(AB$6:AB6) -> 0 | AC7: =SUMIF(INDIRECT(AC$5&"!"&"A:A"),"<="&$B$7,INDIRECT(J$5&"!"&"F:F"))-SUM(AC$6:AC6) -> 0 | AD7: =SUMIF(INDIRECT(AD$5&"!"&"A:A"),"<="&$B$7,INDIRECT(K$5&"!"&"F:F"))-SUM(AD$6:AD6) -> 0 | ... AN7: =SUMIF(INDIRECT(AN$5&"!"&"A:A"),"<="&$B$7,INDIRECT(U$5&"!"&"F:F"))-SUM(AN$6:AN6) -> 0 | AP7: =SUMIF(INDIRECT(AP$5&"!"&"A:A"),"<="&$B$7,INDIRECT(AP$5&"!"&"I:I"))-SUM(AP$6:AP6) -> #N/A | AQ7: =SUMIF(INDIRECT(AQ$5&"!"&"A:A"),"<="&$B$7,INDIRECT(AQ$5&"!"&"I:I"))-SUM(AQ$6:AQ6) -> 0 | AR7: =SUMIF(INDIRECT(AR$5&"!"&"A:A"),"<="&$B$7,INDIRECT(AR$5&"!"&"I:I"))-SUM(AR$6:AR6) -> 0 | AS7: =SUMIF(INDIRECT(AS$5&"!"&"A:A"),"<="&$B$7,INDIRECT(AS$5&"!"&"I:I"))-SUM(AS$6:AS6) -> 0 | AT7: =SUMIF(INDIRECT(AT$5&"!"&"A:A"),"<="&$B$7,INDIRECT(AT$5&"!"&"I:I"))-SUM(AT$6:AT6) -> 0 | AU7: =SUMIF(INDIRECT(AU$5&"!"&"A:A"),"<="&$B$7,INDIRECT(AU$5&"!"&"I:I"))-SUM(AU$6:AU6) -> 0 | AV7: =SUMIF(INDIRECT(AV$5&"!"&"A:A"),"<="&$B$7,INDIRECT(AV$5&"!"&"I:I"))-SUM(AV$6:AV6) -> 0 | AW7: =SUMIF(INDIRECT(AW$5&"!"&"A:A"),"<="&$B$7,INDIRECT(AW$5&"!"&"I:I"))-SUM(AW$6:AW6) -> 0 | ... BG7: =SUMIF(INDIRECT(BG$5&"!"&"A:A"),"<="&$B$7,INDIRECT(BG$5&"!"&"I:I"))-SUM(BG$6:BG6) -> 0 | BI7: {=TRANSPOSE(OBR_April_2025!$E$4:$E$21)} -> 20875.083 | BJ7: 133652.1 | BK7: 223506.57 | BL7: 156788.15 | BM7: 64.071575 | BN7: 46.928342 | BO7: 62.5 | BP7: 54860.448 | BQ7: 50 | BR7: 46.666667 | BS7: 58.248442 | BT7: 33.290897 | BU7: 70.463906 | BV7: 59.469194 | BW7: 57.6 | BX7: 77.777778 | BY7: 18333.333 | BZ7: 153000 | CB7: =SUMIF(INDIRECT(CB$5&"!"&"A:A"),"<="&$B$7,INDIRECT(CB$5&"!"&"L:L"))-SUM(CB$6:CB6) -> 0 | CC7: =SUMIF(INDIRECT(CC$5&"!"&"A:A"),"<="&$B$7,INDIRECT(CC$5&"!"&"L:L"))-SUM(CC$6:CC6) -> 0 | CD7: =SUMIF(INDIRECT(CD$5&"!"&"A:A"),"<="&$B$7,INDIRECT(CD$5&"!"&"L:L"))-SUM(CD$6:CD6) -> 0 | CE7: =SUMIF(INDIRECT(CE$5&"!"&"A:A"),"<="&$B$7,INDIRECT(CE$5&"!"&"L:L"))-SUM(CE$6:CE6) -> 0 | CF7: =SUMIF(INDIRECT(CF$5&"!"&"A:A"),"<="&$B$7,INDIRECT(CF$5&"!"&"L:L"))-SUM(CF$6:CF6) -> 0 | CG7: =SUMIF(INDIRECT(CG$5&"!"&"A:A"),"<="&$B$7,INDIRECT(CG$5&"!"&"L:L"))-SUM(CG$6:CG6) -> 0 | CH7: =SUMIF(INDIRECT(CH$5&"!"&"A:A"),"<="&$B$7,INDIRECT(CH$5&"!"&"L:L"))-SUM(CH$6:CH6) -> 0 | CI7: =SUMIF(INDIRECT(CI$5&"!"&"A:A"),"<="&$B$7,INDIRECT(CI$5&"!"&"L:L"))-SUM(CI$6:CI6) -> 0 | ... CS7: =SUMIF(INDIRECT(CS$5&"!"&"A:A"),"<="&$B$7,INDIRECT(CS$5&"!"&"L:L"))-SUM(CS$6:CS6) -> 0 | CU7: =SUM(CB7:CS7) -> 0
B8: 45777 | D8: =SUMIF(INDIRECT(D$5&"!"&"A:A"),"<="&$B8,INDIRECT(D$5&"!"&"D:D"))-SUM(D$6:D7) -> 0 | E8: =SUMIF(INDIRECT(E$5&"!"&"A:A"),"<="&$B8,INDIRECT(E$5&"!"&"D:D"))-SUM(E$6:E7) -> 0 | F8: =SUMIF(INDIRECT(F$5&"!"&"A:A"),"<="&$B8,INDIRECT(F$5&"!"&"D:D"))-SUM(F$6:F7) -> 0 | G8: =SUMIF(INDIRECT(G$5&"!"&"A:A"),"<="&$B8,INDIRECT(G$5&"!"&"D:D"))-SUM(G$6:G7) -> 0 | H8: =SUMIF(INDIRECT(H$5&"!"&"A:A"),"<="&$B8,INDIRECT(H$5&"!"&"D:D"))-SUM(H$6:H7) -> 0 | I8: =SUMIF(INDIRECT(I$5&"!"&"A:A"),"<="&$B8,INDIRECT(I$5&"!"&"D:D"))-SUM(I$6:I7) -> 0 | J8: =SUMIF(INDIRECT(J$5&"!"&"A:A"),"<="&$B8,INDIRECT(J$5&"!"&"D:D"))-SUM(J$6:J7) -> 0 | K8: =SUMIF(INDIRECT(K$5&"!"&"A:A"),"<="&$B8,INDIRECT(K$5&"!"&"D:D"))-SUM(K$6:K7) -> 0 | ... U8: =SUMIF(INDIRECT(U$5&"!"&"A:A"),"<="&$B8,INDIRECT(U$5&"!"&"D:D"))-SUM(U$6:U7) -> 0 | W8: =SUMIF(INDIRECT(W$5&"!"&"A:A"),"<="&$B8,INDIRECT(D$5&"!"&"F:F"))-SUM(W$6:W7) -> 0 | X8: =SUMIF(INDIRECT(X$5&"!"&"A:A"),"<="&$B8,INDIRECT(E$5&"!"&"F:F"))-SUM(X$6:X7) -> 0 | Y8: =SUMIF(INDIRECT(Y$5&"!"&"A:A"),"<="&$B8,INDIRECT(F$5&"!"&"F:F"))-SUM(Y$6:Y7) -> 0 | Z8: =SUMIF(INDIRECT(Z$5&"!"&"A:A"),"<="&$B8,INDIRECT(G$5&"!"&"F:F"))-SUM(Z$6:Z7) -> 0 | AA8: =SUMIF(INDIRECT(AA$5&"!"&"A:A"),"<="&$B8,INDIRECT(H$5&"!"&"F:F"))-SUM(AA$6:AA7) -> 0 | AB8: =SUMIF(INDIRECT(AB$5&"!"&"A:A"),"<="&$B8,INDIRECT(I$5&"!"&"F:F"))-SUM(AB$6:AB7) -> 0 | AC8: =SUMIF(INDIRECT(AC$5&"!"&"A:A"),"<="&$B8,INDIRECT(J$5&"!"&"F:F"))-SUM(AC$6:AC7) -> 0 | AD8: =SUMIF(INDIRECT(AD$5&"!"&"A:A"),"<="&$B8,INDIRECT(K$5&"!"&"F:F"))-SUM(AD$6:AD7) -> 0 | ... AN8: =SUMIF(INDIRECT(AN$5&"!"&"A:A"),"<="&$B8,INDIRECT(U$5&"!"&"F:F"))-SUM(AN$6:AN7) -> 0 | AP8: =SUMIF(INDIRECT(AP$5&"!"&"A:A"),"<="&$B8,INDIRECT(AP$5&"!"&"I:I"))-SUM(AP$6:AP7) -> #N/A | AQ8: =SUMIF(INDIRECT(AQ$5&"!"&"A:A"),"<="&$B8,INDIRECT(AQ$5&"!"&"I:I"))-SUM(AQ$6:AQ7) -> 0 | AR8: =SUMIF(INDIRECT(AR$5&"!"&"A:A"),"<="&$B8,INDIRECT(AR$5&"!"&"I:I"))-SUM(AR$6:AR7) -> 0 | AS8: =SUMIF(INDIRECT(AS$5&"!"&"A:A"),"<="&$B8,INDIRECT(AS$5&"!"&"I:I"))-SUM(AS$6:AS7) -> 0 | AT8: =SUMIF(INDIRECT(AT$5&"!"&"A:A"),"<="&$B8,INDIRECT(AT$5&"!"&"I:I"))-SUM(AT$6:AT7) -> 0 | AU8: =SUMIF(INDIRECT(AU$5&"!"&"A:A"),"<="&$B8,INDIRECT(AU$5&"!"&"I:I"))-SUM(AU$6:AU7) -> 0 | AV8: =SUMIF(INDIRECT(AV$5&"!"&"A:A"),"<="&$B8,INDIRECT(AV$5&"!"&"I:I"))-SUM(AV$6:AV7) -> 0 | AW8: =SUMIF(INDIRECT(AW$5&"!"&"A:A"),"<="&$B8,INDIRECT(AW$5&"!"&"I:I"))-SUM(AW$6:AW7) -> 0 | ... BG8: =SUMIF(INDIRECT(BG$5&"!"&"A:A"),"<="&$B8,INDIRECT(BG$5&"!"&"I:I"))-SUM(BG$6:BG7) -> 0 | BI8: {=TRANSPOSE(OBR_May_2025!$E$4:$E$21)} -> 20875.083 | BJ8: 130889.3 | BK8: 223506.57 | BL8: 156788.15 | BM8: 64.071575 | BN8: 55.166372 | BO8: 68.562458 | BP8: 47428.23 | BQ8: 55.508956 | BR8: 83.985507 | BS8: 58.248442 | BT8: 33.290897 | BU8: 70.463906 | BV8: 59.469194 | BW8: 57.6 | BX8: 77.777778 | BY8: 23166.667 | BZ8: 153373.39 | CB8: =SUMIF(INDIRECT(CB$5&"!"&"A:A"),"<="&$B8,INDIRECT(CB$5&"!"&"L:L"))-SUM(CB$6:CB7) -> 0 | CC8: =SUMIF(INDIRECT(CC$5&"!"&"A:A"),"<="&$B8,INDIRECT(CC$5&"!"&"L:L"))-SUM(CC$6:CC7) -> 0 | CD8: =SUMIF(INDIRECT(CD$5&"!"&"A:A"),"<="&$B8,INDIRECT(CD$5&"!"&"L:L"))-SUM(CD$6:CD7) -> 0 | CE8: =SUMIF(INDIRECT(CE$5&"!"&"A:A"),"<="&$B8,INDIRECT(CE$5&"!"&"L:L"))-SUM(CE$6:CE7) -> 0 | CF8: =SUMIF(INDIRECT(CF$5&"!"&"A:A"),"<="&$B8,INDIRECT(CF$5&"!"&"L:L"))-SUM(CF$6:CF7) -> 0 | CG8: =SUMIF(INDIRECT(CG$5&"!"&"A:A"),"<="&$B8,INDIRECT(CG$5&"!"&"L:L"))-SUM(CG$6:CG7) -> 0 | CH8: =SUMIF(INDIRECT(CH$5&"!"&"A:A"),"<="&$B8,INDIRECT(CH$5&"!"&"L:L"))-SUM(CH$6:CH7) -> 0 | CI8: =SUMIF(INDIRECT(CI$5&"!"&"A:A"),"<="&$B8,INDIRECT(CI$5&"!"&"L:L"))-SUM(CI$6:CI7) -> 0 | ... CS8: =SUMIF(INDIRECT(CS$5&"!"&"A:A"),"<="&$B8,INDIRECT(CS$5&"!"&"L:L"))-SUM(CS$6:CS7) -> 0 | CU8: =SUM(CB8:CS8) -> 0
B9: 45808 | D9: =SUMIF(INDIRECT(D$5&"!"&"A:A"),"<="&$B9,INDIRECT(D$5&"!"&"D:D"))-SUM(D$6:D8) -> 0 | E9: =SUMIF(INDIRECT(E$5&"!"&"A:A"),"<="&$B9,INDIRECT(E$5&"!"&"D:D"))-SUM(E$6:E8) -> 0 | F9: =SUMIF(INDIRECT(F$5&"!"&"A:A"),"<="&$B9,INDIRECT(F$5&"!"&"D:D"))-SUM(F$6:F8) -> 0 | G9: =SUMIF(INDIRECT(G$5&"!"&"A:A"),"<="&$B9,INDIRECT(G$5&"!"&"D:D"))-SUM(G$6:G8) -> 0 | H9: =SUMIF(INDIRECT(H$5&"!"&"A:A"),"<="&$B9,INDIRECT(H$5&"!"&"D:D"))-SUM(H$6:H8) -> 0 | I9: =SUMIF(INDIRECT(I$5&"!"&"A:A"),"<="&$B9,INDIRECT(I$5&"!"&"D:D"))-SUM(I$6:I8) -> 0 | J9: =SUMIF(INDIRECT(J$5&"!"&"A:A"),"<="&$B9,INDIRECT(J$5&"!"&"D:D"))-SUM(J$6:J8) -> 0 | K9: =SUMIF(INDIRECT(K$5&"!"&"A:A"),"<="&$B9,INDIRECT(K$5&"!"&"D:D"))-SUM(K$6:K8) -> 0 | ... U9: =SUMIF(INDIRECT(U$5&"!"&"A:A"),"<="&$B9,INDIRECT(U$5&"!"&"D:D"))-SUM(U$6:U8) -> 0 | W9: =SUMIF(INDIRECT(W$5&"!"&"A:A"),"<="&$B9,INDIRECT(D$5&"!"&"F:F"))-SUM(W$6:W8) -> 0 | X9: =SUMIF(INDIRECT(X$5&"!"&"A:A"),"<="&$B9,INDIRECT(E$5&"!"&"F:F"))-SUM(X$6:X8) -> 0 | Y9: =SUMIF(INDIRECT(Y$5&"!"&"A:A"),"<="&$B9,INDIRECT(F$5&"!"&"F:F"))-SUM(Y$6:Y8) -> 0 | Z9: =SUMIF(INDIRECT(Z$5&"!"&"A:A"),"<="&$B9,INDIRECT(G$5&"!"&"F:F"))-SUM(Z$6:Z8) -> 0 | AA9: =SUMIF(INDIRECT(AA$5&"!"&"A:A"),"<="&$B9,INDIRECT(H$5&"!"&"F:F"))-SUM(AA$6:AA8) -> 0 | AB9: =SUMIF(INDIRECT(AB$5&"!"&"A:A"),"<="&$B9,INDIRECT(I$5&"!"&"F:F"))-SUM(AB$6:AB8) -> 0 | AC9: =SUMIF(INDIRECT(AC$5&"!"&"A:A"),"<="&$B9,INDIRECT(J$5&"!"&"F:F"))-SUM(AC$6:AC8) -> 0 | AD9: =SUMIF(INDIRECT(AD$5&"!"&"A:A"),"<="&$B9,INDIRECT(K$5&"!"&"F:F"))-SUM(AD$6:AD8) -> 0 | ... AN9: =SUMIF(INDIRECT(AN$5&"!"&"A:A"),"<="&$B9,INDIRECT(U$5&"!"&"F:F"))-SUM(AN$6:AN8) -> 0 | AP9: =SUMIF(INDIRECT(AP$5&"!"&"A:A"),"<="&$B9,INDIRECT(AP$5&"!"&"I:I"))-SUM(AP$6:AP8) -> #N/A | AQ9: =SUMIF(INDIRECT(AQ$5&"!"&"A:A"),"<="&$B9,INDIRECT(AQ$5&"!"&"I:I"))-SUM(AQ$6:AQ8) -> 0 | AR9: =SUMIF(INDIRECT(AR$5&"!"&"A:A"),"<="&$B9,INDIRECT(AR$5&"!"&"I:I"))-SUM(AR$6:AR8) -> 0 | AS9: =SUMIF(INDIRECT(AS$5&"!"&"A:A"),"<="&$B9,INDIRECT(AS$5&"!"&"I:I"))-SUM(AS$6:AS8) -> 0 | AT9: =SUMIF(INDIRECT(AT$5&"!"&"A:A"),"<="&$B9,INDIRECT(AT$5&"!"&"I:I"))-SUM(AT$6:AT8) -> 0 | AU9: =SUMIF(INDIRECT(AU$5&"!"&"A:A"),"<="&$B9,INDIRECT(AU$5&"!"&"I:I"))-SUM(AU$6:AU8) -> 0 | AV9: =SUMIF(INDIRECT(AV$5&"!"&"A:A"),"<="&$B9,INDIRECT(AV$5&"!"&"I:I"))-SUM(AV$6:AV8) -> 0 | AW9: =SUMIF(INDIRECT(AW$5&"!"&"A:A"),"<="&$B9,INDIRECT(AW$5&"!"&"I:I"))-SUM(AW$6:AW8) -> 0 | ... BG9: =SUMIF(INDIRECT(BG$5&"!"&"A:A"),"<="&$B9,INDIRECT(BG$5&"!"&"I:I"))-SUM(BG$6:BG8) -> 0 | BI9: {=TRANSPOSE(OBR_June_2025!$E$4:$E$21)} -> 21101.173 | BJ9: 131296.61 | BK9: 226601.83 | BL9: 154959.77 | BM9: 64.071575 | BN9: 50.117962 | BO9: 68.562458 | BP9: 47428.23 | BQ9: 55.508956 | BR9: 83.985507 | BS9: 58.248442 | BT9: 33.290897 | BU9: 69.743385 | BV9: 58.515933 | BW9: 57.6 | BX9: 77.777778 | BY9: 32668.582 | BZ9: 153049.79 | CB9: =SUMIF(INDIRECT(CB$5&"!"&"A:A"),"<="&$B9,INDIRECT(CB$5&"!"&"L:L"))-SUM(CB$6:CB8) -> 0 | CC9: =SUMIF(INDIRECT(CC$5&"!"&"A:A"),"<="&$B9,INDIRECT(CC$5&"!"&"L:L"))-SUM(CC$6:CC8) -> 0 | CD9: =SUMIF(INDIRECT(CD$5&"!"&"A:A"),"<="&$B9,INDIRECT(CD$5&"!"&"L:L"))-SUM(CD$6:CD8) -> 0 | CE9: =SUMIF(INDIRECT(CE$5&"!"&"A:A"),"<="&$B9,INDIRECT(CE$5&"!"&"L:L"))-SUM(CE$6:CE8) -> 0 | CF9: =SUMIF(INDIRECT(CF$5&"!"&"A:A"),"<="&$B9,INDIRECT(CF$5&"!"&"L:L"))-SUM(CF$6:CF8) -> 0 | CG9: =SUMIF(INDIRECT(CG$5&"!"&"A:A"),"<="&$B9,INDIRECT(CG$5&"!"&"L:L"))-SUM(CG$6:CG8) -> 0 | CH9: =SUMIF(INDIRECT(CH$5&"!"&"A:A"),"<="&$B9,INDIRECT(CH$5&"!"&"L:L"))-SUM(CH$6:CH8) -> 0 | CI9: =SUMIF(INDIRECT(CI$5&"!"&"A:A"),"<="&$B9,INDIRECT(CI$5&"!"&"L:L"))-SUM(CI$6:CI8) -> 0 | ... CS9: =SUMIF(INDIRECT(CS$5&"!"&"A:A"),"<="&$B9,INDIRECT(CS$5&"!"&"L:L"))-SUM(CS$6:CS8) -> 0 | CU9: =SUM(CB9:CS9) -> 0
B10: 45838 | D10: =SUMIF(INDIRECT(D$5&"!"&"A:A"),"<="&$B10,INDIRECT(D$5&"!"&"D:D"))-SUM(D$6:D9) -> 0 | E10: =SUMIF(INDIRECT(E$5&"!"&"A:A"),"<="&$B10,INDIRECT(E$5&"!"&"D:D"))-SUM(E$6:E9) -> 0 | F10: =SUMIF(INDIRECT(F$5&"!"&"A:A"),"<="&$B10,INDIRECT(F$5&"!"&"D:D"))-SUM(F$6:F9) -> 0 | G10: =SUMIF(INDIRECT(G$5&"!"&"A:A"),"<="&$B10,INDIRECT(G$5&"!"&"D:D"))-SUM(G$6:G9) -> 0 | H10: =SUMIF(INDIRECT(H$5&"!"&"A:A"),"<="&$B10,INDIRECT(H$5&"!"&"D:D"))-SUM(H$6:H9) -> 0 | I10: =SUMIF(INDIRECT(I$5&"!"&"A:A"),"<="&$B10,INDIRECT(I$5&"!"&"D:D"))-SUM(I$6:I9) -> 0 | J10: =SUMIF(INDIRECT(J$5&"!"&"A:A"),"<="&$B10,INDIRECT(J$5&"!"&"D:D"))-SUM(J$6:J9) -> 0 | K10: =SUMIF(INDIRECT(K$5&"!"&"A:A"),"<="&$B10,INDIRECT(K$5&"!"&"D:D"))-SUM(K$6:K9) -> 0 | ... U10: =SUMIF(INDIRECT(U$5&"!"&"A:A"),"<="&$B10,INDIRECT(U$5&"!"&"D:D"))-SUM(U$6:U9) -> 0 | W10: =SUMIF(INDIRECT(W$5&"!"&"A:A"),"<="&$B10,INDIRECT(D$5&"!"&"F:F"))-SUM(W$6:W9) -> 0 | X10: =SUMIF(INDIRECT(X$5&"!"&"A:A"),"<="&$B10,INDIRECT(E$5&"!"&"F:F"))-SUM(X$6:X9) -> 0 | Y10: =SUMIF(INDIRECT(Y$5&"!"&"A:A"),"<="&$B10,INDIRECT(F$5&"!"&"F:F"))-SUM(Y$6:Y9) -> 0 | Z10: =SUMIF(INDIRECT(Z$5&"!"&"A:A"),"<="&$B10,INDIRECT(G$5&"!"&"F:F"))-SUM(Z$6:Z9) -> 0 | AA10: =SUMIF(INDIRECT(AA$5&"!"&"A:A"),"<="&$B10,INDIRECT(H$5&"!"&"F:F"))-SUM(AA$6:AA9) -> 0 | AB10: =SUMIF(INDIRECT(AB$5&"!"&"A:A"),"<="&$B10,INDIRECT(I$5&"!"&"F:F"))-SUM(AB$6:AB9) -> 0 | AC10: =SUMIF(INDIRECT(AC$5&"!"&"A:A"),"<="&$B10,INDIRECT(J$5&"!"&"F:F"))-SUM(AC$6:AC9) -> 0 | AD10: =SUMIF(INDIRECT(AD$5&"!"&"A:A"),"<="&$B10,INDIRECT(K$5&"!"&"F:F"))-SUM(AD$6:AD9) -> 0 | ... AN10: =SUMIF(INDIRECT(AN$5&"!"&"A:A"),"<="&$B10,INDIRECT(U$5&"!"&"F:F"))-SUM(AN$6:AN9) -> 0 | AP10: =SUMIF(INDIRECT(AP$5&"!"&"A:A"),"<="&$B10,INDIRECT(AP$5&"!"&"I:I"))-SUM(AP$6:AP9) -> #N/A | AQ10: =SUMIF(INDIRECT(AQ$5&"!"&"A:A"),"<="&$B10,INDIRECT(AQ$5&"!"&"I:I"))-SUM(AQ$6:AQ9) -> 0 | AR10: =SUMIF(INDIRECT(AR$5&"!"&"A:A"),"<="&$B10,INDIRECT(AR$5&"!"&"I:I"))-SUM(AR$6:AR9) -> 0 | AS10: =SUMIF(INDIRECT(AS$5&"!"&"A:A"),"<="&$B10,INDIRECT(AS$5&"!"&"I:I"))-SUM(AS$6:AS9) -> 0 | AT10: =SUMIF(INDIRECT(AT$5&"!"&"A:A"),"<="&$B10,INDIRECT(AT$5&"!"&"I:I"))-SUM(AT$6:AT9) -> 0 | AU10: =SUMIF(INDIRECT(AU$5&"!"&"A:A"),"<="&$B10,INDIRECT(AU$5&"!"&"I:I"))-SUM(AU$6:AU9) -> 0 | AV10: =SUMIF(INDIRECT(AV$5&"!"&"A:A"),"<="&$B10,INDIRECT(AV$5&"!"&"I:I"))-SUM(AV$6:AV9) -> 0 | AW10: =SUMIF(INDIRECT(AW$5&"!"&"A:A"),"<="&$B10,INDIRECT(AW$5&"!"&"I:I"))-SUM(AW$6:AW9) -> 0 | ... BG10: =SUMIF(INDIRECT(BG$5&"!"&"A:A"),"<="&$B10,INDIRECT(BG$5&"!"&"I:I"))-SUM(BG$6:BG9) -> 0 | BI10: {=TRANSPOSE(OBR_July_2025!$E$4:$E$21)} -> 21107.448 | BJ10: 131945.67 | BK10: 227274.25 | BL10: 148642.3 | BM10: 64.937106 | BN10: 52.389178 | BO10: 68.562458 | BP10: 47428.23 | BQ10: 55.508956 | BR10: 83.985507 | BS10: 58.248442 | BT10: 33.290897 | BU10: 69.653419 | BV10: 51.53926 | BW10: 57.6 | BX10: 77.777778 | BY10: 33834.291 | BZ10: 153005.53 | CB10: =SUMIF(INDIRECT(CB$5&"!"&"A:A"),"<="&$B10,INDIRECT(CB$5&"!"&"L:L"))-SUM(CB$6:CB9) -> 0 | CC10: =SUMIF(INDIRECT(CC$5&"!"&"A:A"),"<="&$B10,INDIRECT(CC$5&"!"&"L:L"))-SUM(CC$6:CC9) -> 0 | CD10: =SUMIF(INDIRECT(CD$5&"!"&"A:A"),"<="&$B10,INDIRECT(CD$5&"!"&"L:L"))-SUM(CD$6:CD9) -> 0 | CE10: =SUMIF(INDIRECT(CE$5&"!"&"A:A"),"<="&$B10,INDIRECT(CE$5&"!"&"L:L"))-SUM(CE$6:CE9) -> 0 | CF10: =SUMIF(INDIRECT(CF$5&"!"&"A:A"),"<="&$B10,INDIRECT(CF$5&"!"&"L:L"))-SUM(CF$6:CF9) -> 0 | CG10: =SUMIF(INDIRECT(CG$5&"!"&"A:A"),"<="&$B10,INDIRECT(CG$5&"!"&"L:L"))-SUM(CG$6:CG9) -> 0 | CH10: =SUMIF(INDIRECT(CH$5&"!"&"A:A"),"<="&$B10,INDIRECT(CH$5&"!"&"L:L"))-SUM(CH$6:CH9) -> 0 | CI10: =SUMIF(INDIRECT(CI$5&"!"&"A:A"),"<="&$B10,INDIRECT(CI$5&"!"&"L:L"))-SUM(CI$6:CI9) -> 0 | ... CS10: =SUMIF(INDIRECT(CS$5&"!"&"A:A"),"<="&$B10,INDIRECT(CS$5&"!"&"L:L"))-SUM(CS$6:CS9) -> 0 | CU10: =SUM(CB10:CS10) -> 0
B11: 45869 | D11: =SUMIF(INDIRECT(D$5&"!"&"A:A"),"<="&$B11,INDIRECT(D$5&"!"&"D:D"))-SUM(D$6:D10) -> 0 | E11: =SUMIF(INDIRECT(E$5&"!"&"A:A"),"<="&$B11,INDIRECT(E$5&"!"&"D:D"))-SUM(E$6:E10) -> 0 | F11: =SUMIF(INDIRECT(F$5&"!"&"A:A"),"<="&$B11,INDIRECT(F$5&"!"&"D:D"))-SUM(F$6:F10) -> 0 | G11: =SUMIF(INDIRECT(G$5&"!"&"A:A"),"<="&$B11,INDIRECT(G$5&"!"&"D:D"))-SUM(G$6:G10) -> 0 | H11: =SUMIF(INDIRECT(H$5&"!"&"A:A"),"<="&$B11,INDIRECT(H$5&"!"&"D:D"))-SUM(H$6:H10) -> 0 | I11: =SUMIF(INDIRECT(I$5&"!"&"A:A"),"<="&$B11,INDIRECT(I$5&"!"&"D:D"))-SUM(I$6:I10) -> 0 | J11: =SUMIF(INDIRECT(J$5&"!"&"A:A"),"<="&$B11,INDIRECT(J$5&"!"&"D:D"))-SUM(J$6:J10) -> 0 | K11: =SUMIF(INDIRECT(K$5&"!"&"A:A"),"<="&$B11,INDIRECT(K$5&"!"&"D:D"))-SUM(K$6:K10) -> 0 | ... U11: =SUMIF(INDIRECT(U$5&"!"&"A:A"),"<="&$B11,INDIRECT(U$5&"!"&"D:D"))-SUM(U$6:U10) -> 0 | W11: =SUMIF(INDIRECT(W$5&"!"&"A:A"),"<="&$B11,INDIRECT(D$5&"!"&"F:F"))-SUM(W$6:W10) -> 0 | X11: =SUMIF(INDIRECT(X$5&"!"&"A:A"),"<="&$B11,INDIRECT(E$5&"!"&"F:F"))-SUM(X$6:X10) -> 0 | Y11: =SUMIF(INDIRECT(Y$5&"!"&"A:A"),"<="&$B11,INDIRECT(F$5&"!"&"F:F"))-SUM(Y$6:Y10) -> 0 | Z11: =SUMIF(INDIRECT(Z$5&"!"&"A:A"),"<="&$B11,INDIRECT(G$5&"!"&"F:F"))-SUM(Z$6:Z10) -> 0 | AA11: =SUMIF(INDIRECT(AA$5&"!"&"A:A"),"<="&$B11,INDIRECT(H$5&"!"&"F:F"))-SUM(AA$6:AA10) -> 0 | AB11: =SUMIF(INDIRECT(AB$5&"!"&"A:A"),"<="&$B11,INDIRECT(I$5&"!"&"F:F"))-SUM(AB$6:AB10) -> 0 | AC11: =SUMIF(INDIRECT(AC$5&"!"&"A:A"),"<="&$B11,INDIRECT(J$5&"!"&"F:F"))-SUM(AC$6:AC10) -> 0 | AD11: =SUMIF(INDIRECT(AD$5&"!"&"A:A"),"<="&$B11,INDIRECT(K$5&"!"&"F:F"))-SUM(AD$6:AD10) -> 0 | ... AN11: =SUMIF(INDIRECT(AN$5&"!"&"A:A"),"<="&$B11,INDIRECT(U$5&"!"&"F:F"))-SUM(AN$6:AN10) -> 0 | AP11: =SUMIF(INDIRECT(AP$5&"!"&"A:A"),"<="&$B11,INDIRECT(AP$5&"!"&"I:I"))-SUM(AP$6:AP10) -> #N/A | AQ11: =SUMIF(INDIRECT(AQ$5&"!"&"A:A"),"<="&$B11,INDIRECT(AQ$5&"!"&"I:I"))-SUM(AQ$6:AQ10) -> 0 | AR11: =SUMIF(INDIRECT(AR$5&"!"&"A:A"),"<="&$B11,INDIRECT(AR$5&"!"&"I:I"))-SUM(AR$6:AR10) -> 0 | AS11: =SUMIF(INDIRECT(AS$5&"!"&"A:A"),"<="&$B11,INDIRECT(AS$5&"!"&"I:I"))-SUM(AS$6:AS10) -> 0 | AT11: =SUMIF(INDIRECT(AT$5&"!"&"A:A"),"<="&$B11,INDIRECT(AT$5&"!"&"I:I"))-SUM(AT$6:AT10) -> 0 | AU11: =SUMIF(INDIRECT(AU$5&"!"&"A:A"),"<="&$B11,INDIRECT(AU$5&"!"&"I:I"))-SUM(AU$6:AU10) -> 0 | AV11: =SUMIF(INDIRECT(AV$5&"!"&"A:A"),"<="&$B11,INDIRECT(AV$5&"!"&"I:I"))-SUM(AV$6:AV10) -> 0 | AW11: =SUMIF(INDIRECT(AW$5&"!"&"A:A"),"<="&$B11,INDIRECT(AW$5&"!"&"I:I"))-SUM(AW$6:AW10) -> 0 | ... BG11: =SUMIF(INDIRECT(BG$5&"!"&"A:A"),"<="&$B11,INDIRECT(BG$5&"!"&"I:I"))-SUM(BG$6:BG10) -> 0 | BI11: {=TRANSPOSE(OBR_Aug_2025!$E$4:$E$21)} -> 21107.448 | BJ11: 130509.79 | BK11: 227967.19 | BL11: 145999.02 | BM11: 64.937106 | BN11: 52.389178 | BO11: 68.562458 | BP11: 47428.23 | BQ11: 55.508956 | BR11: 83.985507 | BS11: 58.248442 | BT11: 33.290897 | BU11: 69.653419 | BV11: 51.53926 | BW11: 57.6 | BX11: 77.777778 | BY11: 34600.101 | BZ11: 145001.84 | CB11: =SUMIF(INDIRECT(CB$5&"!"&"A:A"),"<="&$B11,INDIRECT(CB$5&"!"&"L:L"))-SUM(CB$6:CB10) -> 0 | CC11: =SUMIF(INDIRECT(CC$5&"!"&"A:A"),"<="&$B11,INDIRECT(CC$5&"!"&"L:L"))-SUM(CC$6:CC10) -> 0 | CD11: =SUMIF(INDIRECT(CD$5&"!"&"A:A"),"<="&$B11,INDIRECT(CD$5&"!"&"L:L"))-SUM(CD$6:CD10) -> 0 | CE11: =SUMIF(INDIRECT(CE$5&"!"&"A:A"),"<="&$B11,INDIRECT(CE$5&"!"&"L:L"))-SUM(CE$6:CE10) -> 0 | CF11: =SUMIF(INDIRECT(CF$5&"!"&"A:A"),"<="&$B11,INDIRECT(CF$5&"!"&"L:L"))-SUM(CF$6:CF10) -> 0 | CG11: =SUMIF(INDIRECT(CG$5&"!"&"A:A"),"<="&$B11,INDIRECT(CG$5&"!"&"L:L"))-SUM(CG$6:CG10) -> 0 | CH11: =SUMIF(INDIRECT(CH$5&"!"&"A:A"),"<="&$B11,INDIRECT(CH$5&"!"&"L:L"))-SUM(CH$6:CH10) -> 0 | CI11: =SUMIF(INDIRECT(CI$5&"!"&"A:A"),"<="&$B11,INDIRECT(CI$5&"!"&"L:L"))-SUM(CI$6:CI10) -> 0 | ... CS11: =SUMIF(INDIRECT(CS$5&"!"&"A:A"),"<="&$B11,INDIRECT(CS$5&"!"&"L:L"))-SUM(CS$6:CS10) -> 0 | CU11: =SUM(CB11:CS11) -> 0
B12: 45900 | D12: =SUMIF(INDIRECT(D$5&"!"&"A:A"),"<="&$B12,INDIRECT(D$5&"!"&"D:D"))-SUM(D$6:D11) -> 0 | E12: =SUMIF(INDIRECT(E$5&"!"&"A:A"),"<="&$B12,INDIRECT(E$5&"!"&"D:D"))-SUM(E$6:E11) -> 0 | F12: =SUMIF(INDIRECT(F$5&"!"&"A:A"),"<="&$B12,INDIRECT(F$5&"!"&"D:D"))-SUM(F$6:F11) -> 0 | G12: =SUMIF(INDIRECT(G$5&"!"&"A:A"),"<="&$B12,INDIRECT(G$5&"!"&"D:D"))-SUM(G$6:G11) -> 0 | H12: =SUMIF(INDIRECT(H$5&"!"&"A:A"),"<="&$B12,INDIRECT(H$5&"!"&"D:D"))-SUM(H$6:H11) -> 0 | I12: =SUMIF(INDIRECT(I$5&"!"&"A:A"),"<="&$B12,INDIRECT(I$5&"!"&"D:D"))-SUM(I$6:I11) -> 0 | J12: =SUMIF(INDIRECT(J$5&"!"&"A:A"),"<="&$B12,INDIRECT(J$5&"!"&"D:D"))-SUM(J$6:J11) -> 0 | K12: =SUMIF(INDIRECT(K$5&"!"&"A:A"),"<="&$B12,INDIRECT(K$5&"!"&"D:D"))-SUM(K$6:K11) -> 0 | ... U12: =SUMIF(INDIRECT(U$5&"!"&"A:A"),"<="&$B12,INDIRECT(U$5&"!"&"D:D"))-SUM(U$6:U11) -> 0 | W12: =SUMIF(INDIRECT(W$5&"!"&"A:A"),"<="&$B12,INDIRECT(D$5&"!"&"F:F"))-SUM(W$6:W11) -> 0 | X12: =SUMIF(INDIRECT(X$5&"!"&"A:A"),"<="&$B12,INDIRECT(E$5&"!"&"F:F"))-SUM(X$6:X11) -> 0 | Y12: =SUMIF(INDIRECT(Y$5&"!"&"A:A"),"<="&$B12,INDIRECT(F$5&"!"&"F:F"))-SUM(Y$6:Y11) -> 0 | Z12: =SUMIF(INDIRECT(Z$5&"!"&"A:A"),"<="&$B12,INDIRECT(G$5&"!"&"F:F"))-SUM(Z$6:Z11) -> 0 | AA12: =SUMIF(INDIRECT(AA$5&"!"&"A:A"),"<="&$B12,INDIRECT(H$5&"!"&"F:F"))-SUM(AA$6:AA11) -> 0 | AB12: =SUMIF(INDIRECT(AB$5&"!"&"A:A"),"<="&$B12,INDIRECT(I$5&"!"&"F:F"))-SUM(AB$6:AB11) -> 0 | AC12: =SUMIF(INDIRECT(AC$5&"!"&"A:A"),"<="&$B12,INDIRECT(J$5&"!"&"F:F"))-SUM(AC$6:AC11) -> 0 | AD12: =SUMIF(INDIRECT(AD$5&"!"&"A:A"),"<="&$B12,INDIRECT(K$5&"!"&"F:F"))-SUM(AD$6:AD11) -> 0 | ... AN12: =SUMIF(INDIRECT(AN$5&"!"&"A:A"),"<="&$B12,INDIRECT(U$5&"!"&"F:F"))-SUM(AN$6:AN11) -> 0 | AP12: =SUMIF(INDIRECT(AP$5&"!"&"A:A"),"<="&$B12,INDIRECT(AP$5&"!"&"I:I"))-SUM(AP$6:AP11) -> #N/A | AQ12: =SUMIF(INDIRECT(AQ$5&"!"&"A:A"),"<="&$B12,INDIRECT(AQ$5&"!"&"I:I"))-SUM(AQ$6:AQ11) -> 0 | AR12: =SUMIF(INDIRECT(AR$5&"!"&"A:A"),"<="&$B12,INDIRECT(AR$5&"!"&"I:I"))-SUM(AR$6:AR11) -> 0 | AS12: =SUMIF(INDIRECT(AS$5&"!"&"A:A"),"<="&$B12,INDIRECT(AS$5&"!"&"I:I"))-SUM(AS$6:AS11) -> 0 | AT12: =SUMIF(INDIRECT(AT$5&"!"&"A:A"),"<="&$B12,INDIRECT(AT$5&"!"&"I:I"))-SUM(AT$6:AT11) -> 0 | AU12: =SUMIF(INDIRECT(AU$5&"!"&"A:A"),"<="&$B12,INDIRECT(AU$5&"!"&"I:I"))-SUM(AU$6:AU11) -> 0 | AV12: =SUMIF(INDIRECT(AV$5&"!"&"A:A"),"<="&$B12,INDIRECT(AV$5&"!"&"I:I"))-SUM(AV$6:AV11) -> 0 | AW12: =SUMIF(INDIRECT(AW$5&"!"&"A:A"),"<="&$B12,INDIRECT(AW$5&"!"&"I:I"))-SUM(AW$6:AW11) -> 0 | ... BG12: =SUMIF(INDIRECT(BG$5&"!"&"A:A"),"<="&$B12,INDIRECT(BG$5&"!"&"I:I"))-SUM(BG$6:BG11) -> 0 | BI12: {=TRANSPOSE(OBR_Aug_2025!$E$4:$E$21)} -> 21107.448 | BJ12: 130509.79 | BK12: 227967.19 | BL12: 145999.02 | BM12: 64.937106 | BN12: 52.389178 | BO12: 68.562458 | BP12: 47428.23 | BQ12: 55.508956 | BR12: 83.985507 | BS12: 58.248442 | BT12: 33.290897 | BU12: 69.653419 | BV12: 51.53926 | BW12: 57.6 | BX12: 77.777778 | BY12: 34600.101 | BZ12: 145001.84 | CB12: =SUMIF(INDIRECT(CB$5&"!"&"A:A"),"<="&$B12,INDIRECT(CB$5&"!"&"L:L"))-SUM(CB$6:CB11) -> 0 | CC12: =SUMIF(INDIRECT(CC$5&"!"&"A:A"),"<="&$B12,INDIRECT(CC$5&"!"&"L:L"))-SUM(CC$6:CC11) -> 0 | CD12: =SUMIF(INDIRECT(CD$5&"!"&"A:A"),"<="&$B12,INDIRECT(CD$5&"!"&"L:L"))-SUM(CD$6:CD11) -> 0 | CE12: =SUMIF(INDIRECT(CE$5&"!"&"A:A"),"<="&$B12,INDIRECT(CE$5&"!"&"L:L"))-SUM(CE$6:CE11) -> 0 | CF12: =SUMIF(INDIRECT(CF$5&"!"&"A:A"),"<="&$B12,INDIRECT(CF$5&"!"&"L:L"))-SUM(CF$6:CF11) -> 0 | CG12: =SUMIF(INDIRECT(CG$5&"!"&"A:A"),"<="&$B12,INDIRECT(CG$5&"!"&"L:L"))-SUM(CG$6:CG11) -> 0 | CH12: =SUMIF(INDIRECT(CH$5&"!"&"A:A"),"<="&$B12,INDIRECT(CH$5&"!"&"L:L"))-SUM(CH$6:CH11) -> 0 | CI12: =SUMIF(INDIRECT(CI$5&"!"&"A:A"),"<="&$B12,INDIRECT(CI$5&"!"&"L:L"))-SUM(CI$6:CI11) -> 0 | ... CS12: =SUMIF(INDIRECT(CS$5&"!"&"A:A"),"<="&$B12,INDIRECT(CS$5&"!"&"L:L"))-SUM(CS$6:CS11) -> 0 | CU12: =SUM(CB12:CS12) -> 0
B13: 45930 | D13: =SUMIF(INDIRECT(D$5&"!"&"A:A"),"<="&$B13,INDIRECT(D$5&"!"&"D:D"))-SUM(D$6:D12) -> 0 | E13: =SUMIF(INDIRECT(E$5&"!"&"A:A"),"<="&$B13,INDIRECT(E$5&"!"&"D:D"))-SUM(E$6:E12) -> 0 | F13: =SUMIF(INDIRECT(F$5&"!"&"A:A"),"<="&$B13,INDIRECT(F$5&"!"&"D:D"))-SUM(F$6:F12) -> 0 | G13: =SUMIF(INDIRECT(G$5&"!"&"A:A"),"<="&$B13,INDIRECT(G$5&"!"&"D:D"))-SUM(G$6:G12) -> 0 | H13: =SUMIF(INDIRECT(H$5&"!"&"A:A"),"<="&$B13,INDIRECT(H$5&"!"&"D:D"))-SUM(H$6:H12) -> 0 | I13: =SUMIF(INDIRECT(I$5&"!"&"A:A"),"<="&$B13,INDIRECT(I$5&"!"&"D:D"))-SUM(I$6:I12) -> 0 | J13: =SUMIF(INDIRECT(J$5&"!"&"A:A"),"<="&$B13,INDIRECT(J$5&"!"&"D:D"))-SUM(J$6:J12) -> 0 | K13: =SUMIF(INDIRECT(K$5&"!"&"A:A"),"<="&$B13,INDIRECT(K$5&"!"&"D:D"))-SUM(K$6:K12) -> 0 | ... U13: =SUMIF(INDIRECT(U$5&"!"&"A:A"),"<="&$B13,INDIRECT(U$5&"!"&"D:D"))-SUM(U$6:U12) -> 0 | W13: =SUMIF(INDIRECT(W$5&"!"&"A:A"),"<="&$B13,INDIRECT(D$5&"!"&"F:F"))-SUM(W$6:W12) -> 0 | X13: =SUMIF(INDIRECT(X$5&"!"&"A:A"),"<="&$B13,INDIRECT(E$5&"!"&"F:F"))-SUM(X$6:X12) -> 0 | Y13: =SUMIF(INDIRECT(Y$5&"!"&"A:A"),"<="&$B13,INDIRECT(F$5&"!"&"F:F"))-SUM(Y$6:Y12) -> 0 | Z13: =SUMIF(INDIRECT(Z$5&"!"&"A:A"),"<="&$B13,INDIRECT(G$5&"!"&"F:F"))-SUM(Z$6:Z12) -> 0 | AA13: =SUMIF(INDIRECT(AA$5&"!"&"A:A"),"<="&$B13,INDIRECT(H$5&"!"&"F:F"))-SUM(AA$6:AA12) -> 0 | AB13: =SUMIF(INDIRECT(AB$5&"!"&"A:A"),"<="&$B13,INDIRECT(I$5&"!"&"F:F"))-SUM(AB$6:AB12) -> 0 | AC13: =SUMIF(INDIRECT(AC$5&"!"&"A:A"),"<="&$B13,INDIRECT(J$5&"!"&"F:F"))-SUM(AC$6:AC12) -> 0 | AD13: =SUMIF(INDIRECT(AD$5&"!"&"A:A"),"<="&$B13,INDIRECT(K$5&"!"&"F:F"))-SUM(AD$6:AD12) -> 0 | ... AN13: =SUMIF(INDIRECT(AN$5&"!"&"A:A"),"<="&$B13,INDIRECT(U$5&"!"&"F:F"))-SUM(AN$6:AN12) -> 0 | AP13: =SUMIF(INDIRECT(AP$5&"!"&"A:A"),"<="&$B13,INDIRECT(AP$5&"!"&"I:I"))-SUM(AP$6:AP12) -> #N/A | AQ13: =SUMIF(INDIRECT(AQ$5&"!"&"A:A"),"<="&$B13,INDIRECT(AQ$5&"!"&"I:I"))-SUM(AQ$6:AQ12) -> 0 | AR13: =SUMIF(INDIRECT(AR$5&"!"&"A:A"),"<="&$B13,INDIRECT(AR$5&"!"&"I:I"))-SUM(AR$6:AR12) -> 0 | AS13: =SUMIF(INDIRECT(AS$5&"!"&"A:A"),"<="&$B13,INDIRECT(AS$5&"!"&"I:I"))-SUM(AS$6:AS12) -> 0 | AT13: =SUMIF(INDIRECT(AT$5&"!"&"A:A"),"<="&$B13,INDIRECT(AT$5&"!"&"I:I"))-SUM(AT$6:AT12) -> 0 | AU13: =SUMIF(INDIRECT(AU$5&"!"&"A:A"),"<="&$B13,INDIRECT(AU$5&"!"&"I:I"))-SUM(AU$6:AU12) -> 0 | AV13: =SUMIF(INDIRECT(AV$5&"!"&"A:A"),"<="&$B13,INDIRECT(AV$5&"!"&"I:I"))-SUM(AV$6:AV12) -> 0 | AW13: =SUMIF(INDIRECT(AW$5&"!"&"A:A"),"<="&$B13,INDIRECT(AW$5&"!"&"I:I"))-SUM(AW$6:AW12) -> 0 | ... BG13: =SUMIF(INDIRECT(BG$5&"!"&"A:A"),"<="&$B13,INDIRECT(BG$5&"!"&"I:I"))-SUM(BG$6:BG12) -> 0 | BI13: {=TRANSPOSE(OBR_Aug_2025!$E$4:$E$21)} -> 21107.448 | BJ13: 130509.79 | BK13: 227967.19 | BL13: 145999.02 | BM13: 64.937106 | BN13: 52.389178 | BO13: 68.562458 | BP13: 47428.23 | BQ13: 55.508956 | BR13: 83.985507 | BS13: 58.248442 | BT13: 33.290897 | BU13: 69.653419 | BV13: 51.53926 | BW13: 57.6 | BX13: 77.777778 | BY13: 34600.101 | BZ13: 145001.84 | CB13: =SUMIF(INDIRECT(CB$5&"!"&"A:A"),"<="&$B13,INDIRECT(CB$5&"!"&"L:L"))-SUM(CB$6:CB12) -> 0 | CC13: =SUMIF(INDIRECT(CC$5&"!"&"A:A"),"<="&$B13,INDIRECT(CC$5&"!"&"L:L"))-SUM(CC$6:CC12) -> 0 | CD13: =SUMIF(INDIRECT(CD$5&"!"&"A:A"),"<="&$B13,INDIRECT(CD$5&"!"&"L:L"))-SUM(CD$6:CD12) -> 0 | CE13: =SUMIF(INDIRECT(CE$5&"!"&"A:A"),"<="&$B13,INDIRECT(CE$5&"!"&"L:L"))-SUM(CE$6:CE12) -> 0 | CF13: =SUMIF(INDIRECT(CF$5&"!"&"A:A"),"<="&$B13,INDIRECT(CF$5&"!"&"L:L"))-SUM(CF$6:CF12) -> 0 | CG13: =SUMIF(INDIRECT(CG$5&"!"&"A:A"),"<="&$B13,INDIRECT(CG$5&"!"&"L:L"))-SUM(CG$6:CG12) -> 0 | CH13: =SUMIF(INDIRECT(CH$5&"!"&"A:A"),"<="&$B13,INDIRECT(CH$5&"!"&"L:L"))-SUM(CH$6:CH12) -> 0 | CI13: =SUMIF(INDIRECT(CI$5&"!"&"A:A"),"<="&$B13,INDIRECT(CI$5&"!"&"L:L"))-SUM(CI$6:CI12) -> 0 | ... CS13: =SUMIF(INDIRECT(CS$5&"!"&"A:A"),"<="&$B13,INDIRECT(CS$5&"!"&"L:L"))-SUM(CS$6:CS12) -> 0 | CU13: =SUM(CB13:CS13) -> 0
B14: 45961 | D14: =SUMIF(INDIRECT(D$5&"!"&"A:A"),"<="&$B14,INDIRECT(D$5&"!"&"D:D"))-SUM(D$6:D13) -> 0 | E14: =SUMIF(INDIRECT(E$5&"!"&"A:A"),"<="&$B14,INDIRECT(E$5&"!"&"D:D"))-SUM(E$6:E13) -> 0 | F14: =SUMIF(INDIRECT(F$5&"!"&"A:A"),"<="&$B14,INDIRECT(F$5&"!"&"D:D"))-SUM(F$6:F13) -> 0 | G14: =SUMIF(INDIRECT(G$5&"!"&"A:A"),"<="&$B14,INDIRECT(G$5&"!"&"D:D"))-SUM(G$6:G13) -> 0 | H14: =SUMIF(INDIRECT(H$5&"!"&"A:A"),"<="&$B14,INDIRECT(H$5&"!"&"D:D"))-SUM(H$6:H13) -> 0 | I14: =SUMIF(INDIRECT(I$5&"!"&"A:A"),"<="&$B14,INDIRECT(I$5&"!"&"D:D"))-SUM(I$6:I13) -> 0 | J14: =SUMIF(INDIRECT(J$5&"!"&"A:A"),"<="&$B14,INDIRECT(J$5&"!"&"D:D"))-SUM(J$6:J13) -> 0 | K14: =SUMIF(INDIRECT(K$5&"!"&"A:A"),"<="&$B14,INDIRECT(K$5&"!"&"D:D"))-SUM(K$6:K13) -> 0 | ... U14: =SUMIF(INDIRECT(U$5&"!"&"A:A"),"<="&$B14,INDIRECT(U$5&"!"&"D:D"))-SUM(U$6:U13) -> 0 | W14: =SUMIF(INDIRECT(W$5&"!"&"A:A"),"<="&$B14,INDIRECT(D$5&"!"&"F:F"))-SUM(W$6:W13) -> 0 | X14: =SUMIF(INDIRECT(X$5&"!"&"A:A"),"<="&$B14,INDIRECT(E$5&"!"&"F:F"))-SUM(X$6:X13) -> 0 | Y14: =SUMIF(INDIRECT(Y$5&"!"&"A:A"),"<="&$B14,INDIRECT(F$5&"!"&"F:F"))-SUM(Y$6:Y13) -> 0 | Z14: =SUMIF(INDIRECT(Z$5&"!"&"A:A"),"<="&$B14,INDIRECT(G$5&"!"&"F:F"))-SUM(Z$6:Z13) -> 0 | AA14: =SUMIF(INDIRECT(AA$5&"!"&"A:A"),"<="&$B14,INDIRECT(H$5&"!"&"F:F"))-SUM(AA$6:AA13) -> 0 | AB14: =SUMIF(INDIRECT(AB$5&"!"&"A:A"),"<="&$B14,INDIRECT(I$5&"!"&"F:F"))-SUM(AB$6:AB13) -> 0 | AC14: =SUMIF(INDIRECT(AC$5&"!"&"A:A"),"<="&$B14,INDIRECT(J$5&"!"&"F:F"))-SUM(AC$6:AC13) -> 0 | AD14: =SUMIF(INDIRECT(AD$5&"!"&"A:A"),"<="&$B14,INDIRECT(K$5&"!"&"F:F"))-SUM(AD$6:AD13) -> 0 | ... AN14: =SUMIF(INDIRECT(AN$5&"!"&"A:A"),"<="&$B14,INDIRECT(U$5&"!"&"F:F"))-SUM(AN$6:AN13) -> 0 | AP14: =SUMIF(INDIRECT(AP$5&"!"&"A:A"),"<="&$B14,INDIRECT(AP$5&"!"&"I:I"))-SUM(AP$6:AP13) -> #N/A | AQ14: =SUMIF(INDIRECT(AQ$5&"!"&"A:A"),"<="&$B14,INDIRECT(AQ$5&"!"&"I:I"))-SUM(AQ$6:AQ13) -> 0 | AR14: =SUMIF(INDIRECT(AR$5&"!"&"A:A"),"<="&$B14,INDIRECT(AR$5&"!"&"I:I"))-SUM(AR$6:AR13) -> 0 | AS14: =SUMIF(INDIRECT(AS$5&"!"&"A:A"),"<="&$B14,INDIRECT(AS$5&"!"&"I:I"))-SUM(AS$6:AS13) -> 0 | AT14: =SUMIF(INDIRECT(AT$5&"!"&"A:A"),"<="&$B14,INDIRECT(AT$5&"!"&"I:I"))-SUM(AT$6:AT13) -> 0 | AU14: =SUMIF(INDIRECT(AU$5&"!"&"A:A"),"<="&$B14,INDIRECT(AU$5&"!"&"I:I"))-SUM(AU$6:AU13) -> 0 | AV14: =SUMIF(INDIRECT(AV$5&"!"&"A:A"),"<="&$B14,INDIRECT(AV$5&"!"&"I:I"))-SUM(AV$6:AV13) -> 0 | AW14: =SUMIF(INDIRECT(AW$5&"!"&"A:A"),"<="&$B14,INDIRECT(AW$5&"!"&"I:I"))-SUM(AW$6:AW13) -> 0 | ... BG14: =SUMIF(INDIRECT(BG$5&"!"&"A:A"),"<="&$B14,INDIRECT(BG$5&"!"&"I:I"))-SUM(BG$6:BG13) -> 0 | BI14: {=TRANSPOSE(OBR_Aug_2025!$E$4:$E$21)} -> 21107.448 | BJ14: 130509.79 | BK14: 227967.19 | BL14: 145999.02 | BM14: 64.937106 | BN14: 52.389178 | BO14: 68.562458 | BP14: 47428.23 | BQ14: 55.508956 | BR14: 83.985507 | BS14: 58.248442 | BT14: 33.290897 | BU14: 69.653419 | BV14: 51.53926 | BW14: 57.6 | BX14: 77.777778 | BY14: 34600.101 | BZ14: 145001.84 | CB14: =SUMIF(INDIRECT(CB$5&"!"&"A:A"),"<="&$B14,INDIRECT(CB$5&"!"&"L:L"))-SUM(CB$6:CB13) -> 0 | CC14: =SUMIF(INDIRECT(CC$5&"!"&"A:A"),"<="&$B14,INDIRECT(CC$5&"!"&"L:L"))-SUM(CC$6:CC13) -> 0 | CD14: =SUMIF(INDIRECT(CD$5&"!"&"A:A"),"<="&$B14,INDIRECT(CD$5&"!"&"L:L"))-SUM(CD$6:CD13) -> 0 | CE14: =SUMIF(INDIRECT(CE$5&"!"&"A:A"),"<="&$B14,INDIRECT(CE$5&"!"&"L:L"))-SUM(CE$6:CE13) -> 0 | CF14: =SUMIF(INDIRECT(CF$5&"!"&"A:A"),"<="&$B14,INDIRECT(CF$5&"!"&"L:L"))-SUM(CF$6:CF13) -> 0 | CG14: =SUMIF(INDIRECT(CG$5&"!"&"A:A"),"<="&$B14,INDIRECT(CG$5&"!"&"L:L"))-SUM(CG$6:CG13) -> 0 | CH14: =SUMIF(INDIRECT(CH$5&"!"&"A:A"),"<="&$B14,INDIRECT(CH$5&"!"&"L:L"))-SUM(CH$6:CH13) -> 0 | CI14: =SUMIF(INDIRECT(CI$5&"!"&"A:A"),"<="&$B14,INDIRECT(CI$5&"!"&"L:L"))-SUM(CI$6:CI13) -> 0 | ... CS14: =SUMIF(INDIRECT(CS$5&"!"&"A:A"),"<="&$B14,INDIRECT(CS$5&"!"&"L:L"))-SUM(CS$6:CS13) -> 0 | CU14: =SUM(CB14:CS14) -> 0

Sheet Raw Material Tracker>>>>>>>
B2: Raw Material Tracker >>>>>>>>>>>>

Sheet 12001
A1: Received Date | B1: Particular | C1: Opening Stock | D1: Purchase Quantity | E1: Unit Cost | F1: Total Cost (Purchase + Carriage Inward) | G1: Total Stock Before Production | H1: WAC per Unit | I1: Used in Production | J1: Ground Stock | K1: Closing Inventory Value | L1: Cost of Production | N1: =OBR_Feb_2025!B2 -> #REF! | O1: =OBR_Feb_2025!A2 -> #REF!
A2: =IFERROR(__xludf.DUMMYFUNCTION("QUERY(IMPORTRANGE(""https://docs.google.com/spreadsheets/d/1sOBA95jI3gUTkNtq3pD8Ob7Zb_EY63WYXvHKt7aiQk8/edit?gid=2092145476#gid=2092145476"",""Daily Record - Raw Material Purchases!B4:T500""),""SELECT Col13 WHERE Col6 = 12001"",0)"),"#REF!") -> #REF! | B2: =IFERROR(__xludf.DUMMYFUNCTION("QUERY(IMPORTRANGE(""https://docs.google.com/spreadsheets/d/1sOBA95jI3gUTkNtq3pD8Ob7Zb_EY63WYXvHKt7aiQk8/edit?gid=2092145476#gid=2092145476"",""Daily Record - Raw Material Purchases!B4:T500""),""SELECT Col4 WHERE Col6 = 12001"",0)"),"#REF!") -> #REF! | C2: =OBR_Feb_2025!D2 -> 101 | D2: =IFERROR(__xludf.DUMMYFUNCTION("QUERY(IMPORTRANGE(""https://docs.google.com/spreadsheets/d/1sOBA95jI3gUTkNtq3pD8Ob7Zb_EY63WYXvHKt7aiQk8/edit?gid=2092145476#gid=2092145476"",""Daily Record - Raw Material Purchases!B4:T500""),""SELECT Col8 WHERE Col6 = 12001"",0)"),"#REF!") -> #REF! | E2: =IFERROR(__xludf.DUMMYFUNCTION("QUERY(IMPORTRANGE(""https://docs.google.com/spreadsheets/d/1sOBA95jI3gUTkNtq3pD8Ob7Zb_EY63WYXvHKt7aiQk8/edit?gid=2092145476#gid=2092145476"",""Daily Record - Raw Material Purchases!B4:T500""),""SELECT Col12 WHERE Col6 = 12001"",0)"),"#REF!") -> #REF! | F2: =D2*E2 -> #REF! | G2: =C2+D2 -> #REF! | H2: =IF(G2=0,0,((C2*OBR_Feb_2025!E2)+(D2*E2))/G2) -> #REF! | I2: =IF(ISBLANK(J2),"",G2-J2) -> #REF! | J2: =OBR_Mar_2025!D4 -> 226 | K2: =IF(ISBLANK(J2),"",J2*H2) -> #REF! | L2: =IF(ISBLANK(J2),"",I2*H2) -> #REF!
C3: =G2-I2 -> #REF! | F3: =D3*E3 -> 0 | G3: =C3+D3 -> #REF! | H3: =IF(G3=0,0,((C3*H2)+(D3*E3))/G3) -> #REF! | I3: =IF(ISBLANK(J3),"",G3-J3) -> #REF! | J3: 116 | K3: =IF(ISBLANK(J3),"",J3*H3) -> #REF! | L3: =IF(ISBLANK(J3),"",I3*H3) -> #REF!
C4: =G3-I3 -> #REF! | F4: =D4*E4 -> 0 | G4: =C4+D4 -> #REF! | H4: =IF(G4=0,0,((C4*H3)+(D4*E4))/G4) -> #REF! | I4: =IF(ISBLANK(J4),"",G4-J4) -> #REF! | J4: 60 | K4: =IF(ISBLANK(J4),"",J4*H4) -> #REF! | L4: =IF(ISBLANK(J4),"",I4*H4) -> #REF!
C5: =G4-I4 -> #REF! | F5: =D5*E5 -> 0 | G5: =C5+D5 -> #REF! | H5: =IF(G5=0,0,((C5*H4)+(D5*E5))/G5) -> #REF! | I5: =IF(ISBLANK(J5),"",G5-J5) | K5: =J5*H5 -> #REF! | L5: =IF(ISBLANK(J5),"",I5*H5)
C6: =G5-I5 -> #REF! | F6: =D6*E6 -> 0 | G6: =C6+D6 -> #REF! | H6: =IF(G6=0,0,((C6*H5)+(D6*E6))/G6) -> #REF! | I6: =IF(ISBLANK(J6),"",G6-J6) -> #REF! | J6: 86 | K6: =J6*H6 -> #REF! | L6: =IF(ISBLANK(J6),"",I6*H6) -> #REF!
C7: =G6-I6 -> #REF! | F7: =D7*E7 -> 0 | G7: =C7+D7 -> #REF! | H7: =IF(G7=0,0,((C7*H6)+(D7*E7))/G7) -> #REF! | I7: =IF(ISBLANK(J7),"",G7-J7) -> #REF! | J7: 94 | K7: =J7*H7 -> #REF! | L7: =IF(ISBLANK(J7),"",I7*H7) -> #REF!
C8: =G7-I7 -> #REF! | F8: =D8*E8 -> 0 | G8: =C8+D8 -> #REF! | H8: =IF(G8=0,0,((C8*H7)+(D8*E8))/G8) -> #REF! | I8: =IF(ISBLANK(J8),"",G8-J8) -> #REF! | J8: 40 | K8: =J8*H8 -> #REF! | L8: =IF(ISBLANK(J8),"",I8*H8) -> #REF!
C9: =G8-I8 -> #REF! | F9: =D9*E9 -> 0 | G9: =C9+D9 -> #REF! | H9: =IF(G9=0,0,((C9*H8)+(D9*E9))/G9) -> #REF! | I9: =IF(ISBLANK(J9),"",G9-J9) -> #REF! | J9: 98 | K9: =J9*H9 -> #REF! | L9: =IF(ISBLANK(J9),"",I9*H9) -> #REF!
C10: =G9-I9 -> #REF! | F10: =D10*E10 -> 0 | G10: =C10+D10 -> #REF! | H10: =IF(G10=0,0,((C10*H9)+(D10*E10))/G10) -> #REF! | I10: =IF(ISBLANK(J10),"",G10-J10) -> #REF! | J10: 84 | K10: =J10*H10 -> #REF! | L10: =IF(ISBLANK(J10),"",I10*H10) -> #REF!
C11: =G10-I10 -> #REF! | F11: =D11*E11 -> 0 | G11: =C11+D11 -> #REF! | H11: =IF(G11=0,0,((C11*H10)+(D11*E11))/G11) -> #REF! | I11: =IF(ISBLANK(J11),"",G11-J11) -> #REF! | J11: 114 | K11: =J11*H11 -> #REF! | L11: =IF(ISBLANK(J11),"",I11*H11) -> #REF!
C12: =G11-I11 -> #REF! | H12: =IF(G12=0,0,((C12*H11)+(D12*E12))/G12) -> 0 | I12: =IF(ISBLANK(J12),"",G12-J12) | K12: =J12*H12 -> 0 | L12: =IF(ISBLANK(J12),"",I12*H12)
C13: =G12-I12 -> 0 | H13: =IF(G13=0,0,((C13*H12)+(D13*E13))/G13) -> 0 | I13: =IF(ISBLANK(J13),"",G13-J13) | K13: =J13*H13 -> 0 | L13: =IF(ISBLANK(J13),"",I13*H13)
C14: =G13-I13 -> 0 | H14: =IF(G14=0,0,((C14*H13)+(D14*E14))/G14) -> 0 | I14: =IF(ISBLANK(J14),"",G14-J14) | K14: =J14*H14 -> 0 | L14: =IF(ISBLANK(J14),"",I14*H14)
C15: =G14-I14 -> 0 | H15: =IF(G15=0,0,((C15*H14)+(D15*E15))/G15) -> 0 | I15: =IF(ISBLANK(J15),"",G15-J15) | K15: =J15*H15 -> 0 | L15: =IF(ISBLANK(J15),"",I15*H15)

Sheet 12002
A1: Received Date | B1: Particular | C1: Opening Stock | D1: Purchase Quantity | E1: Unit Cost | F1: Total Cost (Purchase + Carriage Inward) | G1: Total Stock Before Production | H1: WAC per Unit | I1: Used in Production | J1: Ground Stock | K1: Closing Inventory Value | L1: Cost of Production | N1: =OBR_Feb_2025!B3 | O1: =OBR_Feb_2025!A3
A2: =IFERROR(__xludf.DUMMYFUNCTION("QUERY(IMPORTRANGE(""https://docs.google.com/spreadsheets/d/1sOBA95jI3gUTkNtq3pD8Ob7Zb_EY63WYXvHKt7aiQk8/edit?gid=2092145476#gid=2092145476"",""Daily Record - Raw Material Purchases!B4:T500""),""SELECT Col13 WHERE Col6 = 12002"",0)"),"#REF!") -> #REF! | B2: =IFERROR(__xludf.DUMMYFUNCTION("QUERY(IMPORTRANGE(""https://docs.google.com/spreadsheets/d/1sOBA95jI3gUTkNtq3pD8Ob7Zb_EY63WYXvHKt7aiQk8/edit?gid=2092145476#gid=2092145476"",""Daily Record - Raw Material Purchases!B4:T500""),""SELECT Col4 WHERE Col6 = 12002"",0)"),"#REF!") -> #REF! | C2: =OBR_Feb_2025!D3 -> 1 | D2: =IFERROR(__xludf.DUMMYFUNCTION("QUERY(IMPORTRANGE(""https://docs.google.com/spreadsheets/d/1sOBA95jI3gUTkNtq3pD8Ob7Zb_EY63WYXvHKt7aiQk8/edit?gid=2092145476#gid=2092145476"",""Daily Record - Raw Material Purchases!B4:T500""),""SELECT Col8 WHERE Col6 = 12002"",0)"),"#REF!") -> #REF! | E2: =IFERROR(__xludf.DUMMYFUNCTION("QUERY(IMPORTRANGE(""https://docs.google.com/spreadsheets/d/1sOBA95jI3gUTkNtq3pD8Ob7Zb_EY63WYXvHKt7aiQk8/edit?gid=2092145476#gid=2092145476"",""Daily Record - Raw Material Purchases!B4:T500""),""SELECT Col12 WHERE Col6 = 12002"",0)"),"#REF!") -> #REF! | F2: =D2*E2 -> #REF! | G2: =C2+D2 -> #REF! | H2: =IF(G2=0,0,((C2*OBR_Feb_2025!E3)+(D2*E2))/G2) -> #REF! | I2: =IF(ISBLANK(J2),"",G2-J2) -> #REF! | J2: =OBR_Mar_2025!D5 -> 12 | K2: =J2*H2 -> #REF! | L2: =IF(ISBLANK(J2),"",I2*H2) -> #REF!
C3: =G2-I2 -> #REF! | F3: =D3*E3 -> 0 | G3: =C3+D3 -> #REF! | H3: =IF(G3=0,0,((C3*H2)+(D3*E3))/G3) -> #REF! | I3: =IF(ISBLANK(J3),"",G3-J3) -> #REF! | J3: 7 | K3: =J3*H3 -> #REF! | L3: =IF(ISBLANK(J3),"",I3*H3) -> #REF!
C4: =G3-I3 -> #REF! | F4: =D4*E4 -> 0 | G4: =C4+D4 -> #REF! | H4: =IF(G4=0,0,((C4*H3)+(D4*E4))/G4) -> #REF! | I4: =IF(ISBLANK(J4),"",G4-J4) -> #REF! | J4: 16 | K4: =J4*H4 -> #REF! | L4: =IF(ISBLANK(J4),"",I4*H4) -> #REF!
C5: =G4-I4 -> #REF! | F5: =D5*E5 -> 0 | G5: =C5+D5 -> #REF! | H5: =IF(G5=0,0,((C5*H4)+(D5*E5))/G5) -> #REF! | I5: =IF(ISBLANK(J5),"",G5-J5) -> #REF! | J5: 4.5 | K5: =J5*H5 -> #REF! | L5: =IF(ISBLANK(J5),"",I5*H5) -> #REF!
C6: =G5-I5 -> #REF! | F6: =D6*E6 -> 0 | G6: =C6+D6 -> #REF! | H6: =IF(G6=0,0,((C6*H5)+(D6*E6))/G6) -> #REF! | I6: =IF(ISBLANK(J6),"",G6-J6) -> #REF! | J6: 3 | K6: =J6*H6 -> #REF! | L6: =IF(ISBLANK(J6),"",I6*H6) -> #REF!
C7: =G6-I6 -> #REF! | F7: =D7*E7 -> 0 | G7: =C7+D7 -> #REF! | H7: =IF(G7=0,0,((C7*H6)+(D7*E7))/G7) -> #REF! | I7: =IF(ISBLANK(J7),"",G7-J7) | K7: =J7*H7 -> #REF! | L7: =IF(ISBLANK(J7),"",I7*H7)
C8: =G7-I7 -> #REF! | F8: =D8*E8 -> 0 | G8: =C8+D8 -> #REF! | H8: =IF(G8=0,0,((C8*H7)+(D8*E8))/G8) -> #REF! | I8: =IF(ISBLANK(J8),"",G8-J8) -> #REF! | J8: 8.48 | K8: =J8*H8 -> #REF! | L8: =IF(ISBLANK(J8),"",I8*H8) -> #REF!
C9: =G8-I8 -> #REF! | F9: =D9*E9 -> 0 | G9: =C9+D9 -> #REF! | H9: =IF(G9=0,0,((C9*H8)+(D9*E9))/G9) -> #REF! | I9: =IF(ISBLANK(J9),"",G9-J9) -> #REF! | J9: 12.6 | K9: =J9*H9 -> #REF! | L9: =IF(ISBLANK(J9),"",I9*H9) -> #REF!
C10: =G9-I9 -> #REF! | F10: =D10*E10 -> 0 | G10: =C10+D10 -> #REF! | H10: =IF(G10=0,0,((C10*H9)+(D10*E10))/G10) -> #REF! | I10: =IF(ISBLANK(J10),"",G10-J10) -> #REF! | J10: 11.28 | K10: =J10*H10 -> #REF! | L10: =IF(ISBLANK(J10),"",I10*H10) -> #REF!
C11: =G10-I10 -> #REF! | F11: =D11*E11 -> 0 | G11: =C11+D11 -> #REF! | H11: =IF(G11=0,0,((C11*H10)+(D11*E11))/G11) -> #REF! | I11: =IF(ISBLANK(J11),"",G11-J11) -> #REF! | J11: 7.32 | K11: =J11*H11 -> #REF! | L11: =IF(ISBLANK(J11),"",I11*H11) -> #REF!
C12: =G11-I11 -> #REF! | H12: =IF(G12=0,0,((C12*H11)+(D12*E12))/G12) -> 0 | I12: =IF(ISBLANK(J12),"",G12-J12) | K12: =J12*H12 -> 0 | L12: =IF(ISBLANK(J12),"",I12*H12)
C13: =G12-I12 -> 0 | H13: =IF(G13=0,0,((C13*H12)+(D13*E13))/G13) -> 0 | I13: =IF(ISBLANK(J13),"",G13-J13) | K13: =J13*H13 -> 0 | L13: =IF(ISBLANK(J13),"",I13*H13)
C14: =G13-I13 -> 0 | H14: =IF(G14=0,0,((C14*H13)+(D14*E14))/G14) -> 0 | I14: =IF(ISBLANK(J14),"",G14-J14) | K14: =J14*H14 -> 0 | L14: =IF(ISBLANK(J14),"",I14*H14)
C15: =G14-I14 -> 0 | H15: =IF(G15=0,0,((C15*H14)+(D15*E15))/G15) -> 0 | I15: =IF(ISBLANK(J15),"",G15-J15) | K15: =J15*H15 -> 0 | L15: =IF(ISBLANK(J15),"",I15*H15)

Sheet 12003
A1: Received Date | B1: Particular | C1: Opening Stock | D1: Purchase Quantity | E1: Unit Cost | F1: Total Cost (Purchase + Carriage Inward) | G1: Total Stock Before Production | H1: WAC per Unit | I1: Used in Production | J1: Ground Stock | K1: Closing Inventory Value | L1: Cost of Production | N1: =OBR_Feb_2025!B4 | O1: =OBR_Feb_2025!A4
A2: =IFERROR(__xludf.DUMMYFUNCTION("QUERY(IMPORTRANGE(""https://docs.google.com/spreadsheets/d/1sOBA95jI3gUTkNtq3pD8Ob7Zb_EY63WYXvHKt7aiQk8/edit?gid=2092145476#gid=2092145476"",""Daily Record - Raw Material Purchases!B4:T500""),""SELECT Col13 WHERE Col6 = 12003"",0)"),"#REF!") -> #REF! | B2: =IFERROR(__xludf.DUMMYFUNCTION("QUERY(IMPORTRANGE(""https://docs.google.com/spreadsheets/d/1sOBA95jI3gUTkNtq3pD8Ob7Zb_EY63WYXvHKt7aiQk8/edit?gid=2092145476#gid=2092145476"",""Daily Record - Raw Material Purchases!B4:T500""),""SELECT Col4 WHERE Col6 = 12003"",0)"),"#REF!") -> #REF! | C2: =OBR_Feb_2025!D4 -> 1.5 | D2: =IFERROR(__xludf.DUMMYFUNCTION("QUERY(IMPORTRANGE(""https://docs.google.com/spreadsheets/d/1sOBA95jI3gUTkNtq3pD8Ob7Zb_EY63WYXvHKt7aiQk8/edit?gid=2092145476#gid=2092145476"",""Daily Record - Raw Material Purchases!B4:T500""),""SELECT Col8 WHERE Col6 = 12003"",0)"),"#REF!") -> #REF! | E2: =IFERROR(__xludf.DUMMYFUNCTION("QUERY(IMPORTRANGE(""https://docs.google.com/spreadsheets/d/1sOBA95jI3gUTkNtq3pD8Ob7Zb_EY63WYXvHKt7aiQk8/edit?gid=2092145476#gid=2092145476"",""Daily Record - Raw Material Purchases!B4:T500""),""SELECT Col12 WHERE Col6 = 12003"",0)"),"#REF!") -> #REF! | F2: =D2*E2 -> #REF! | G2: =C2+D2 -> #REF! | H2: =IF(G2=0,0,((C2*OBR_Feb_2025!E4)+(D2*E2))/G2) -> #REF! | I2: =IF(ISBLANK(J2),"",G2-J2) -> #REF! | J2: =OBR_Mar_2025!D6 -> 1.5 | K2: =J2*H2 -> #REF! | L2: =IF(ISBLANK(J2),"",I2*H2) -> #REF!
C3: =G2-I2 -> #REF! | F3: =D3*E3 -> 0 | G3: =C3+D3 -> #REF! | H3: =IF(G3=0,0,((C3*H2)+(D3*E3))/G3) -> #REF! | I3: =IF(ISBLANK(J3),"",G3-J3) | K3: =J3*H3 -> #REF! | L3: =IF(ISBLANK(J3),"",I3*H3)
C4: =G3-I3 -> #REF! | F4: =D4*E4 -> 0 | G4: =C4+D4 -> #REF! | H4: =IF(G4=0,0,((C4*H3)+(D4*E4))/G4) -> #REF! | I4: =IF(ISBLANK(J4),"",G4-J4) -> #REF! | J4: 2 | K4: =J4*H4 -> #REF! | L4: =IF(ISBLANK(J4),"",I4*H4) -> #REF!
C5: =G4-I4 -> #REF! | F5: =D5*E5 -> 0 | G5: =C5+D5 -> #REF! | H5: =IF(G5=0,0,((C5*H4)+(D5*E5))/G5) -> #REF! | I5: =IF(ISBLANK(J5),"",G5-J5) -> #REF! | J5: 1 | K5: =J5*H5 -> #REF! | L5: =IF(ISBLANK(J5),"",I5*H5) -> #REF!
C6: =G5-I5 -> #REF! | F6: =D6*E6 -> 0 | G6: =C6+D6 -> #REF! | H6: =IF(G6=0,0,((C6*H5)+(D6*E6))/G6) -> #REF! | I6: =IF(ISBLANK(J6),"",G6-J6) -> #REF! | J6: 1 | K6: =J6*H6 -> #REF! | L6: =IF(ISBLANK(J6),"",I6*H6) -> #REF!
C7: =G6-I6 -> #REF! | F7: =D7*E7 -> 0 | G7: =C7+D7 -> #REF! | H7: =IF(G7=0,0,((C7*H6)+(D7*E7))/G7) -> #REF! | I7: =IF(ISBLANK(J7),"",G7-J7) | K7: =J7*H7 -> #REF! | L7: =IF(ISBLANK(J7),"",I7*H7)
C8: =G7-I7 -> #REF! | F8: =D8*E8 -> 0 | G8: =C8+D8 -> #REF! | H8: =IF(G8=0,0,((C8*H7)+(D8*E8))/G8) -> #REF! | I8: =IF(ISBLANK(J8),"",G8-J8) -> #REF! | J8: 2.16 | K8: =J8*H8 -> #REF! | L8: =IF(ISBLANK(J8),"",I8*H8) -> #REF!
C9: =G8-I8 -> #REF! | F9: =D9*E9 -> 0 | G9: =C9+D9 -> #REF! | H9: =IF(G9=0,0,((C9*H8)+(D9*E9))/G9) -> #REF! | I9: =IF(ISBLANK(J9),"",G9-J9) -> #REF! | J9: 2.44 | K9: =J9*H9 -> #REF! | L9: =IF(ISBLANK(J9),"",I9*H9) -> #REF!
C10: =G9-I9 -> #REF! | F10: =D10*E10 -> 0 | G10: =C10+D10 -> #REF! | H10: =IF(G10=0,0,((C10*H9)+(D10*E10))/G10) -> #REF! | I10: =IF(ISBLANK(J10),"",G10-J10) -> #REF! | J10: 1.92 | K10: =J10*H10 -> #REF! | L10: =IF(ISBLANK(J10),"",I10*H10) -> #REF!
C11: =G10-I10 -> #REF! | F11: =D11*E11 -> 0 | G11: =C11+D11 -> #REF! | H11: =IF(G11=0,0,((C11*H10)+(D11*E11))/G11) -> #REF! | I11: =IF(ISBLANK(J11),"",G11-J11) -> #REF! | J11: 1.48 | K11: =J11*H11 -> #REF! | L11: =IF(ISBLANK(J11),"",I11*H11) -> #REF!
C12: =G11-I11 -> #REF! | F12: =D12*E12 -> 0 | G12: =C12+D12 -> #REF! | H12: =IF(G12=0,0,((C12*H11)+(D12*E12))/G12) -> #REF! | I12: =IF(ISBLANK(J12),"",G12-J12) -> #REF! | J12: 1.7 | K12: =J12*H12 -> #REF! | L12: =IF(ISBLANK(J12),"",I12*H12) -> #REF!
H13: =IF(G13=0,0,((C13*H12)+(D13*E13))/G13) -> 0
H14: =IF(G14=0,0,((C14*H13)+(D14*E14))/G14) -> 0
H15: =IF(G15=0,0,((C15*H14)+(D15*E15))/G15) -> 0

Sheet 12004
A1: Received Date | B1: Particular | C1: Opening Stock | D1: Purchase Quantity | E1: Unit Cost | F1: Total Cost (Purchase + Carriage Inward) | G1: Total Stock Before Production | H1: WAC per Unit | I1: Used in Production | J1: Ground Stock | K1: Closing Inventory Value | L1: Cost of Production | N1: =OBR_Feb_2025!B5 | O1: =OBR_Feb_2025!A5
